Workbook

Sheet Leeme
A1: Planificador · reproyección oct–dic 2025 y presupuesto 2026
A2: Cobranzas del Sur S.A. · datos 100% ficticios · generado el 2026-10-04
A4: Para qué sirve | B4: Arma el cierre 2025 (real ene–sep + reproyección oct–dic) y el presupuesto 2026 mes a mes, desde la operación real de jul–sep 2025.
A5: Qué se carga | B5: Celdas azules con fondo amarillo: supuestos mes a mes (hoja Supuestos) y lo que proyecta cada supervisor por cartera (hoja Drivers). Todo lo demás son fórmulas.
A6: Supuestos | B6: Inflación mensual, tipo de cambio, aumentos salariales por tramos (paritarias), aumento del precio del SMS y estacionalidad.
A7: Drivers por cartera | B7: Volumen de deuda asignada (índice real, sep-25 = 100), % de recupero, fee y posiciones. Para dar de baja una cartera, poné volumen y posiciones en 0.
A8: Cálculo | B8: Una fila por cartera y línea del estado de resultados. La columna Categoría dice con qué índice se mueve cada línea (ver la lista abajo).
A9: EERR | B9: Estado de resultados mensual: real ene–sep, reproyección oct–dic, cierre 2025 contra presupuesto 2025, y presupuesto 2026 mes a mes.
A10: Por cartera | B10: Ingresos y margen de contribución por cartera para el cierre 2025 y el presupuesto 2026.
A11: Dotación | B11: Posiciones por cartera y remuneraciones operativas. Información sensible: solo RRHH, Gerencia y Control de Gestión.
A12: Base | B12: Run-rate de jul–sep 2025 llevado a precios de septiembre; los ingresos se desestacionalizan y la estacionalidad se vuelve a aplicar mes a mes.
A13: Montos | B13: En pesos; las tablas de resultados se muestran en millones (formato de celda). Índices: sep-25 = 1.
A14: Al abrir | B14: Si Excel abre en Vista protegida y ves celdas vacías, tocá «Habilitar edición»: el archivo recalcula todo al abrir.
A16: Categorías de cálculo
A17: rev | B17: Ingreso: precios (o TC) × volumen × recupero × fee × estacionalidad
A18: iibb | B18: Igual que el ingreso (es un % de lo facturado)
A19: pos_sal | B19: Índice salarial × posiciones
A20: pos_usd | B20: Índice de TC × posiciones
A21: pos_inf | B21: Índice de precios × posiciones
A22: vol_usd | B22: Índice de TC × volumen
A23: vol_inf | B23: Índice de precios × volumen
A24: sms | B24: Índice de precio SMS × volumen
A25: zero | B25: No se presupuesta (se carga aparte si hay desvinculaciones)
A26: sal | B26: Índice salarial
A27: usd | B27: Índice de TC
A28: inf | B28: Índice de precios
... A32: tax | B32: Tasa × resultado antes de impuestos
A34: Colores
A35: 1.234 | B35: Dato que se carga (supuesto o proyección)
A36: 1.234 | B36: Fórmula
A37: 1.234 | B37: Vínculo a otra hoja

Sheet Supuestos
A1: Supuestos mes a mes
A2: Celdas azules: se cargan. Índices con base sep-25 = 1.
A4: Supuesto | B4: Unidad | C4: Base sep-25 | D4: oct-25 | E4: nov-25 | F4: dic-25 | G4: ene-26 | H4: feb-26 | I4: mar-26 | J4: abr-26 | K4: may-26 | L4: jun-26 | M4: jul-26 | N4: ago-26 | O4: sep-26 | P4: oct-26 | Q4: nov-26 | R4: dic-26 | S4: Comentario
A5: Inflación mensual | B5: % | D5: 0.023 | E5: 0.023 | F5: 0.023 | G5: 0.019 | H5: 0.019 | I5: 0.019 | J5: 0.019 | K5: 0.019 | L5: 0.019 | M5: 0.019 | N5: 0.019 | O5: 0.019 | P5: 0.019 | Q5: 0.019 | R5: 0.019 | S5: Variación mensual de precios. Ajusta la deuda en pesos (y el ingreso) y los costos que siguen a la inflación.
A6: Índice de precios | B6: índice | C6: 1 | D6: =C6*(1+D5) | E6: =D6*(1+E5) | F6: =E6*(1+F5) | G6: =F6*(1+G5) | H6: =G6*(1+H5) | I6: =H6*(1+I5) | J6: =I6*(1+J5) | K6: =J6*(1+K5) | ... R6: =Q6*(1+R5) | S6: Acumula la inflación desde sep-25.
A7: Tipo de cambio promedio | B7: $ / US$ | C7: 1365 | D7: 1398 | E7: 1432 | F7: 1465 | G7: 1489 | H7: 1512 | I7: 1536 | J7: 1560 | K7: 1584 | L7: 1608 | M7: 1631 | N7: 1655 | O7: 1679 | P7: 1702 | Q7: 1726 | R7: 1750 | S7: Mueve los ingresos de carteras en dólares y los costos en dólares (Paraguay, licencias, mailing).
A8: Índice de tipo de cambio | B8: índice | C8: 1 | D8: =D7/$C$7 | E8: =E7/$C$7 | F8: =F7/$C$7 | G8: =G7/$C$7 | H8: =H7/$C$7 | I8: =I7/$C$7 | J8: =J7/$C$7 | K8: =K7/$C$7 | ... R8: =R7/$C$7 | S8: TC del mes / TC de sep-25.
A9: Aumento salarial del mes (paritaria) | B9: % | D9: 0.06 | E9: 0 | F9: 0 | G9: 0.055 | H9: 0 | I9: 0 | J9: 0.055 | K9: 0 | L9: 0 | M9: 0.055 | N9: 0 | O9: 0 | P9: 0.055 | Q9: 0 | R9: 0 | S9: Cargá el % en el mes del tramo (trimestral, bimestral o mensual).
A10: Índice salarial | B10: índice | C10: 1 | D10: =C10*(1+D9) | E10: =D10*(1+E9) | F10: =E10*(1+F9) | G10: =F10*(1+G9) | H10: =G10*(1+H9) | I10: =H10*(1+I9) | J10: =I10*(1+J9) | K10: =J10*(1+K9) | ... R10: =Q10*(1+R9) | S10: Acumula los tramos de paritaria.
A11: Aumento del precio del SMS | B11: % | D11: 0.023 | E11: 0.023 | F11: 0.023 | G11: 0.019 | H11: 0.019 | I11: 0.019 | J11: 0.019 | K11: 0.019 | L11: 0.019 | M11: 0.019 | N11: 0.019 | O11: 0.019 | P11: 0.019 | Q11: 0.019 | R11: 0.019 | S11: Por defecto, igual a la inflación.
A12: Índice de precio SMS | B12: índice | C12: 1 | D12: =C12*(1+D11) | E12: =D12*(1+E11) | F12: =E12*(1+F11) | G12: =F12*(1+G11) | H12: =G12*(1+H11) | I12: =H12*(1+I11) | J12: =I12*(1+J11) | K12: =J12*(1+K11) | ... R12: =Q12*(1+R11)
A13: Estacionalidad de ingresos | B13: factor | D13: 1.01 | E13: 1 | F13: 0.97 | G13: 0.96 | H13: 0.97 | I13: 1.03 | J13: 1.01 | K13: 1 | L13: 0.99 | M13: 1 | N13: 1.01 | O13: 1.02 | P13: 1.01 | Q13: 1 | R13: 0.97 | S13: Factor del mes calendario (1 = mes promedio).
A15: Parámetros
A16: Saldo a cobrar intercompany | B16: US$ | C16: 35114 | D16: Promedio jul–sep 2025. La diferencia de cambio del mes = saldo × variación del TC.
A17: Tasa de impuesto a las ganancias | B17: % | C17: 0.35

Sheet Drivers
A1: Drivers por cartera · lo que proyecta cada supervisor
A2: Volumen: índice real (sep-25 = 100). Recupero y fee en %. Posiciones: operadores en Argentina + posiciones en Paraguay.
A4: Cartera / driver | B4: Unidad | C4: Base sep-25 | D4: oct-25 | E4: nov-25 | F4: dic-25 | G4: ene-26 | H4: feb-26 | I4: mar-26 | J4: abr-26 | K4: may-26 | L4: jun-26 | M4: jul-26 | N4: ago-26 | O4: sep-26 | P4: oct-26 | Q4: nov-26 | R4: dic-26
A5: TMV · Telco Móvil · Temprana (ARS)
A6: Volumen asignado | B6: índice | C6: 100 | D6: 100 | E6: 100 | F6: 100 | G6: 100 | H6: 100 | I6: 100 | J6: 100 | K6: 100 | L6: 100 | M6: 100 | N6: 100 | O6: 100 | P6: 100 | Q6: 100 | R6: 100
A7: % de recupero | B7: % | C7: 0.33665 | D7: 0.33665 | E7: 0.33665 | F7: 0.33665 | G7: 0.33665 | H7: 0.33665 | I7: 0.33665 | J7: 0.33665 | K7: 0.33665 | L7: 0.33665 | M7: 0.33665 | N7: 0.33665 | O7: 0.33665 | P7: 0.33665 | Q7: 0.33665 | R7: 0.33665
A8: Fee | B8: % | C8: 0.068 | D8: 0.068 | E8: 0.068 | F8: 0.068 | G8: 0.068 | H8: 0.068 | I8: 0.068 | J8: 0.068 | K8: 0.068 | L8: 0.068 | M8: 0.068 | N8: 0.068 | O8: 0.068 | P8: 0.068 | Q8: 0.068 | R8: 0.068
A9: Posiciones | B9: n | C9: 30 | D9: 30 | E9: 30 | F9: 30 | G9: 30 | H9: 30 | I9: 30 | J9: 30 | K9: 30 | L9: 30 | M9: 30 | N9: 30 | O9: 30 | P9: 30 | Q9: 30 | R9: 30
A11: TFP · Tarjeta Federal · Prelegal (ARS)
A12: Volumen asignado | B12: índice | C12: 100 | D12: 100 | E12: 100 | F12: 100 | G12: 100 | H12: 100 | I12: 100 | J12: 100 | K12: 100 | L12: 100 | M12: 100 | N12: 100 | O12: 100 | P12: 100 | Q12: 100 | R12: 100
A13: % de recupero | B13: % | C13: 0.16079 | D13: 0.16079 | E13: 0.16079 | F13: 0.16079 | G13: 0.16079 | H13: 0.16079 | I13: 0.16079 | J13: 0.16079 | K13: 0.16079 | L13: 0.16079 | M13: 0.16079 | N13: 0.16079 | O13: 0.16079 | P13: 0.16079 | Q13: 0.16079 | R13: 0.16079
A14: Fee | B14: % | C14: 0.14 | D14: 0.14 | E14: 0.14 | F14: 0.14 | G14: 0.14 | H14: 0.14 | I14: 0.14 | J14: 0.14 | K14: 0.14 | L14: 0.14 | M14: 0.14 | N14: 0.14 | O14: 0.14 | P14: 0.14 | Q14: 0.14 | R14: 0.14
A15: Posiciones | B15: n | C15: 40 | D15: 40 | E15: 40 | F15: 40 | G15: 40 | H15: 40 | I15: 40 | J15: 40 | K15: 40 | L15: 40 | M15: 40 | N15: 40 | O15: 40 | P15: 40 | Q15: 40 | R15: 40
A17: RSM · Retail Sur · Temprana (ARS)
A18: Volumen asignado | B18: índice | C18: 100 | D18: 100 | E18: 100 | F18: 100 | G18: 100 | H18: 100 | I18: 100 | J18: 100 | K18: 100 | L18: 100 | M18: 100 | N18: 100 | O18: 100 | P18: 100 | Q18: 100 | R18: 100
A19: % de recupero | B19: % | C19: 0.39473 | D19: 0.39473 | E19: 0.39473 | F19: 0.39473 | G19: 0.39473 | H19: 0.39473 | I19: 0.39473 | J19: 0.39473 | K19: 0.39473 | L19: 0.39473 | M19: 0.39473 | N19: 0.39473 | O19: 0.39473 | P19: 0.39473 | Q19: 0.39473 | R19: 0.39473
A20: Fee | B20: % | C20: 0.06 | D20: 0.06 | E20: 0.06 | F20: 0.06 | G20: 0.06 | H20: 0.06 | I20: 0.06 | J20: 0.06 | K20: 0.06 | L20: 0.06 | M20: 0.06 | N20: 0.06 | O20: 0.06 | P20: 0.06 | Q20: 0.06 | R20: 0.06
A21: Posiciones | B21: n | C21: 22 | D21: 22 | E21: 22 | F21: 22 | G21: 22 | H21: 22 | I21: 22 | J21: 22 | K21: 22 | L21: 22 | M21: 22 | N21: 22 | O21: 22 | P21: 22 | Q21: 22 | R21: 22
A23: FPG · Fintech Pago · Temprana (ARS)
A24: Volumen asignado | B24: índice | C24: 100 | D24: 100 | E24: 100 | F24: 100 | G24: 100 | H24: 100 | I24: 100 | J24: 100 | K24: 100 | L24: 100 | M24: 100 | N24: 100 | O24: 100 | P24: 100 | Q24: 100 | R24: 100
A25: % de recupero | B25: % | C25: 0.40434 | D25: 0.40434 | E25: 0.40434 | F25: 0.40434 | G25: 0.40434 | H25: 0.40434 | I25: 0.40434 | J25: 0.40434 | K25: 0.40434 | L25: 0.40434 | M25: 0.40434 | N25: 0.40434 | O25: 0.40434 | P25: 0.40434 | Q25: 0.40434 | R25: 0.40434
A26: Fee | B26: % | C26: 0.065 | D26: 0.065 | E26: 0.065 | F26: 0.065 | G26: 0.065 | H26: 0.065 | I26: 0.065 | J26: 0.065 | K26: 0.065 | L26: 0.065 | M26: 0.065 | N26: 0.065 | O26: 0.065 | P26: 0.065 | Q26: 0.065 | R26: 0.065
A27: Posiciones | B27: n | C27: 9 | D27: 9 | E27: 9 | F27: 9 | G27: 9 | H27: 9 | I27: 9 | J27: 9 | K27: 9 | L27: 9 | M27: 9 | N27: 9 | O27: 9 | P27: 9 | Q27: 9 | R27: 9
A29: GNM · Gas Natural · Masiva (ARS)
A30: Volumen asignado | B30: índice | C30: 100 | D30: 100 | E30: 100 | F30: 100 | G30: 100 | H30: 100 | I30: 100 | J30: 100 | K30: 100 | L30: 100 | M30: 100 | N30: 100 | O30: 100 | P30: 100 | Q30: 100 | R30: 100
A31: % de recupero | B31: % | C31: 0.3081 | D31: 0.3081 | E31: 0.3081 | F31: 0.3081 | G31: 0.3081 | H31: 0.3081 | I31: 0.3081 | J31: 0.3081 | K31: 0.3081 | L31: 0.3081 | M31: 0.3081 | N31: 0.3081 | O31: 0.3081 | P31: 0.3081 | Q31: 0.3081 | R31: 0.3081
A32: Fee | B32: % | C32: 0.055 | D32: 0.055 | E32: 0.055 | F32: 0.055 | G32: 0.055 | H32: 0.055 | I32: 0.055 | J32: 0.055 | K32: 0.055 | L32: 0.055 | M32: 0.055 | N32: 0.055 | O32: 0.055 | P32: 0.055 | Q32: 0.055 | R32: 0.055
A33: Posiciones | B33: n | C33: 6 | D33: 6 | E33: 6 | F33: 6 | G33: 6 | H33: 6 | I33: 6 | J33: 6 | K33: 6 | L33: 6 | M33: 6 | N33: 6 | O33: 6 | P33: 6 | Q33: 6 | R33: 6
A35: CFM · Cable & Fibra · Masiva (ARS)
A36: Volumen asignado | B36: índice | C36: 100 | D36: 100 | E36: 100 | F36: 100 | G36: 100 | H36: 100 | I36: 100 | J36: 100 | K36: 100 | L36: 100 | M36: 100 | N36: 100 | O36: 100 | P36: 100 | Q36: 100 | R36: 100
A37: % de recupero | B37: % | C37: 0.27384 | D37: 0.27384 | E37: 0.27384 | F37: 0.27384 | G37: 0.27384 | H37: 0.27384 | I37: 0.27384 | J37: 0.27384 | K37: 0.27384 | L37: 0.27384 | M37: 0.27384 | N37: 0.27384 | O37: 0.27384 | P37: 0.27384 | Q37: 0.27384 | R37: 0.27384
A38: Fee | B38: % | C38: 0.06 | D38: 0.06 | E38: 0.06 | F38: 0.06 | G38: 0.06 | H38: 0.06 | I38: 0.06 | J38: 0.06 | K38: 0.06 | L38: 0.06 | M38: 0.06 | N38: 0.06 | O38: 0.06 | P38: 0.06 | Q38: 0.06 | R38: 0.06
A39: Posiciones | B39: n | C39: 6 | D39: 6 | E39: 6 | F39: 6 | G39: 6 | H39: 6 | I39: 6 | J39: 6 | K39: 6 | L39: 6 | M39: 6 | N39: 6 | O39: 6 | P39: 6 | Q39: 6 | R39: 6
A41: PUY · Préstamos Uruguay · Temprana (USD)
A42: Volumen asignado | B42: índice | C42: 100 | D42: 100 | E42: 100 | F42: 100 | G42: 100 | H42: 100 | I42: 100 | J42: 100 | K42: 100 | L42: 100 | M42: 100 | N42: 100 | O42: 100 | P42: 100 | Q42: 100 | R42: 100
A43: % de recupero | B43: % | C43: 0.40762 | D43: 0.40762 | E43: 0.40762 | F43: 0.40762 | G43: 0.40762 | H43: 0.40762 | I43: 0.40762 | J43: 0.40762 | K43: 0.40762 | L43: 0.40762 | M43: 0.40762 | N43: 0.40762 | O43: 0.40762 | P43: 0.40762 | Q43: 0.40762 | R43: 0.40762
A44: Fee | B44: % | C44: 0.09 | D44: 0.09 | E44: 0.09 | F44: 0.09 | G44: 0.09 | H44: 0.09 | I44: 0.09 | J44: 0.09 | K44: 0.09 | L44: 0.09 | M44: 0.09 | N44: 0.09 | O44: 0.09 | P44: 0.09 | Q44: 0.09 | R44: 0.09
A45: Posiciones | B45: n | C45: 4 | D45: 4 | E45: 4 | F45: 4 | G45: 4 | H45: 4 | I45: 4 | J45: 4 | K45: 4 | L45: 4 | M45: 4 | N45: 4 | O45: 4 | P45: 4 | Q45: 4 | R45: 4
A47: TUY · Telco Uruguay · Temprana (USD)
A48: Volumen asignado | B48: índice | C48: 100 | D48: 100 | E48: 100 | F48: 100 | G48: 100 | H48: 100 | I48: 100 | J48: 100 | K48: 100 | L48: 100 | M48: 100 | N48: 100 | O48: 100 | P48: 100 | Q48: 100 | R48: 100
...

Sheet Cálculo
A1: Cálculo por cartera y línea
A2: Cada celda = base mensual × índices de la categoría. No se carga nada acá.
A4: Ámbito | B4: Moneda | C4: N1 | D4: N2 | E4: Ítem | F4: Categoría | G4: Base mensual sep-25 ($) | H4: oct-25 | I4: nov-25 | J4: dic-25 | K4: ene-26 | L4: feb-26 | M4: mar-26 | N4: abr-26 | O4: may-26 | P4: jun-26 | Q4: jul-26 | R4: ago-26 | S4: sep-26 | T4: oct-26 | U4: nov-26 | V4: dic-26
A5: TMV | B5: ARS | C5: 1 Ingreso Operacional | D5: 1.1 Ingreso Cobranzas | E5: Ingreso por recupero | F5: rev | G5: 1.1849142e+08 | H5: =$G5*Supuestos!D$6*(Drivers!D$6/100)*(Drivers!D$7/Drivers!$C$7)*(Drivers!D$8/Drivers!$C$8)*Supuestos!D$13 | I5: =$G5*Supuestos!E$6*(Drivers!E$6/100)*(Drivers!E$7/Drivers!$C$7)*(Drivers!E$8/Drivers!$C$8)*Supuestos!E$13 | J5: =$G5*Supuestos!F$6*(Drivers!F$6/100)*(Drivers!F$7/Drivers!$C$7)*(Drivers!F$8/Drivers!$C$8)*Supuestos!F$13 | K5: =$G5*Supuestos!G$6*(Drivers!G$6/100)*(Drivers!G$7/Drivers!$C$7)*(Drivers!G$8/Drivers!$C$8)*Supuestos!G$13 | L5: =$G5*Supuestos!H$6*(Drivers!H$6/100)*(Drivers!H$7/Drivers!$C$7)*(Drivers!H$8/Drivers!$C$8)*Supuestos!H$13 | M5: =$G5*Supuestos!I$6*(Drivers!I$6/100)*(Drivers!I$7/Drivers!$C$7)*(Drivers!I$8/Drivers!$C$8)*Supuestos!I$13 | N5: =$G5*Supuestos!J$6*(Drivers!J$6/100)*(Drivers!J$7/Drivers!$C$7)*(Drivers!J$8/Drivers!$C$8)*Supuestos!J$13 | O5: =$G5*Supuestos!K$6*(Drivers!K$6/100)*(Drivers!K$7/Drivers!$C$7)*(Drivers!K$8/Drivers!$C$8)*Supuestos!K$13 | ... V5: =$G5*Supuestos!R$6*(Drivers!R$6/100)*(Drivers!R$7/Drivers!$C$7)*(Drivers!R$8/Drivers!$C$8)*Supuestos!R$13
A6: TMV | B6: ARS | C6: 2 Costos de Explotación | D6: 2.1 Remuneraciones | E6: Operadores | F6: pos_sal | G6: -19388811 | H6: =$G6*Supuestos!D$10*(Drivers!D$9/Drivers!$C$9) | I6: =$G6*Supuestos!E$10*(Drivers!E$9/Drivers!$C$9) | J6: =$G6*Supuestos!F$10*(Drivers!F$9/Drivers!$C$9) | K6: =$G6*Supuestos!G$10*(Drivers!G$9/Drivers!$C$9) | L6: =$G6*Supuestos!H$10*(Drivers!H$9/Drivers!$C$9) | M6: =$G6*Supuestos!I$10*(Drivers!I$9/Drivers!$C$9) | N6: =$G6*Supuestos!J$10*(Drivers!J$9/Drivers!$C$9) | O6: =$G6*Supuestos!K$10*(Drivers!K$9/Drivers!$C$9) | ... V6: =$G6*Supuestos!R$10*(Drivers!R$9/Drivers!$C$9)
A7: TMV | B7: ARS | C7: 2 Costos de Explotación | D7: 2.1 Remuneraciones | E7: Supervisión | F7: pos_sal | G7: -4170292 | H7: =$G7*Supuestos!D$10*(Drivers!D$9/Drivers!$C$9) | I7: =$G7*Supuestos!E$10*(Drivers!E$9/Drivers!$C$9) | J7: =$G7*Supuestos!F$10*(Drivers!F$9/Drivers!$C$9) | K7: =$G7*Supuestos!G$10*(Drivers!G$9/Drivers!$C$9) | L7: =$G7*Supuestos!H$10*(Drivers!H$9/Drivers!$C$9) | M7: =$G7*Supuestos!I$10*(Drivers!I$9/Drivers!$C$9) | N7: =$G7*Supuestos!J$10*(Drivers!J$9/Drivers!$C$9) | O7: =$G7*Supuestos!K$10*(Drivers!K$9/Drivers!$C$9) | ... V7: =$G7*Supuestos!R$10*(Drivers!R$9/Drivers!$C$9)
A8: TMV | B8: ARS | C8: 2 Costos de Explotación | D8: 2.1 Remuneraciones | E8: Calidad | F8: pos_sal | G8: -986520.95 | H8: =$G8*Supuestos!D$10*(Drivers!D$9/Drivers!$C$9) | I8: =$G8*Supuestos!E$10*(Drivers!E$9/Drivers!$C$9) | J8: =$G8*Supuestos!F$10*(Drivers!F$9/Drivers!$C$9) | K8: =$G8*Supuestos!G$10*(Drivers!G$9/Drivers!$C$9) | L8: =$G8*Supuestos!H$10*(Drivers!H$9/Drivers!$C$9) | M8: =$G8*Supuestos!I$10*(Drivers!I$9/Drivers!$C$9) | N8: =$G8*Supuestos!J$10*(Drivers!J$9/Drivers!$C$9) | O8: =$G8*Supuestos!K$10*(Drivers!K$9/Drivers!$C$9) | ... V8: =$G8*Supuestos!R$10*(Drivers!R$9/Drivers!$C$9)
A9: TMV | B9: ARS | C9: 2 Costos de Explotación | D9: 2.1 Remuneraciones | E9: Back Office | F9: pos_sal | G9: -672628.03 | H9: =$G9*Supuestos!D$10*(Drivers!D$9/Drivers!$C$9) | I9: =$G9*Supuestos!E$10*(Drivers!E$9/Drivers!$C$9) | J9: =$G9*Supuestos!F$10*(Drivers!F$9/Drivers!$C$9) | K9: =$G9*Supuestos!G$10*(Drivers!G$9/Drivers!$C$9) | L9: =$G9*Supuestos!H$10*(Drivers!H$9/Drivers!$C$9) | M9: =$G9*Supuestos!I$10*(Drivers!I$9/Drivers!$C$9) | N9: =$G9*Supuestos!J$10*(Drivers!J$9/Drivers!$C$9) | O9: =$G9*Supuestos!K$10*(Drivers!K$9/Drivers!$C$9) | ... V9: =$G9*Supuestos!R$10*(Drivers!R$9/Drivers!$C$9)
A10: TMV | B10: ARS | C10: 2 Costos de Explotación | D10: 2.1 Remuneraciones | E10: Ejecutivos de cuenta | F10: pos_sal | G10: -1277993.1 | H10: =$G10*Supuestos!D$10*(Drivers!D$9/Drivers!$C$9) | I10: =$G10*Supuestos!E$10*(Drivers!E$9/Drivers!$C$9) | J10: =$G10*Supuestos!F$10*(Drivers!F$9/Drivers!$C$9) | K10: =$G10*Supuestos!G$10*(Drivers!G$9/Drivers!$C$9) | L10: =$G10*Supuestos!H$10*(Drivers!H$9/Drivers!$C$9) | M10: =$G10*Supuestos!I$10*(Drivers!I$9/Drivers!$C$9) | N10: =$G10*Supuestos!J$10*(Drivers!J$9/Drivers!$C$9) | O10: =$G10*Supuestos!K$10*(Drivers!K$9/Drivers!$C$9) | ... V10: =$G10*Supuestos!R$10*(Drivers!R$9/Drivers!$C$9)
A11: TMV | B11: ARS | C11: 2 Costos de Explotación | D11: 2.1 Remuneraciones | E11: Gerencia de Operaciones | F11: pos_sal | G11: -1434939.4 | H11: =$G11*Supuestos!D$10*(Drivers!D$9/Drivers!$C$9) | I11: =$G11*Supuestos!E$10*(Drivers!E$9/Drivers!$C$9) | J11: =$G11*Supuestos!F$10*(Drivers!F$9/Drivers!$C$9) | K11: =$G11*Supuestos!G$10*(Drivers!G$9/Drivers!$C$9) | L11: =$G11*Supuestos!H$10*(Drivers!H$9/Drivers!$C$9) | M11: =$G11*Supuestos!I$10*(Drivers!I$9/Drivers!$C$9) | N11: =$G11*Supuestos!J$10*(Drivers!J$9/Drivers!$C$9) | O11: =$G11*Supuestos!K$10*(Drivers!K$9/Drivers!$C$9) | ... V11: =$G11*Supuestos!R$10*(Drivers!R$9/Drivers!$C$9)
A12: TMV | B12: ARS | C12: 2 Costos de Explotación | D12: 2.1 Remuneraciones | E12: Indemnizaciones | F12: zero | G12: -225265.47 | H12: =0 | I12: =0 | J12: =0 | K12: =0 | L12: =0 | M12: =0 | N12: =0 | O12: =0 | ... V12: =0
A13: TMV | B13: ARS | C13: 2 Costos de Explotación | D13: 2.2 Servicios de Terceros | E13: Posiciones Paraguay | F13: pos_usd | G13: -7098000 | H13: =$G13*Supuestos!D$8*(Drivers!D$9/Drivers!$C$9) | I13: =$G13*Supuestos!E$8*(Drivers!E$9/Drivers!$C$9) | J13: =$G13*Supuestos!F$8*(Drivers!F$9/Drivers!$C$9) | K13: =$G13*Supuestos!G$8*(Drivers!G$9/Drivers!$C$9) | L13: =$G13*Supuestos!H$8*(Drivers!H$9/Drivers!$C$9) | M13: =$G13*Supuestos!I$8*(Drivers!I$9/Drivers!$C$9) | N13: =$G13*Supuestos!J$8*(Drivers!J$9/Drivers!$C$9) | O13: =$G13*Supuestos!K$8*(Drivers!K$9/Drivers!$C$9) | ... V13: =$G13*Supuestos!R$8*(Drivers!R$9/Drivers!$C$9)
A14: TMV | B14: ARS | C14: 2 Costos de Explotación | D14: 2.3 Licencias | E14: Licencias discador/CRM | F14: pos_usd | G14: -1842750 | H14: =$G14*Supuestos!D$8*(Drivers!D$9/Drivers!$C$9) | I14: =$G14*Supuestos!E$8*(Drivers!E$9/Drivers!$C$9) | J14: =$G14*Supuestos!F$8*(Drivers!F$9/Drivers!$C$9) | K14: =$G14*Supuestos!G$8*(Drivers!G$9/Drivers!$C$9) | L14: =$G14*Supuestos!H$8*(Drivers!H$9/Drivers!$C$9) | M14: =$G14*Supuestos!I$8*(Drivers!I$9/Drivers!$C$9) | N14: =$G14*Supuestos!J$8*(Drivers!J$9/Drivers!$C$9) | O14: =$G14*Supuestos!K$8*(Drivers!K$9/Drivers!$C$9) | ... V14: =$G14*Supuestos!R$8*(Drivers!R$9/Drivers!$C$9)
A15: TMV | B15: ARS | C15: 2 Costos de Explotación | D15: 2.5 Telefonía | E15: Telefonía celular | F15: pos_inf | G15: -1202037 | H15: =$G15*Supuestos!D$6*(Drivers!D$9/Drivers!$C$9) | I15: =$G15*Supuestos!E$6*(Drivers!E$9/Drivers!$C$9) | J15: =$G15*Supuestos!F$6*(Drivers!F$9/Drivers!$C$9) | K15: =$G15*Supuestos!G$6*(Drivers!G$9/Drivers!$C$9) | L15: =$G15*Supuestos!H$6*(Drivers!H$9/Drivers!$C$9) | M15: =$G15*Supuestos!I$6*(Drivers!I$9/Drivers!$C$9) | N15: =$G15*Supuestos!J$6*(Drivers!J$9/Drivers!$C$9) | O15: =$G15*Supuestos!K$6*(Drivers!K$9/Drivers!$C$9) | ... V15: =$G15*Supuestos!R$6*(Drivers!R$9/Drivers!$C$9)
A16: TMV | B16: ARS | C16: 2 Costos de Explotación | D16: 2.5 Telefonía | E16: Telefonía LDN | F16: pos_inf | G16: -309095.1 | H16: =$G16*Supuestos!D$6*(Drivers!D$9/Drivers!$C$9) | I16: =$G16*Supuestos!E$6*(Drivers!E$9/Drivers!$C$9) | J16: =$G16*Supuestos!F$6*(Drivers!F$9/Drivers!$C$9) | K16: =$G16*Supuestos!G$6*(Drivers!G$9/Drivers!$C$9) | L16: =$G16*Supuestos!H$6*(Drivers!H$9/Drivers!$C$9) | M16: =$G16*Supuestos!I$6*(Drivers!I$9/Drivers!$C$9) | N16: =$G16*Supuestos!J$6*(Drivers!J$9/Drivers!$C$9) | O16: =$G16*Supuestos!K$6*(Drivers!K$9/Drivers!$C$9) | ... V16: =$G16*Supuestos!R$6*(Drivers!R$9/Drivers!$C$9)
A17: TMV | B17: ARS | C17: 2 Costos de Explotación | D17: 2.5 Telefonía | E17: Telefonía local y 0800 | F17: pos_inf | G17: -206063.51 | H17: =$G17*Supuestos!D$6*(Drivers!D$9/Drivers!$C$9) | I17: =$G17*Supuestos!E$6*(Drivers!E$9/Drivers!$C$9) | J17: =$G17*Supuestos!F$6*(Drivers!F$9/Drivers!$C$9) | K17: =$G17*Supuestos!G$6*(Drivers!G$9/Drivers!$C$9) | L17: =$G17*Supuestos!H$6*(Drivers!H$9/Drivers!$C$9) | M17: =$G17*Supuestos!I$6*(Drivers!I$9/Drivers!$C$9) | N17: =$G17*Supuestos!J$6*(Drivers!J$9/Drivers!$C$9) | O17: =$G17*Supuestos!K$6*(Drivers!K$9/Drivers!$C$9) | ... V17: =$G17*Supuestos!R$6*(Drivers!R$9/Drivers!$C$9)
A18: TMV | B18: ARS | C18: 2 Costos de Explotación | D18: 2.6 SMS | E18: SMS | F18: sms | G18: -1994875.3 | H18: =$G18*Supuestos!D$12*(Drivers!D$6/100) | I18: =$G18*Supuestos!E$12*(Drivers!E$6/100) | J18: =$G18*Supuestos!F$12*(Drivers!F$6/100) | K18: =$G18*Supuestos!G$12*(Drivers!G$6/100) | L18: =$G18*Supuestos!H$12*(Drivers!H$6/100) | M18: =$G18*Supuestos!I$12*(Drivers!I$6/100) | N18: =$G18*Supuestos!J$12*(Drivers!J$6/100) | O18: =$G18*Supuestos!K$12*(Drivers!K$6/100) | ... V18: =$G18*Supuestos!R$12*(Drivers!R$6/100)
A19: TMV | B19: ARS | C19: 2 Costos de Explotación | D19: 2.7 Bocas de Cobranza | E19: Bocas de cobranza | F19: vol_inf | G19: -1226593.6 | H19: =$G19*Supuestos!D$6*(Drivers!D$6/100) | I19: =$G19*Supuestos!E$6*(Drivers!E$6/100) | J19: =$G19*Supuestos!F$6*(Drivers!F$6/100) | K19: =$G19*Supuestos!G$6*(Drivers!G$6/100) | L19: =$G19*Supuestos!H$6*(Drivers!H$6/100) | M19: =$G19*Supuestos!I$6*(Drivers!I$6/100) | N19: =$G19*Supuestos!J$6*(Drivers!J$6/100) | O19: =$G19*Supuestos!K$6*(Drivers!K$6/100) | ... V19: =$G19*Supuestos!R$6*(Drivers!R$6/100)
A20: TMV | B20: ARS | C20: 2 Costos de Explotación | D20: 2.8 Mailing | E20: Mailing | F20: vol_usd | G20: -643879.8 | H20: =$G20*Supuestos!D$8*(Drivers!D$6/100) | I20: =$G20*Supuestos!E$8*(Drivers!E$6/100) | J20: =$G20*Supuestos!F$8*(Drivers!F$6/100) | K20: =$G20*Supuestos!G$8*(Drivers!G$6/100) | L20: =$G20*Supuestos!H$8*(Drivers!H$6/100) | M20: =$G20*Supuestos!I$8*(Drivers!I$6/100) | N20: =$G20*Supuestos!J$8*(Drivers!J$6/100) | O20: =$G20*Supuestos!K$8*(Drivers!K$6/100) | ... V20: =$G20*Supuestos!R$8*(Drivers!R$6/100)
A21: TMV | B21: ARS | C21: 2 Costos de Explotación | D21: 2.9 Informes Comerciales | E21: Informes comerciales | F21: vol_inf | G21: -247024.83 | H21: =$G21*Supuestos!D$6*(Drivers!D$6/100) | I21: =$G21*Supuestos!E$6*(Drivers!E$6/100) | J21: =$G21*Supuestos!F$6*(Drivers!F$6/100) | K21: =$G21*Supuestos!G$6*(Drivers!G$6/100) | L21: =$G21*Supuestos!H$6*(Drivers!H$6/100) | M21: =$G21*Supuestos!I$6*(Drivers!I$6/100) | N21: =$G21*Supuestos!J$6*(Drivers!J$6/100) | O21: =$G21*Supuestos!K$6*(Drivers!K$6/100) | ... V21: =$G21*Supuestos!R$6*(Drivers!R$6/100)
A22: TMV | B22: ARS | C22: 2 Costos de Explotación | D22: 2.12 WhatsApp | E22: WhatsApp | F22: vol_usd | G22: -552825 | H22: =$G22*Supuestos!D$8*(Drivers!D$6/100) | I22: =$G22*Supuestos!E$8*(Drivers!E$6/100) | J22: =$G22*Supuestos!F$8*(Drivers!F$6/100) | K22: =$G22*Supuestos!G$8*(Drivers!G$6/100) | L22: =$G22*Supuestos!H$8*(Drivers!H$6/100) | M22: =$G22*Supuestos!I$8*(Drivers!I$6/100) | N22: =$G22*Supuestos!J$8*(Drivers!J$6/100) | O22: =$G22*Supuestos!K$8*(Drivers!K$6/100) | ... V22: =$G22*Supuestos!R$8*(Drivers!R$6/100)
A23: TMV | B23: ARS | C23: 3 Impuestos Directos | D23: 3.1 Ingresos Brutos | E23: Ingresos Brutos | F23: iibb | G23: -3554742.6 | H23: =$G23*Supuestos!D$6*(Drivers!D$6/100)*(Drivers!D$7/Drivers!$C$7)*(Drivers!D$8/Drivers!$C$8)*Supuestos!D$13 | I23: =$G23*Supuestos!E$6*(Drivers!E$6/100)*(Drivers!E$7/Drivers!$C$7)*(Drivers!E$8/Drivers!$C$8)*Supuestos!E$13 | J23: =$G23*Supuestos!F$6*(Drivers!F$6/100)*(Drivers!F$7/Drivers!$C$7)*(Drivers!F$8/Drivers!$C$8)*Supuestos!F$13 | K23: =$G23*Supuestos!G$6*(Drivers!G$6/100)*(Drivers!G$7/Drivers!$C$7)*(Drivers!G$8/Drivers!$C$8)*Supuestos!G$13 | L23: =$G23*Supuestos!H$6*(Drivers!H$6/100)*(Drivers!H$7/Drivers!$C$7)*(Drivers!H$8/Drivers!$C$8)*Supuestos!H$13 | M23: =$G23*Supuestos!I$6*(Drivers!I$6/100)*(Drivers!I$7/Drivers!$C$7)*(Drivers!I$8/Drivers!$C$8)*Supuestos!I$13 | N23: =$G23*Supuestos!J$6*(Drivers!J$6/100)*(Drivers!J$7/Drivers!$C$7)*(Drivers!J$8/Drivers!$C$8)*Supuestos!J$13 | O23: =$G23*Supuestos!K$6*(Drivers!K$6/100)*(Drivers!K$7/Drivers!$C$7)*(Drivers!K$8/Drivers!$C$8)*Supuestos!K$13 | ... V23: =$G23*Supuestos!R$6*(Drivers!R$6/100)*(Drivers!R$7/Drivers!$C$7)*(Drivers!R$8/Drivers!$C$8)*Supuestos!R$13
A24: TFP | B24: ARS | C24: 1 Ingreso Operacional | D24: 1.1 Ingreso Cobranzas | E24: Ingreso por recupero | F24: rev | G24: 69579411 | H24: =$G24*Supuestos!D$6*(Drivers!D$12/100)*(Drivers!D$13/Drivers!$C$13)*(Drivers!D$14/Drivers!$C$14)*Supuestos!D$13 | I24: =$G24*Supuestos!E$6*(Drivers!E$12/100)*(Drivers!E$13/Drivers!$C$13)*(Drivers!E$14/Drivers!$C$14)*Supuestos!E$13 | J24: =$G24*Supuestos!F$6*(Drivers!F$12/100)*(Drivers!F$13/Drivers!$C$13)*(Drivers!F$14/Drivers!$C$14)*Supuestos!F$13 | K24: =$G24*Supuestos!G$6*(Drivers!G$12/100)*(Drivers!G$13/Drivers!$C$13)*(Drivers!G$14/Drivers!$C$14)*Supuestos!G$13 | L24: =$G24*Supuestos!H$6*(Drivers!H$12/100)*(Drivers!H$13/Drivers!$C$13)*(Drivers!H$14/Drivers!$C$14)*Supuestos!H$13 | M24: =$G24*Supuestos!I$6*(Drivers!I$12/100)*(Drivers!I$13/Drivers!$C$13)*(Drivers!I$14/Drivers!$C$14)*Supuestos!I$13 | N24: =$G24*Supuestos!J$6*(Drivers!J$12/100)*(Drivers!J$13/Drivers!$C$13)*(Drivers!J$14/Drivers!$C$14)*Supuestos!J$13 | O24: =$G24*Supuestos!K$6*(Drivers!K$12/100)*(Drivers!K$13/Drivers!$C$13)*(Drivers!K$14/Drivers!$C$14)*Supuestos!K$13 | ... V24: =$G24*Supuestos!R$6*(Drivers!R$12/100)*(Drivers!R$13/Drivers!$C$13)*(Drivers!R$14/Drivers!$C$14)*Supuestos!R$13
A25: TFP | B25: ARS | C25: 2 Costos de Explotación | D25: 2.1 Remuneraciones | E25: Operadores | F25: pos_sal | G25: -15908856 | H25: =$G25*Supuestos!D$10*(Drivers!D$15/Drivers!$C$15) | I25: =$G25*Supuestos!E$10*(Drivers!E$15/Drivers!$C$15) | J25: =$G25*Supuestos!F$10*(Drivers!F$15/Drivers!$C$15) | K25: =$G25*Supuestos!G$10*(Drivers!G$15/Drivers!$C$15) | L25: =$G25*Supuestos!H$10*(Drivers!H$15/Drivers!$C$15) | M25: =$G25*Supuestos!I$10*(Drivers!I$15/Drivers!$C$15) | N25: =$G25*Supuestos!J$10*(Drivers!J$15/Drivers!$C$15) | O25: =$G25*Supuestos!K$10*(Drivers!K$15/Drivers!$C$15) | ... V25: =$G25*Supuestos!R$10*(Drivers!R$15/Drivers!$C$15)
A26: TFP | B26: ARS | C26: 2 Costos de Explotación | D26: 2.1 Remuneraciones | E26: Supervisión | F26: pos_sal | G26: -5560389.6 | H26: =$G26*Supuestos!D$10*(Drivers!D$15/Drivers!$C$15) | I26: =$G26*Supuestos!E$10*(Drivers!E$15/Drivers!$C$15) | J26: =$G26*Supuestos!F$10*(Drivers!F$15/Drivers!$C$15) | K26: =$G26*Supuestos!G$10*(Drivers!G$15/Drivers!$C$15) | L26: =$G26*Supuestos!H$10*(Drivers!H$15/Drivers!$C$15) | M26: =$G26*Supuestos!I$10*(Drivers!I$15/Drivers!$C$15) | N26: =$G26*Supuestos!J$10*(Drivers!J$15/Drivers!$C$15) | O26: =$G26*Supuestos!K$10*(Drivers!K$15/Drivers!$C$15) | ... V26: =$G26*Supuestos!R$10*(Drivers!R$15/Drivers!$C$15)
A27: TFP | B27: ARS | C27: 2 Costos de Explotación | D27: 2.1 Remuneraciones | E27: Calidad | F27: pos_sal | G27: -1315361.1 | H27: =$G27*Supuestos!D$10*(Drivers!D$15/Drivers!$C$15) | I27: =$G27*Supuestos!E$10*(Drivers!E$15/Drivers!$C$15) | J27: =$G27*Supuestos!F$10*(Drivers!F$15/Drivers!$C$15) | K27: =$G27*Supuestos!G$10*(Drivers!G$15/Drivers!$C$15) | L27: =$G27*Supuestos!H$10*(Drivers!H$15/Drivers!$C$15) | M27: =$G27*Supuestos!I$10*(Drivers!I$15/Drivers!$C$15) | N27: =$G27*Supuestos!J$10*(Drivers!J$15/Drivers!$C$15) | O27: =$G27*Supuestos!K$10*(Drivers!K$15/Drivers!$C$15) | ... V27: =$G27*Supuestos!R$10*(Drivers!R$15/Drivers!$C$15)
A28: TFP | B28: ARS | C28: 2 Costos de Explotación | D28: 2.1 Remuneraciones | E28: Back Office | F28: pos_sal | G28: -896837.27 | H28: =$G28*Supuestos!D$10*(Drivers!D$15/Drivers!$C$15) | I28: =$G28*Supuestos!E$10*(Drivers!E$15/Drivers!$C$15) | J28: =$G28*Supuestos!F$10*(Drivers!F$15/Drivers!$C$15) | K28: =$G28*Supuestos!G$10*(Drivers!G$15/Drivers!$C$15) | L28: =$G28*Supuestos!H$10*(Drivers!H$15/Drivers!$C$15) | M28: =$G28*Supuestos!I$10*(Drivers!I$15/Drivers!$C$15) | N28: =$G28*Supuestos!J$10*(Drivers!J$15/Drivers!$C$15) | O28: =$G28*Supuestos!K$10*(Drivers!K$15/Drivers!$C$15) | ... V28: =$G28*Supuestos!R$10*(Drivers!R$15/Drivers!$C$15)
A29: TFP | B29: ARS | C29: 2 Costos de Explotación | D29: 2.1 Remuneraciones | E29: Ejecutivos de cuenta | F29: pos_sal | G29: -1703990.2 | H29: =$G29*Supuestos!D$10*(Drivers!D$15/Drivers!$C$15) | I29: =$G29*Supuestos!E$10*(Drivers!E$15/Drivers!$C$15) | J29: =$G29*Supuestos!F$10*(Drivers!F$15/Drivers!$C$15) | K29: =$G29*Supuestos!G$10*(Drivers!G$15/Drivers!$C$15) | L29: =$G29*Supuestos!H$10*(Drivers!H$15/Drivers!$C$15) | M29: =$G29*Supuestos!I$10*(Drivers!I$15/Drivers!$C$15) | N29: =$G29*Supuestos!J$10*(Drivers!J$15/Drivers!$C$15) | O29: =$G29*Supuestos!K$10*(Drivers!K$15/Drivers!$C$15) | ... V29: =$G29*Supuestos!R$10*(Drivers!R$15/Drivers!$C$15)
A30: TFP | B30: ARS | C30: 2 Costos de Explotación | D30: 2.1 Remuneraciones | E30: Gerencia de Operaciones | F30: pos_sal | G30: -1913252.2 | H30: =$G30*Supuestos!D$10*(Drivers!D$15/Drivers!$C$15) | I30: =$G30*Supuestos!E$10*(Drivers!E$15/Drivers!$C$15) | J30: =$G30*Supuestos!F$10*(Drivers!F$15/Drivers!$C$15) | K30: =$G30*Supuestos!G$10*(Drivers!G$15/Drivers!$C$15) | L30: =$G30*Supuestos!H$10*(Drivers!H$15/Drivers!$C$15) | M30: =$G30*Supuestos!I$10*(Drivers!I$15/Drivers!$C$15) | N30: =$G30*Supuestos!J$10*(Drivers!J$15/Drivers!$C$15) | O30: =$G30*Supuestos!K$10*(Drivers!K$15/Drivers!$C$15) | ... V30: =$G30*Supuestos!R$10*(Drivers!R$15/Drivers!$C$15)
A31: TFP | B31: ARS | C31: 2 Costos de Explotación | D31: 2.1 Remuneraciones | E31: Indemnizaciones | F31: zero | G31: -300353.85 | H31: =0 | I31: =0 | J31: =0 | K31: =0 | L31: =0 | M31: =0 | N31: =0 | O31: =0 | ... V31: =0
A32: TFP | B32: ARS | C32: 2 Costos de Explotación | D32: 2.2 Servicios de Terceros | E32: Posiciones Paraguay | F32: pos_usd | G32: -19519500 | H32: =$G32*Supuestos!D$8*(Drivers!D$15/Drivers!$C$15) | I32: =$G32*Supuestos!E$8*(Drivers!E$15/Drivers!$C$15) | J32: =$G32*Supuestos!F$8*(Drivers!F$15/Drivers!$C$15) | K32: =$G32*Supuestos!G$8*(Drivers!G$15/Drivers!$C$15) | L32: =$G32*Supuestos!H$8*(Drivers!H$15/Drivers!$C$15) | M32: =$G32*Supuestos!I$8*(Drivers!I$15/Drivers!$C$15) | N32: =$G32*Supuestos!J$8*(Drivers!J$15/Drivers!$C$15) | O32: =$G32*Supuestos!K$8*(Drivers!K$15/Drivers!$C$15) | ... V32: =$G32*Supuestos!R$8*(Drivers!R$15/Drivers!$C$15)
A33: TFP | B33: ARS | C33: 2 Costos de Explotación | D33: 2.3 Licencias | E33: Licencias discador/CRM | F33: pos_usd | G33: -2457000 | H33: =$G33*Supuestos!D$8*(Drivers!D$15/Drivers!$C$15) | I33: =$G33*Supuestos!E$8*(Drivers!E$15/Drivers!$C$15) | J33: =$G33*Supuestos!F$8*(Drivers!F$15/Drivers!$C$15) | K33: =$G33*Supuestos!G$8*(Drivers!G$15/Drivers!$C$15) | L33: =$G33*Supuestos!H$8*(Drivers!H$15/Drivers!$C$15) | M33: =$G33*Supuestos!I$8*(Drivers!I$15/Drivers!$C$15) | N33: =$G33*Supuestos!J$8*(Drivers!J$15/Drivers!$C$15) | O33: =$G33*Supuestos!K$8*(Drivers!K$15/Drivers!$C$15) | ... V33: =$G33*Supuestos!R$8*(Drivers!R$15/Drivers!$C$15)
A34: TFP | B34: ARS | C34: 2 Costos de Explotación | D34: 2.5 Telefonía | E34: Telefonía celular | F34: pos_inf | G34: -1688555.4 | H34: =$G34*Supuestos!D$6*(Drivers!D$15/Drivers!$C$15) | I34: =$G34*Supuestos!E$6*(Drivers!E$15/Drivers!$C$15) | J34: =$G34*Supuestos!F$6*(Drivers!F$15/Drivers!$C$15) | K34: =$G34*Supuestos!G$6*(Drivers!G$15/Drivers!$C$15) | L34: =$G34*Supuestos!H$6*(Drivers!H$15/Drivers!$C$15) | M34: =$G34*Supuestos!I$6*(Drivers!I$15/Drivers!$C$15) | N34: =$G34*Supuestos!J$6*(Drivers!J$15/Drivers!$C$15) | O34: =$G34*Supuestos!K$6*(Drivers!K$15/Drivers!$C$15) | ... V34: =$G34*Supuestos!R$6*(Drivers!R$15/Drivers!$C$15)
A35: TFP | B35: ARS | C35: 2 Costos de Explotación | D35: 2.5 Telefonía | E35: Telefonía LDN | F35: pos_inf | G35: -434200.01 | H35: =$G35*Supuestos!D$6*(Drivers!D$15/Drivers!$C$15) | I35: =$G35*Supuestos!E$6*(Drivers!E$15/Drivers!$C$15) | J35: =$G35*Supuestos!F$6*(Drivers!F$15/Drivers!$C$15) | K35: =$G35*Supuestos!G$6*(Drivers!G$15/Drivers!$C$15) | L35: =$G35*Supuestos!H$6*(Drivers!H$15/Drivers!$C$15) | M35: =$G35*Supuestos!I$6*(Drivers!I$15/Drivers!$C$15) | N35: =$G35*Supuestos!J$6*(Drivers!J$15/Drivers!$C$15) | O35: =$G35*Supuestos!K$6*(Drivers!K$15/Drivers!$C$15) | ... V35: =$G35*Supuestos!R$6*(Drivers!R$15/Drivers!$C$15)
A36: TFP | B36: ARS | C36: 2 Costos de Explotación | D36: 2.5 Telefonía | E36: Telefonía local y 0800 | F36: pos_inf | G36: -289466.9 | H36: =$G36*Supuestos!D$6*(Drivers!D$15/Drivers!$C$15) | I36: =$G36*Supuestos!E$6*(Drivers!E$15/Drivers!$C$15) | J36: =$G36*Supuestos!F$6*(Drivers!F$15/Drivers!$C$15) | K36: =$G36*Supuestos!G$6*(Drivers!G$15/Drivers!$C$15) | L36: =$G36*Supuestos!H$6*(Drivers!H$15/Drivers!$C$15) | M36: =$G36*Supuestos!I$6*(Drivers!I$15/Drivers!$C$15) | N36: =$G36*Supuestos!J$6*(Drivers!J$15/Drivers!$C$15) | O36: =$G36*Supuestos!K$6*(Drivers!K$15/Drivers!$C$15) | ... V36: =$G36*Supuestos!R$6*(Drivers!R$15/Drivers!$C$15)
A37: TFP | B37: ARS | C37: 2 Costos de Explotación | D37: 2.6 SMS | E37: SMS | F37: sms | G37: -1226157.8 | H37: =$G37*Supuestos!D$12*(Drivers!D$12/100) | I37: =$G37*Supuestos!E$12*(Drivers!E$12/100) | J37: =$G37*Supuestos!F$12*(Drivers!F$12/100) | K37: =$G37*Supuestos!G$12*(Drivers!G$12/100) | L37: =$G37*Supuestos!H$12*(Drivers!H$12/100) | M37: =$G37*Supuestos!I$12*(Drivers!I$12/100) | N37: =$G37*Supuestos!J$12*(Drivers!J$12/100) | O37: =$G37*Supuestos!K$12*(Drivers!K$12/100) | ... V37: =$G37*Supuestos!R$12*(Drivers!R$12/100)
A38: TFP | B38: ARS | C38: 2 Costos de Explotación | D38: 2.7 Bocas de Cobranza | E38: Bocas de cobranza | F38: vol_inf | G38: -605134.96 | H38: =$G38*Supuestos!D$6*(Drivers!D$12/100) | I38: =$G38*Supuestos!E$6*(Drivers!E$12/100) | J38: =$G38*Supuestos!F$6*(Drivers!F$12/100) | K38: =$G38*Supuestos!G$6*(Drivers!G$12/100) | L38: =$G38*Supuestos!H$6*(Drivers!H$12/100) | M38: =$G38*Supuestos!I$6*(Drivers!I$12/100) | N38: =$G38*Supuestos!J$6*(Drivers!J$12/100) | O38: =$G38*Supuestos!K$6*(Drivers!K$12/100) | ... V38: =$G38*Supuestos!R$6*(Drivers!R$12/100)
A39: TFP | B39: ARS | C39: 2 Costos de Explotación | D39: 2.8 Mailing | E39: Mailing | F39: vol_usd | G39: -313881.53 | H39: =$G39*Supuestos!D$8*(Drivers!D$12/100) | I39: =$G39*Supuestos!E$8*(Drivers!E$12/100) | J39: =$G39*Supuestos!F$8*(Drivers!F$12/100) | K39: =$G39*Supuestos!G$8*(Drivers!G$12/100) | L39: =$G39*Supuestos!H$8*(Drivers!H$12/100) | M39: =$G39*Supuestos!I$8*(Drivers!I$12/100) | N39: =$G39*Supuestos!J$8*(Drivers!J$12/100) | O39: =$G39*Supuestos!K$8*(Drivers!K$12/100) | ... V39: =$G39*Supuestos!R$8*(Drivers!R$12/100)
A40: TFP | B40: ARS | C40: 2 Costos de Explotación | D40: 2.9 Informes Comerciales | E40: Informes comerciales | F40: vol_inf | G40: -536485 | H40: =$G40*Supuestos!D$6*(Drivers!D$12/100) | I40: =$G40*Supuestos!E$6*(Drivers!E$12/100) | J40: =$G40*Supuestos!F$6*(Drivers!F$12/100) | K40: =$G40*Supuestos!G$6*(Drivers!G$12/100) | L40: =$G40*Supuestos!H$6*(Drivers!H$12/100) | M40: =$G40*Supuestos!I$6*(Drivers!I$12/100) | N40: =$G40*Supuestos!J$6*(Drivers!J$12/100) | O40: =$G40*Supuestos!K$6*(Drivers!K$12/100) | ... V40: =$G40*Supuestos!R$6*(Drivers!R$12/100)
A41: TFP | B41: ARS | C41: 2 Costos de Explotación | D41: 2.12 WhatsApp | E41: WhatsApp | F41: vol_usd | G41: -476385 | H41: =$G41*Supuestos!D$8*(Drivers!D$12/100) | I41: =$G41*Supuestos!E$8*(Drivers!E$12/100) | J41: =$G41*Supuestos!F$8*(Drivers!F$12/100) | K41: =$G41*Supuestos!G$8*(Drivers!G$12/100) | L41: =$G41*Supuestos!H$8*(Drivers!H$12/100) | M41: =$G41*Supuestos!I$8*(Drivers!I$12/100) | N41: =$G41*Supuestos!J$8*(Drivers!J$12/100) | O41: =$G41*Supuestos!K$8*(Drivers!K$12/100) | ... V41: =$G41*Supuestos!R$8*(Drivers!R$12/100)
...

Sheet EERR
A1: Estado de resultados de gestión · cierre 2025 y presupuesto 2026
A2: En millones de pesos (formato de celda). Real ene–sep: datos de gestión; oct–dic: reproyección; 2026: presupuesto. Si ves celdas vacías, habilitá la edición.
A4: Línea | B4: Real ene–sep 2025 | C4: oct-25 | D4: nov-25 | E4: dic-25 | F4: Cierre 2025 | G4: Presupuesto 2025 | H4: Cierre vs presup. | I4: ene-26 | J4: feb-26 | K4: mar-26 | L4: abr-26 | M4: may-26 | N4: jun-26 | O4: jul-26 | P4: ago-26 | Q4: sep-26 | R4: oct-26 | S4: nov-26 | T4: dic-26 | U4: Total 2026 | V4: 2026 vs cierre 2025
A5: 1 Ingreso Operacional | B5: =B6+B7 | C5: =C6+C7 | D5: =D6+D7 | E5: =E6+E7 | F5: =B5+SUM(C5:E5) | G5: =G6+G7 | H5: =F5-G5 | I5: =I6+I7 | J5: =J6+J7 | K5: =K6+K7 | L5: =L6+L7 | M5: =M6+M7 | N5: =N6+N7 | O5: =O6+O7 | P5: =P6+P7 | ... T5: =T6+T7 | U5: =SUM(I5:T5) | V5: =IFERROR(U5/F5-1,"-")
A6: 1.1 Ingreso Cobranzas | B6: 3222169846 | C6: =SUMIFS(Cálculo!$H$5:$H$216,Cálculo!$D$5:$D$216,$A6) | D6: =SUMIFS(Cálculo!$I$5:$I$216,Cálculo!$D$5:$D$216,$A6) | E6: =SUMIFS(Cálculo!$J$5:$J$216,Cálculo!$D$5:$D$216,$A6) | F6: =B6+SUM(C6:E6) | G6: 4891908983 | H6: =F6-G6 | I6: =SUMIFS(Cálculo!$K$5:$K$216,Cálculo!$D$5:$D$216,$A6) | J6: =SUMIFS(Cálculo!$L$5:$L$216,Cálculo!$D$5:$D$216,$A6) | K6: =SUMIFS(Cálculo!$M$5:$M$216,Cálculo!$D$5:$D$216,$A6) | L6: =SUMIFS(Cálculo!$N$5:$N$216,Cálculo!$D$5:$D$216,$A6) | M6: =SUMIFS(Cálculo!$O$5:$O$216,Cálculo!$D$5:$D$216,$A6) | N6: =SUMIFS(Cálculo!$P$5:$P$216,Cálculo!$D$5:$D$216,$A6) | O6: =SUMIFS(Cálculo!$Q$5:$Q$216,Cálculo!$D$5:$D$216,$A6) | P6: =SUMIFS(Cálculo!$R$5:$R$216,Cálculo!$D$5:$D$216,$A6) | Q6: =SUMIFS(Cálculo!$S$5:$S$216,Cálculo!$D$5:$D$216,$A6) | R6: =SUMIFS(Cálculo!$T$5:$T$216,Cálculo!$D$5:$D$216,$A6) | S6: =SUMIFS(Cálculo!$U$5:$U$216,Cálculo!$D$5:$D$216,$A6) | T6: =SUMIFS(Cálculo!$V$5:$V$216,Cálculo!$D$5:$D$216,$A6) | U6: =SUM(I6:T6) | V6: =IFERROR(U6/F6-1,"-")
A7: 1.3 Ingreso Ventas | B7: 162257410 | C7: =SUMIFS(Cálculo!$H$5:$H$216,Cálculo!$D$5:$D$216,$A7) | D7: =SUMIFS(Cálculo!$I$5:$I$216,Cálculo!$D$5:$D$216,$A7) | E7: =SUMIFS(Cálculo!$J$5:$J$216,Cálculo!$D$5:$D$216,$A7) | F7: =B7+SUM(C7:E7) | G7: 228356779 | H7: =F7-G7 | I7: =SUMIFS(Cálculo!$K$5:$K$216,Cálculo!$D$5:$D$216,$A7) | J7: =SUMIFS(Cálculo!$L$5:$L$216,Cálculo!$D$5:$D$216,$A7) | K7: =SUMIFS(Cálculo!$M$5:$M$216,Cálculo!$D$5:$D$216,$A7) | L7: =SUMIFS(Cálculo!$N$5:$N$216,Cálculo!$D$5:$D$216,$A7) | M7: =SUMIFS(Cálculo!$O$5:$O$216,Cálculo!$D$5:$D$216,$A7) | N7: =SUMIFS(Cálculo!$P$5:$P$216,Cálculo!$D$5:$D$216,$A7) | O7: =SUMIFS(Cálculo!$Q$5:$Q$216,Cálculo!$D$5:$D$216,$A7) | P7: =SUMIFS(Cálculo!$R$5:$R$216,Cálculo!$D$5:$D$216,$A7) | Q7: =SUMIFS(Cálculo!$S$5:$S$216,Cálculo!$D$5:$D$216,$A7) | R7: =SUMIFS(Cálculo!$T$5:$T$216,Cálculo!$D$5:$D$216,$A7) | S7: =SUMIFS(Cálculo!$U$5:$U$216,Cálculo!$D$5:$D$216,$A7) | T7: =SUMIFS(Cálculo!$V$5:$V$216,Cálculo!$D$5:$D$216,$A7) | U7: =SUM(I7:T7) | V7: =IFERROR(U7/F7-1,"-")
A8: 2 Costos de Explotación | B8: =B9+B10+B11+B12+B13+B14+B15+B16+B17 | C8: =C9+C10+C11+C12+C13+C14+C15+C16+C17 | D8: =D9+D10+D11+D12+D13+D14+D15+D16+D17 | E8: =E9+E10+E11+E12+E13+E14+E15+E16+E17 | F8: =B8+SUM(C8:E8) | G8: =G9+G10+G11+G12+G13+G14+G15+G16+G17 | H8: =F8-G8 | I8: =I9+I10+I11+I12+I13+I14+I15+I16+I17 | J8: =J9+J10+J11+J12+J13+J14+J15+J16+J17 | K8: =K9+K10+K11+K12+K13+K14+K15+K16+K17 | L8: =L9+L10+L11+L12+L13+L14+L15+L16+L17 | M8: =M9+M10+M11+M12+M13+M14+M15+M16+M17 | N8: =N9+N10+N11+N12+N13+N14+N15+N16+N17 | O8: =O9+O10+O11+O12+O13+O14+O15+O16+O17 | P8: =P9+P10+P11+P12+P13+P14+P15+P16+P17 | ... T8: =T9+T10+T11+T12+T13+T14+T15+T16+T17 | U8: =SUM(I8:T8) | V8: =IFERROR(U8/F8-1,"-")
A9: 2.1 Remuneraciones | B9: -1181706850 | C9: =SUMIFS(Cálculo!$H$5:$H$216,Cálculo!$D$5:$D$216,$A9) | D9: =SUMIFS(Cálculo!$I$5:$I$216,Cálculo!$D$5:$D$216,$A9) | E9: =SUMIFS(Cálculo!$J$5:$J$216,Cálculo!$D$5:$D$216,$A9) | F9: =B9+SUM(C9:E9) | G9: -1757459131 | H9: =F9-G9 | I9: =SUMIFS(Cálculo!$K$5:$K$216,Cálculo!$D$5:$D$216,$A9) | J9: =SUMIFS(Cálculo!$L$5:$L$216,Cálculo!$D$5:$D$216,$A9) | K9: =SUMIFS(Cálculo!$M$5:$M$216,Cálculo!$D$5:$D$216,$A9) | L9: =SUMIFS(Cálculo!$N$5:$N$216,Cálculo!$D$5:$D$216,$A9) | M9: =SUMIFS(Cálculo!$O$5:$O$216,Cálculo!$D$5:$D$216,$A9) | N9: =SUMIFS(Cálculo!$P$5:$P$216,Cálculo!$D$5:$D$216,$A9) | O9: =SUMIFS(Cálculo!$Q$5:$Q$216,Cálculo!$D$5:$D$216,$A9) | P9: =SUMIFS(Cálculo!$R$5:$R$216,Cálculo!$D$5:$D$216,$A9) | Q9: =SUMIFS(Cálculo!$S$5:$S$216,Cálculo!$D$5:$D$216,$A9) | R9: =SUMIFS(Cálculo!$T$5:$T$216,Cálculo!$D$5:$D$216,$A9) | S9: =SUMIFS(Cálculo!$U$5:$U$216,Cálculo!$D$5:$D$216,$A9) | T9: =SUMIFS(Cálculo!$V$5:$V$216,Cálculo!$D$5:$D$216,$A9) | U9: =SUM(I9:T9) | V9: =IFERROR(U9/F9-1,"-")
A10: 2.2 Servicios de Terceros | B10: -366490150 | C10: =SUMIFS(Cálculo!$H$5:$H$216,Cálculo!$D$5:$D$216,$A10) | D10: =SUMIFS(Cálculo!$I$5:$I$216,Cálculo!$D$5:$D$216,$A10) | E10: =SUMIFS(Cálculo!$J$5:$J$216,Cálculo!$D$5:$D$216,$A10) | F10: =B10+SUM(C10:E10) | G10: -501215000 | H10: =F10-G10 | I10: =SUMIFS(Cálculo!$K$5:$K$216,Cálculo!$D$5:$D$216,$A10) | J10: =SUMIFS(Cálculo!$L$5:$L$216,Cálculo!$D$5:$D$216,$A10) | K10: =SUMIFS(Cálculo!$M$5:$M$216,Cálculo!$D$5:$D$216,$A10) | L10: =SUMIFS(Cálculo!$N$5:$N$216,Cálculo!$D$5:$D$216,$A10) | M10: =SUMIFS(Cálculo!$O$5:$O$216,Cálculo!$D$5:$D$216,$A10) | N10: =SUMIFS(Cálculo!$P$5:$P$216,Cálculo!$D$5:$D$216,$A10) | O10: =SUMIFS(Cálculo!$Q$5:$Q$216,Cálculo!$D$5:$D$216,$A10) | P10: =SUMIFS(Cálculo!$R$5:$R$216,Cálculo!$D$5:$D$216,$A10) | Q10: =SUMIFS(Cálculo!$S$5:$S$216,Cálculo!$D$5:$D$216,$A10) | R10: =SUMIFS(Cálculo!$T$5:$T$216,Cálculo!$D$5:$D$216,$A10) | S10: =SUMIFS(Cálculo!$U$5:$U$216,Cálculo!$D$5:$D$216,$A10) | T10: =SUMIFS(Cálculo!$V$5:$V$216,Cálculo!$D$5:$D$216,$A10) | U10: =SUM(I10:T10) | V10: =IFERROR(U10/F10-1,"-")
A11: 2.3 Licencias | B11: -75543075 | C11: =SUMIFS(Cálculo!$H$5:$H$216,Cálculo!$D$5:$D$216,$A11) | D11: =SUMIFS(Cálculo!$I$5:$I$216,Cálculo!$D$5:$D$216,$A11) | E11: =SUMIFS(Cálculo!$J$5:$J$216,Cálculo!$D$5:$D$216,$A11) | F11: =B11+SUM(C11:E11) | G11: -102559950 | H11: =F11-G11 | I11: =SUMIFS(Cálculo!$K$5:$K$216,Cálculo!$D$5:$D$216,$A11) | J11: =SUMIFS(Cálculo!$L$5:$L$216,Cálculo!$D$5:$D$216,$A11) | K11: =SUMIFS(Cálculo!$M$5:$M$216,Cálculo!$D$5:$D$216,$A11) | L11: =SUMIFS(Cálculo!$N$5:$N$216,Cálculo!$D$5:$D$216,$A11) | M11: =SUMIFS(Cálculo!$O$5:$O$216,Cálculo!$D$5:$D$216,$A11) | N11: =SUMIFS(Cálculo!$P$5:$P$216,Cálculo!$D$5:$D$216,$A11) | O11: =SUMIFS(Cálculo!$Q$5:$Q$216,Cálculo!$D$5:$D$216,$A11) | P11: =SUMIFS(Cálculo!$R$5:$R$216,Cálculo!$D$5:$D$216,$A11) | Q11: =SUMIFS(Cálculo!$S$5:$S$216,Cálculo!$D$5:$D$216,$A11) | R11: =SUMIFS(Cálculo!$T$5:$T$216,Cálculo!$D$5:$D$216,$A11) | S11: =SUMIFS(Cálculo!$U$5:$U$216,Cálculo!$D$5:$D$216,$A11) | T11: =SUMIFS(Cálculo!$V$5:$V$216,Cálculo!$D$5:$D$216,$A11) | U11: =SUM(I11:T11) | V11: =IFERROR(U11/F11-1,"-")
A12: 2.5 Telefonía | B12: -70183446 | C12: =SUMIFS(Cálculo!$H$5:$H$216,Cálculo!$D$5:$D$216,$A12) | D12: =SUMIFS(Cálculo!$I$5:$I$216,Cálculo!$D$5:$D$216,$A12) | E12: =SUMIFS(Cálculo!$J$5:$J$216,Cálculo!$D$5:$D$216,$A12) | F12: =B12+SUM(C12:E12) | G12: -101110195 | H12: =F12-G12 | I12: =SUMIFS(Cálculo!$K$5:$K$216,Cálculo!$D$5:$D$216,$A12) | J12: =SUMIFS(Cálculo!$L$5:$L$216,Cálculo!$D$5:$D$216,$A12) | K12: =SUMIFS(Cálculo!$M$5:$M$216,Cálculo!$D$5:$D$216,$A12) | L12: =SUMIFS(Cálculo!$N$5:$N$216,Cálculo!$D$5:$D$216,$A12) | M12: =SUMIFS(Cálculo!$O$5:$O$216,Cálculo!$D$5:$D$216,$A12) | N12: =SUMIFS(Cálculo!$P$5:$P$216,Cálculo!$D$5:$D$216,$A12) | O12: =SUMIFS(Cálculo!$Q$5:$Q$216,Cálculo!$D$5:$D$216,$A12) | P12: =SUMIFS(Cálculo!$R$5:$R$216,Cálculo!$D$5:$D$216,$A12) | Q12: =SUMIFS(Cálculo!$S$5:$S$216,Cálculo!$D$5:$D$216,$A12) | R12: =SUMIFS(Cálculo!$T$5:$T$216,Cálculo!$D$5:$D$216,$A12) | S12: =SUMIFS(Cálculo!$U$5:$U$216,Cálculo!$D$5:$D$216,$A12) | T12: =SUMIFS(Cálculo!$V$5:$V$216,Cálculo!$D$5:$D$216,$A12) | U12: =SUM(I12:T12) | V12: =IFERROR(U12/F12-1,"-")
A13: 2.6 SMS | B13: -74335992 | C13: =SUMIFS(Cálculo!$H$5:$H$216,Cálculo!$D$5:$D$216,$A13) | D13: =SUMIFS(Cálculo!$I$5:$I$216,Cálculo!$D$5:$D$216,$A13) | E13: =SUMIFS(Cálculo!$J$5:$J$216,Cálculo!$D$5:$D$216,$A13) | F13: =B13+SUM(C13:E13) | G13: -97145424 | H13: =F13-G13 | I13: =SUMIFS(Cálculo!$K$5:$K$216,Cálculo!$D$5:$D$216,$A13) | J13: =SUMIFS(Cálculo!$L$5:$L$216,Cálculo!$D$5:$D$216,$A13) | K13: =SUMIFS(Cálculo!$M$5:$M$216,Cálculo!$D$5:$D$216,$A13) | L13: =SUMIFS(Cálculo!$N$5:$N$216,Cálculo!$D$5:$D$216,$A13) | M13: =SUMIFS(Cálculo!$O$5:$O$216,Cálculo!$D$5:$D$216,$A13) | N13: =SUMIFS(Cálculo!$P$5:$P$216,Cálculo!$D$5:$D$216,$A13) | O13: =SUMIFS(Cálculo!$Q$5:$Q$216,Cálculo!$D$5:$D$216,$A13) | P13: =SUMIFS(Cálculo!$R$5:$R$216,Cálculo!$D$5:$D$216,$A13) | Q13: =SUMIFS(Cálculo!$S$5:$S$216,Cálculo!$D$5:$D$216,$A13) | R13: =SUMIFS(Cálculo!$T$5:$T$216,Cálculo!$D$5:$D$216,$A13) | S13: =SUMIFS(Cálculo!$U$5:$U$216,Cálculo!$D$5:$D$216,$A13) | T13: =SUMIFS(Cálculo!$V$5:$V$216,Cálculo!$D$5:$D$216,$A13) | U13: =SUM(I13:T13) | V13: =IFERROR(U13/F13-1,"-")
A14: 2.7 Bocas de Cobranza | B14: -43067764 | C14: =SUMIFS(Cálculo!$H$5:$H$216,Cálculo!$D$5:$D$216,$A14) | D14: =SUMIFS(Cálculo!$I$5:$I$216,Cálculo!$D$5:$D$216,$A14) | E14: =SUMIFS(Cálculo!$J$5:$J$216,Cálculo!$D$5:$D$216,$A14) | F14: =B14+SUM(C14:E14) | G14: -64696140 | H14: =F14-G14 | I14: =SUMIFS(Cálculo!$K$5:$K$216,Cálculo!$D$5:$D$216,$A14) | J14: =SUMIFS(Cálculo!$L$5:$L$216,Cálculo!$D$5:$D$216,$A14) | K14: =SUMIFS(Cálculo!$M$5:$M$216,Cálculo!$D$5:$D$216,$A14) | L14: =SUMIFS(Cálculo!$N$5:$N$216,Cálculo!$D$5:$D$216,$A14) | M14: =SUMIFS(Cálculo!$O$5:$O$216,Cálculo!$D$5:$D$216,$A14) | N14: =SUMIFS(Cálculo!$P$5:$P$216,Cálculo!$D$5:$D$216,$A14) | O14: =SUMIFS(Cálculo!$Q$5:$Q$216,Cálculo!$D$5:$D$216,$A14) | P14: =SUMIFS(Cálculo!$R$5:$R$216,Cálculo!$D$5:$D$216,$A14) | Q14: =SUMIFS(Cálculo!$S$5:$S$216,Cálculo!$D$5:$D$216,$A14) | R14: =SUMIFS(Cálculo!$T$5:$T$216,Cálculo!$D$5:$D$216,$A14) | S14: =SUMIFS(Cálculo!$U$5:$U$216,Cálculo!$D$5:$D$216,$A14) | T14: =SUMIFS(Cálculo!$V$5:$V$216,Cálculo!$D$5:$D$216,$A14) | U14: =SUM(I14:T14) | V14: =IFERROR(U14/F14-1,"-")
A15: 2.8 Mailing | B15: -25828134 | C15: =SUMIFS(Cálculo!$H$5:$H$216,Cálculo!$D$5:$D$216,$A15) | D15: =SUMIFS(Cálculo!$I$5:$I$216,Cálculo!$D$5:$D$216,$A15) | E15: =SUMIFS(Cálculo!$J$5:$J$216,Cálculo!$D$5:$D$216,$A15) | F15: =B15+SUM(C15:E15) | G15: -35674567 | H15: =F15-G15 | I15: =SUMIFS(Cálculo!$K$5:$K$216,Cálculo!$D$5:$D$216,$A15) | J15: =SUMIFS(Cálculo!$L$5:$L$216,Cálculo!$D$5:$D$216,$A15) | K15: =SUMIFS(Cálculo!$M$5:$M$216,Cálculo!$D$5:$D$216,$A15) | L15: =SUMIFS(Cálculo!$N$5:$N$216,Cálculo!$D$5:$D$216,$A15) | M15: =SUMIFS(Cálculo!$O$5:$O$216,Cálculo!$D$5:$D$216,$A15) | N15: =SUMIFS(Cálculo!$P$5:$P$216,Cálculo!$D$5:$D$216,$A15) | O15: =SUMIFS(Cálculo!$Q$5:$Q$216,Cálculo!$D$5:$D$216,$A15) | P15: =SUMIFS(Cálculo!$R$5:$R$216,Cálculo!$D$5:$D$216,$A15) | Q15: =SUMIFS(Cálculo!$S$5:$S$216,Cálculo!$D$5:$D$216,$A15) | R15: =SUMIFS(Cálculo!$T$5:$T$216,Cálculo!$D$5:$D$216,$A15) | S15: =SUMIFS(Cálculo!$U$5:$U$216,Cálculo!$D$5:$D$216,$A15) | T15: =SUMIFS(Cálculo!$V$5:$V$216,Cálculo!$D$5:$D$216,$A15) | U15: =SUM(I15:T15) | V15: =IFERROR(U15/F15-1,"-")
A16: 2.9 Informes Comerciales | B16: -14867561 | C16: =SUMIFS(Cálculo!$H$5:$H$216,Cálculo!$D$5:$D$216,$A16) | D16: =SUMIFS(Cálculo!$I$5:$I$216,Cálculo!$D$5:$D$216,$A16) | E16: =SUMIFS(Cálculo!$J$5:$J$216,Cálculo!$D$5:$D$216,$A16) | F16: =B16+SUM(C16:E16) | G16: -21840243 | H16: =F16-G16 | I16: =SUMIFS(Cálculo!$K$5:$K$216,Cálculo!$D$5:$D$216,$A16) | J16: =SUMIFS(Cálculo!$L$5:$L$216,Cálculo!$D$5:$D$216,$A16) | K16: =SUMIFS(Cálculo!$M$5:$M$216,Cálculo!$D$5:$D$216,$A16) | L16: =SUMIFS(Cálculo!$N$5:$N$216,Cálculo!$D$5:$D$216,$A16) | M16: =SUMIFS(Cálculo!$O$5:$O$216,Cálculo!$D$5:$D$216,$A16) | N16: =SUMIFS(Cálculo!$P$5:$P$216,Cálculo!$D$5:$D$216,$A16) | O16: =SUMIFS(Cálculo!$Q$5:$Q$216,Cálculo!$D$5:$D$216,$A16) | P16: =SUMIFS(Cálculo!$R$5:$R$216,Cálculo!$D$5:$D$216,$A16) | Q16: =SUMIFS(Cálculo!$S$5:$S$216,Cálculo!$D$5:$D$216,$A16) | R16: =SUMIFS(Cálculo!$T$5:$T$216,Cálculo!$D$5:$D$216,$A16) | S16: =SUMIFS(Cálculo!$U$5:$U$216,Cálculo!$D$5:$D$216,$A16) | T16: =SUMIFS(Cálculo!$V$5:$V$216,Cálculo!$D$5:$D$216,$A16) | U16: =SUM(I16:T16) | V16: =IFERROR(U16/F16-1,"-")
A17: 2.12 WhatsApp | B17: -13907210 | C17: =SUMIFS(Cálculo!$H$5:$H$216,Cálculo!$D$5:$D$216,$A17) | D17: =SUMIFS(Cálculo!$I$5:$I$216,Cálculo!$D$5:$D$216,$A17) | E17: =SUMIFS(Cálculo!$J$5:$J$216,Cálculo!$D$5:$D$216,$A17) | F17: =B17+SUM(C17:E17) | G17: -19069880 | H17: =F17-G17 | I17: =SUMIFS(Cálculo!$K$5:$K$216,Cálculo!$D$5:$D$216,$A17) | J17: =SUMIFS(Cálculo!$L$5:$L$216,Cálculo!$D$5:$D$216,$A17) | K17: =SUMIFS(Cálculo!$M$5:$M$216,Cálculo!$D$5:$D$216,$A17) | L17: =SUMIFS(Cálculo!$N$5:$N$216,Cálculo!$D$5:$D$216,$A17) | M17: =SUMIFS(Cálculo!$O$5:$O$216,Cálculo!$D$5:$D$216,$A17) | N17: =SUMIFS(Cálculo!$P$5:$P$216,Cálculo!$D$5:$D$216,$A17) | O17: =SUMIFS(Cálculo!$Q$5:$Q$216,Cálculo!$D$5:$D$216,$A17) | P17: =SUMIFS(Cálculo!$R$5:$R$216,Cálculo!$D$5:$D$216,$A17) | Q17: =SUMIFS(Cálculo!$S$5:$S$216,Cálculo!$D$5:$D$216,$A17) | R17: =SUMIFS(Cálculo!$T$5:$T$216,Cálculo!$D$5:$D$216,$A17) | S17: =SUMIFS(Cálculo!$U$5:$U$216,Cálculo!$D$5:$D$216,$A17) | T17: =SUMIFS(Cálculo!$V$5:$V$216,Cálculo!$D$5:$D$216,$A17) | U17: =SUM(I17:T17) | V17: =IFERROR(U17/F17-1,"-")
A18: 3 Impuestos Directos | B18: =B19 | C18: =C19 | D18: =D19 | E18: =E19 | F18: =B18+SUM(C18:E18) | G18: =G19 | H18: =F18-G18 | I18: =I19 | J18: =J19 | K18: =K19 | L18: =L19 | M18: =M19 | N18: =N19 | O18: =O19 | P18: =P19 | ... T18: =T19 | U18: =SUM(I18:T18) | V18: =IFERROR(U18/F18-1,"-")
A19: 3.1 Ingresos Brutos | B19: -95541356 | C19: =SUMIFS(Cálculo!$H$5:$H$216,Cálculo!$D$5:$D$216,$A19) | D19: =SUMIFS(Cálculo!$I$5:$I$216,Cálculo!$D$5:$D$216,$A19) | E19: =SUMIFS(Cálculo!$J$5:$J$216,Cálculo!$D$5:$D$216,$A19) | F19: =B19+SUM(C19:E19) | G19: -146054345 | H19: =F19-G19 | I19: =SUMIFS(Cálculo!$K$5:$K$216,Cálculo!$D$5:$D$216,$A19) | J19: =SUMIFS(Cálculo!$L$5:$L$216,Cálculo!$D$5:$D$216,$A19) | K19: =SUMIFS(Cálculo!$M$5:$M$216,Cálculo!$D$5:$D$216,$A19) | L19: =SUMIFS(Cálculo!$N$5:$N$216,Cálculo!$D$5:$D$216,$A19) | M19: =SUMIFS(Cálculo!$O$5:$O$216,Cálculo!$D$5:$D$216,$A19) | N19: =SUMIFS(Cálculo!$P$5:$P$216,Cálculo!$D$5:$D$216,$A19) | O19: =SUMIFS(Cálculo!$Q$5:$Q$216,Cálculo!$D$5:$D$216,$A19) | P19: =SUMIFS(Cálculo!$R$5:$R$216,Cálculo!$D$5:$D$216,$A19) | Q19: =SUMIFS(Cálculo!$S$5:$S$216,Cálculo!$D$5:$D$216,$A19) | R19: =SUMIFS(Cálculo!$T$5:$T$216,Cálculo!$D$5:$D$216,$A19) | S19: =SUMIFS(Cálculo!$U$5:$U$216,Cálculo!$D$5:$D$216,$A19) | T19: =SUMIFS(Cálculo!$V$5:$V$216,Cálculo!$D$5:$D$216,$A19) | U19: =SUM(I19:T19) | V19: =IFERROR(U19/F19-1,"-")
A20: Margen bruto | B20: =B5+B8+B18 | C20: =C5+C8+C18 | D20: =D5+D8+D18 | E20: =E5+E8+E18 | F20: =B20+SUM(C20:E20) | G20: =G5+G8+G18 | H20: =F20-G20 | I20: =I5+I8+I18 | J20: =J5+J8+J18 | K20: =K5+K8+K18 | L20: =L5+L8+L18 | M20: =M5+M8+M18 | N20: =N5+N8+N18 | O20: =O5+O8+O18 | P20: =P5+P8+P18 | ... T20: =T5+T8+T18 | U20: =SUM(I20:T20) | V20: =IFERROR(U20/F20-1,"-")
A21: % sobre ingresos | B21: =IFERROR(B20/B5,0) | C21: =IFERROR(C20/C5,0) | D21: =IFERROR(D20/D5,0) | E21: =IFERROR(E20/E5,0) | F21: =IFERROR(F20/F5,0) | G21: =IFERROR(G20/G5,0) | I21: =IFERROR(I20/I5,0) | J21: =IFERROR(J20/J5,0) | K21: =IFERROR(K20/K5,0) | L21: =IFERROR(L20/L5,0) | M21: =IFERROR(M20/M5,0) | N21: =IFERROR(N20/N5,0) | O21: =IFERROR(O20/O5,0) | P21: =IFERROR(P20/P5,0) | ... U21: =IFERROR(U20/U5,0)
A22: 4 Gastos de Estructura | B22: =B23+B24+B25+B26+B27 | C22: =C23+C24+C25+C26+C27 | D22: =D23+D24+D25+D26+D27 | E22: =E23+E24+E25+E26+E27 | F22: =B22+SUM(C22:E22) | G22: =G23+G24+G25+G26+G27 | H22: =F22-G22 | I22: =I23+I24+I25+I26+I27 | J22: =J23+J24+J25+J26+J27 | K22: =K23+K24+K25+K26+K27 | L22: =L23+L24+L25+L26+L27 | M22: =M23+M24+M25+M26+M27 | N22: =N23+N24+N25+N26+N27 | O22: =O23+O24+O25+O26+O27 | P22: =P23+P24+P25+P26+P27 | ... T22: =T23+T24+T25+T26+T27 | U22: =SUM(I22:T22) | V22: =IFERROR(U22/F22-1,"-")
A23: 4.1 Remuneraciones Staff | B23: -701091994 | C23: =SUMIFS(Cálculo!$H$5:$H$216,Cálculo!$D$5:$D$216,$A23) | D23: =SUMIFS(Cálculo!$I$5:$I$216,Cálculo!$D$5:$D$216,$A23) | E23: =SUMIFS(Cálculo!$J$5:$J$216,Cálculo!$D$5:$D$216,$A23) | F23: =B23+SUM(C23:E23) | G23: -1026810649 | H23: =F23-G23 | I23: =SUMIFS(Cálculo!$K$5:$K$216,Cálculo!$D$5:$D$216,$A23) | J23: =SUMIFS(Cálculo!$L$5:$L$216,Cálculo!$D$5:$D$216,$A23) | K23: =SUMIFS(Cálculo!$M$5:$M$216,Cálculo!$D$5:$D$216,$A23) | L23: =SUMIFS(Cálculo!$N$5:$N$216,Cálculo!$D$5:$D$216,$A23) | M23: =SUMIFS(Cálculo!$O$5:$O$216,Cálculo!$D$5:$D$216,$A23) | N23: =SUMIFS(Cálculo!$P$5:$P$216,Cálculo!$D$5:$D$216,$A23) | O23: =SUMIFS(Cálculo!$Q$5:$Q$216,Cálculo!$D$5:$D$216,$A23) | P23: =SUMIFS(Cálculo!$R$5:$R$216,Cálculo!$D$5:$D$216,$A23) | Q23: =SUMIFS(Cálculo!$S$5:$S$216,Cálculo!$D$5:$D$216,$A23) | R23: =SUMIFS(Cálculo!$T$5:$T$216,Cálculo!$D$5:$D$216,$A23) | S23: =SUMIFS(Cálculo!$U$5:$U$216,Cálculo!$D$5:$D$216,$A23) | T23: =SUMIFS(Cálculo!$V$5:$V$216,Cálculo!$D$5:$D$216,$A23) | U23: =SUM(I23:T23) | V23: =IFERROR(U23/F23-1,"-")
A24: 4.2 Honorarios | B24: -44643149 | C24: =SUMIFS(Cálculo!$H$5:$H$216,Cálculo!$D$5:$D$216,$A24) | D24: =SUMIFS(Cálculo!$I$5:$I$216,Cálculo!$D$5:$D$216,$A24) | E24: =SUMIFS(Cálculo!$J$5:$J$216,Cálculo!$D$5:$D$216,$A24) | F24: =B24+SUM(C24:E24) | G24: -64364048 | H24: =F24-G24 | I24: =SUMIFS(Cálculo!$K$5:$K$216,Cálculo!$D$5:$D$216,$A24) | J24: =SUMIFS(Cálculo!$L$5:$L$216,Cálculo!$D$5:$D$216,$A24) | K24: =SUMIFS(Cálculo!$M$5:$M$216,Cálculo!$D$5:$D$216,$A24) | L24: =SUMIFS(Cálculo!$N$5:$N$216,Cálculo!$D$5:$D$216,$A24) | M24: =SUMIFS(Cálculo!$O$5:$O$216,Cálculo!$D$5:$D$216,$A24) | N24: =SUMIFS(Cálculo!$P$5:$P$216,Cálculo!$D$5:$D$216,$A24) | O24: =SUMIFS(Cálculo!$Q$5:$Q$216,Cálculo!$D$5:$D$216,$A24) | P24: =SUMIFS(Cálculo!$R$5:$R$216,Cálculo!$D$5:$D$216,$A24) | Q24: =SUMIFS(Cálculo!$S$5:$S$216,Cálculo!$D$5:$D$216,$A24) | R24: =SUMIFS(Cálculo!$T$5:$T$216,Cálculo!$D$5:$D$216,$A24) | S24: =SUMIFS(Cálculo!$U$5:$U$216,Cálculo!$D$5:$D$216,$A24) | T24: =SUMIFS(Cálculo!$V$5:$V$216,Cálculo!$D$5:$D$216,$A24) | U24: =SUM(I24:T24) | V24: =IFERROR(U24/F24-1,"-")
A25: 4.3 Mantenimiento de Oficina | B25: -59524200 | C25: =SUMIFS(Cálculo!$H$5:$H$216,Cálculo!$D$5:$D$216,$A25) | D25: =SUMIFS(Cálculo!$I$5:$I$216,Cálculo!$D$5:$D$216,$A25) | E25: =SUMIFS(Cálculo!$J$5:$J$216,Cálculo!$D$5:$D$216,$A25) | F25: =B25+SUM(C25:E25) | G25: -85818732 | H25: =F25-G25 | I25: =SUMIFS(Cálculo!$K$5:$K$216,Cálculo!$D$5:$D$216,$A25) | J25: =SUMIFS(Cálculo!$L$5:$L$216,Cálculo!$D$5:$D$216,$A25) | K25: =SUMIFS(Cálculo!$M$5:$M$216,Cálculo!$D$5:$D$216,$A25) | L25: =SUMIFS(Cálculo!$N$5:$N$216,Cálculo!$D$5:$D$216,$A25) | M25: =SUMIFS(Cálculo!$O$5:$O$216,Cálculo!$D$5:$D$216,$A25) | N25: =SUMIFS(Cálculo!$P$5:$P$216,Cálculo!$D$5:$D$216,$A25) | O25: =SUMIFS(Cálculo!$Q$5:$Q$216,Cálculo!$D$5:$D$216,$A25) | P25: =SUMIFS(Cálculo!$R$5:$R$216,Cálculo!$D$5:$D$216,$A25) | Q25: =SUMIFS(Cálculo!$S$5:$S$216,Cálculo!$D$5:$D$216,$A25) | R25: =SUMIFS(Cálculo!$T$5:$T$216,Cálculo!$D$5:$D$216,$A25) | S25: =SUMIFS(Cálculo!$U$5:$U$216,Cálculo!$D$5:$D$216,$A25) | T25: =SUMIFS(Cálculo!$V$5:$V$216,Cálculo!$D$5:$D$216,$A25) | U25: =SUM(I25:T25) | V25: =IFERROR(U25/F25-1,"-")
A26: 4.4 Alquileres | B26: -47206677 | C26: =SUMIFS(Cálculo!$H$5:$H$216,Cálculo!$D$5:$D$216,$A26) | D26: =SUMIFS(Cálculo!$I$5:$I$216,Cálculo!$D$5:$D$216,$A26) | E26: =SUMIFS(Cálculo!$J$5:$J$216,Cálculo!$D$5:$D$216,$A26) | F26: =B26+SUM(C26:E26) | G26: -71515607 | H26: =F26-G26 | I26: =SUMIFS(Cálculo!$K$5:$K$216,Cálculo!$D$5:$D$216,$A26) | J26: =SUMIFS(Cálculo!$L$5:$L$216,Cálculo!$D$5:$D$216,$A26) | K26: =SUMIFS(Cálculo!$M$5:$M$216,Cálculo!$D$5:$D$216,$A26) | L26: =SUMIFS(Cálculo!$N$5:$N$216,Cálculo!$D$5:$D$216,$A26) | M26: =SUMIFS(Cálculo!$O$5:$O$216,Cálculo!$D$5:$D$216,$A26) | N26: =SUMIFS(Cálculo!$P$5:$P$216,Cálculo!$D$5:$D$216,$A26) | O26: =SUMIFS(Cálculo!$Q$5:$Q$216,Cálculo!$D$5:$D$216,$A26) | P26: =SUMIFS(Cálculo!$R$5:$R$216,Cálculo!$D$5:$D$216,$A26) | Q26: =SUMIFS(Cálculo!$S$5:$S$216,Cálculo!$D$5:$D$216,$A26) | R26: =SUMIFS(Cálculo!$T$5:$T$216,Cálculo!$D$5:$D$216,$A26) | S26: =SUMIFS(Cálculo!$U$5:$U$216,Cálculo!$D$5:$D$216,$A26) | T26: =SUMIFS(Cálculo!$V$5:$V$216,Cálculo!$D$5:$D$216,$A26) | U26: =SUM(I26:T26) | V26: =IFERROR(U26/F26-1,"-")
A27: 4.6 Otros Gastos | B27: -72290101 | C27: =SUMIFS(Cálculo!$H$5:$H$216,Cálculo!$D$5:$D$216,$A27) | D27: =SUMIFS(Cálculo!$I$5:$I$216,Cálculo!$D$5:$D$216,$A27) | E27: =SUMIFS(Cálculo!$J$5:$J$216,Cálculo!$D$5:$D$216,$A27) | F27: =B27+SUM(C27:E27) | G27: -98989365 | H27: =F27-G27 | I27: =SUMIFS(Cálculo!$K$5:$K$216,Cálculo!$D$5:$D$216,$A27) | J27: =SUMIFS(Cálculo!$L$5:$L$216,Cálculo!$D$5:$D$216,$A27) | K27: =SUMIFS(Cálculo!$M$5:$M$216,Cálculo!$D$5:$D$216,$A27) | L27: =SUMIFS(Cálculo!$N$5:$N$216,Cálculo!$D$5:$D$216,$A27) | M27: =SUMIFS(Cálculo!$O$5:$O$216,Cálculo!$D$5:$D$216,$A27) | N27: =SUMIFS(Cálculo!$P$5:$P$216,Cálculo!$D$5:$D$216,$A27) | O27: =SUMIFS(Cálculo!$Q$5:$Q$216,Cálculo!$D$5:$D$216,$A27) | P27: =SUMIFS(Cálculo!$R$5:$R$216,Cálculo!$D$5:$D$216,$A27) | Q27: =SUMIFS(Cálculo!$S$5:$S$216,Cálculo!$D$5:$D$216,$A27) | R27: =SUMIFS(Cálculo!$T$5:$T$216,Cálculo!$D$5:$D$216,$A27) | S27: =SUMIFS(Cálculo!$U$5:$U$216,Cálculo!$D$5:$D$216,$A27) | T27: =SUMIFS(Cálculo!$V$5:$V$216,Cálculo!$D$5:$D$216,$A27) | U27: =SUM(I27:T27) | V27: =IFERROR(U27/F27-1,"-")
A28: Margen operativo | B28: =B5+B8+B18+B22 | C28: =C5+C8+C18+C22 | D28: =D5+D8+D18+D22 | E28: =E5+E8+E18+E22 | F28: =B28+SUM(C28:E28) | G28: =G5+G8+G18+G22 | H28: =F28-G28 | I28: =I5+I8+I18+I22 | J28: =J5+J8+J18+J22 | K28: =K5+K8+K18+K22 | L28: =L5+L8+L18+L22 | M28: =M5+M8+M18+M22 | N28: =N5+N8+N18+N22 | O28: =O5+O8+O18+O22 | P28: =P5+P8+P18+P22 | ... T28: =T5+T8+T18+T22 | U28: =SUM(I28:T28) | V28: =IFERROR(U28/F28-1,"-")
A29: % sobre ingresos | B29: =IFERROR(B28/B5,0) | C29: =IFERROR(C28/C5,0) | D29: =IFERROR(D28/D5,0) | E29: =IFERROR(E28/E5,0) | F29: =IFERROR(F28/F5,0) | G29: =IFERROR(G28/G5,0) | I29: =IFERROR(I28/I5,0) | J29: =IFERROR(J28/J5,0) | K29: =IFERROR(K28/K5,0) | L29: =IFERROR(L28/L5,0) | M29: =IFERROR(M28/M5,0) | N29: =IFERROR(N28/N5,0) | O29: =IFERROR(O28/O5,0) | P29: =IFERROR(P28/P5,0) | ... U29: =IFERROR(U28/U5,0)
A30: 5 Resultado No Operacional | B30: =B31+B32+B33 | C30: =C31+C32+C33 | D30: =D31+D32+D33 | E30: =E31+E32+E33 | F30: =B30+SUM(C30:E30) | G30: =G31+G32+G33 | H30: =F30-G30 | I30: =I31+I32+I33 | J30: =J31+J32+J33 | K30: =K31+K32+K33 | L30: =L31+L32+L33 | M30: =M31+M32+M33 | N30: =N31+N32+N33 | O30: =O31+O32+O33 | P30: =P31+P32+P33 | ... T30: =T31+T32+T33 | U30: =SUM(I30:T30) | V30: =IFERROR(U30/F30-1,"-")
A31: 5.1 Amortizaciones | B31: -22500000 | C31: =SUMIFS(Cálculo!$H$5:$H$216,Cálculo!$D$5:$D$216,$A31) | D31: =SUMIFS(Cálculo!$I$5:$I$216,Cálculo!$D$5:$D$216,$A31) | E31: =SUMIFS(Cálculo!$J$5:$J$216,Cálculo!$D$5:$D$216,$A31) | F31: =B31+SUM(C31:E31) | G31: -30000000 | H31: =F31-G31 | I31: =SUMIFS(Cálculo!$K$5:$K$216,Cálculo!$D$5:$D$216,$A31) | J31: =SUMIFS(Cálculo!$L$5:$L$216,Cálculo!$D$5:$D$216,$A31) | K31: =SUMIFS(Cálculo!$M$5:$M$216,Cálculo!$D$5:$D$216,$A31) | L31: =SUMIFS(Cálculo!$N$5:$N$216,Cálculo!$D$5:$D$216,$A31) | M31: =SUMIFS(Cálculo!$O$5:$O$216,Cálculo!$D$5:$D$216,$A31) | N31: =SUMIFS(Cálculo!$P$5:$P$216,Cálculo!$D$5:$D$216,$A31) | O31: =SUMIFS(Cálculo!$Q$5:$Q$216,Cálculo!$D$5:$D$216,$A31) | P31: =SUMIFS(Cálculo!$R$5:$R$216,Cálculo!$D$5:$D$216,$A31) | Q31: =SUMIFS(Cálculo!$S$5:$S$216,Cálculo!$D$5:$D$216,$A31) | R31: =SUMIFS(Cálculo!$T$5:$T$216,Cálculo!$D$5:$D$216,$A31) | S31: =SUMIFS(Cálculo!$U$5:$U$216,Cálculo!$D$5:$D$216,$A31) | T31: =SUMIFS(Cálculo!$V$5:$V$216,Cálculo!$D$5:$D$216,$A31) | U31: =SUM(I31:T31) | V31: =IFERROR(U31/F31-1,"-")
