Workbook

Sheet Léeme
A1: Base de caja y clientes · Pastas Don Aldo
A2: Datos 100% ficticios (generate_pyme.py, semilla fija). Enero a mayo: Excel compartido limpiado con limpiar_excel.py. Junio en adelante: formulario.
A4: Hojas
A5: Cierres: un cierre por local y día, con el arqueo en fórmulas (efectivo esperado, diferencia y si cuadra).
A6: Resumen mensual: venta, efectivo, tickets, costo de plataformas y caja por mes y local, con SUMIFS y COUNTIFS sobre Cierres.
A7: Fiado: lo comprado a cuenta menos lo cobrado, por restaurante; la columna Control compara la fórmula con el motor del tablero.
A8: Pedidos, Cobros y Problemas del Excel: los datos y el registro de cada arreglo de la limpieza.
A10: Supuestos (azul = valor cargado)
A11: Corte de los datos | B11: 45939
A12: Tolerancia para que la caja cuadre ($) | B12: 500
A13: Comisión débito | B13: 0.015
A14: Comisión crédito | B14: 0.035
A15: Comisión billetera virtual | B15: 0.008
A17: Colores: azul = valor cargado · verde = fórmula que lee otra hoja · negro = fórmula de la misma hoja.

Sheet Resumen mensual
A1: Mes | B1: Local | C1: Venta | D1: Efectivo | E1: % efectivo | F1: Tickets | G1: Ticket promedio | H1: Costo plataformas | I1: Cierres con arqueo | J1: Cierres que cuadran | K1: % que cuadra | L1: Faltó en la caja
A2: 2025-01 | B2: Centro | C2: =SUMIFS(Cierres!$J$2:$J$478,Cierres!$A$2:$A$478,">="&DATE(2025,1,1),Cierres!$A$2:$A$478,"<="&EOMONTH(DATE(2025,1,1),0),Cierres!$B$2:$B$478,$B2) -> 11314270 | D2: =SUMIFS(Cierres!$E$2:$E$478,Cierres!$A$2:$A$478,">="&DATE(2025,1,1),Cierres!$A$2:$A$478,"<="&EOMONTH(DATE(2025,1,1),0),Cierres!$B$2:$B$478,$B2) -> 8964820 | E2: =IF(C2=0,"",D2/C2) -> 0.7923463 | F2: =SUMIFS(Cierres!$K$2:$K$478,Cierres!$A$2:$A$478,">="&DATE(2025,1,1),Cierres!$A$2:$A$478,"<="&EOMONTH(DATE(2025,1,1),0),Cierres!$B$2:$B$478,$B2) -> 0 | G2: =IF(F2=0,"",SUMIFS(Cierres!$J$2:$J$478,Cierres!$A$2:$A$478,">="&DATE(2025,1,1),Cierres!$A$2:$A$478,"<="&EOMONTH(DATE(2025,1,1),0),Cierres!$B$2:$B$478,$B2,Cierres!$K$2:$K$478,">0")/F2) | H2: =ROUND(SUMIFS(Cierres!$F$2:$F$478,Cierres!$A$2:$A$478,">="&DATE(2025,1,1),Cierres!$A$2:$A$478,"<="&EOMONTH(DATE(2025,1,1),0),Cierres!$B$2:$B$478,$B2)*Léeme!$B$13+SUMIFS(Cierres!$G$2:$G$478,Cierres!$A$2:$A$478,">="&DATE(2025,1,1),Cierres!$A$2:$A$478,"<="&EOMONTH(DATE(2025,1,1),0),Cierres!$B$2:$B$478,$B2)*Léeme!$B$14+SUMIFS(Cierres!$H$2:$H$478,Cierres!$A$2:$A$478,">="&DATE(2025,1,1),Cierres!$A$2:$A$478,"<="&EOMONTH(DATE(2025,1,1),0),Cierres!$B$2:$B$478,$B2)*Léeme!$B$15,0) -> 33430 | I2: =COUNTIFS(Cierres!$A$2:$A$478,">="&DATE(2025,1,1),Cierres!$A$2:$A$478,"<="&EOMONTH(DATE(2025,1,1),0),Cierres!$B$2:$B$478,$B2,Cierres!$Q$2:$Q$478,"<>") -> 0 | J2: =COUNTIFS(Cierres!$A$2:$A$478,">="&DATE(2025,1,1),Cierres!$A$2:$A$478,"<="&EOMONTH(DATE(2025,1,1),0),Cierres!$B$2:$B$478,$B2,Cierres!$S$2:$S$478,"Cuadra") -> 0 | K2: =IF(I2=0,"",J2/I2) | L2: =-SUMIFS(Cierres!$R$2:$R$478,Cierres!$A$2:$A$478,">="&DATE(2025,1,1),Cierres!$A$2:$A$478,"<="&EOMONTH(DATE(2025,1,1),0),Cierres!$B$2:$B$478,$B2,Cierres!$R$2:$R$478,"<"&-Léeme!$B$12) -> 0
A3: 2025-01 | B3: Jardín | C3: =SUMIFS(Cierres!$J$2:$J$478,Cierres!$A$2:$A$478,">="&DATE(2025,1,1),Cierres!$A$2:$A$478,"<="&EOMONTH(DATE(2025,1,1),0),Cierres!$B$2:$B$478,$B3) -> 8599530 | D3: =SUMIFS(Cierres!$E$2:$E$478,Cierres!$A$2:$A$478,">="&DATE(2025,1,1),Cierres!$A$2:$A$478,"<="&EOMONTH(DATE(2025,1,1),0),Cierres!$B$2:$B$478,$B3) -> 6836090 | E3: =IF(C3=0,"",D3/C3) -> 0.79493763 | F3: =SUMIFS(Cierres!$K$2:$K$478,Cierres!$A$2:$A$478,">="&DATE(2025,1,1),Cierres!$A$2:$A$478,"<="&EOMONTH(DATE(2025,1,1),0),Cierres!$B$2:$B$478,$B3) -> 0 | G3: =IF(F3=0,"",SUMIFS(Cierres!$J$2:$J$478,Cierres!$A$2:$A$478,">="&DATE(2025,1,1),Cierres!$A$2:$A$478,"<="&EOMONTH(DATE(2025,1,1),0),Cierres!$B$2:$B$478,$B3,Cierres!$K$2:$K$478,">0")/F3) | H3: =ROUND(SUMIFS(Cierres!$F$2:$F$478,Cierres!$A$2:$A$478,">="&DATE(2025,1,1),Cierres!$A$2:$A$478,"<="&EOMONTH(DATE(2025,1,1),0),Cierres!$B$2:$B$478,$B3)*Léeme!$B$13+SUMIFS(Cierres!$G$2:$G$478,Cierres!$A$2:$A$478,">="&DATE(2025,1,1),Cierres!$A$2:$A$478,"<="&EOMONTH(DATE(2025,1,1),0),Cierres!$B$2:$B$478,$B3)*Léeme!$B$14+SUMIFS(Cierres!$H$2:$H$478,Cierres!$A$2:$A$478,">="&DATE(2025,1,1),Cierres!$A$2:$A$478,"<="&EOMONTH(DATE(2025,1,1),0),Cierres!$B$2:$B$478,$B3)*Léeme!$B$15,0) -> 25183 | I3: =COUNTIFS(Cierres!$A$2:$A$478,">="&DATE(2025,1,1),Cierres!$A$2:$A$478,"<="&EOMONTH(DATE(2025,1,1),0),Cierres!$B$2:$B$478,$B3,Cierres!$Q$2:$Q$478,"<>") -> 0 | J3: =COUNTIFS(Cierres!$A$2:$A$478,">="&DATE(2025,1,1),Cierres!$A$2:$A$478,"<="&EOMONTH(DATE(2025,1,1),0),Cierres!$B$2:$B$478,$B3,Cierres!$S$2:$S$478,"Cuadra") -> 0 | K3: =IF(I3=0,"",J3/I3) | L3: =-SUMIFS(Cierres!$R$2:$R$478,Cierres!$A$2:$A$478,">="&DATE(2025,1,1),Cierres!$A$2:$A$478,"<="&EOMONTH(DATE(2025,1,1),0),Cierres!$B$2:$B$478,$B3,Cierres!$R$2:$R$478,"<"&-Léeme!$B$12) -> 0
A4: 2025-02 | B4: Centro | C4: =SUMIFS(Cierres!$J$2:$J$478,Cierres!$A$2:$A$478,">="&DATE(2025,2,1),Cierres!$A$2:$A$478,"<="&EOMONTH(DATE(2025,2,1),0),Cierres!$B$2:$B$478,$B4) -> 11221780 | D4: =SUMIFS(Cierres!$E$2:$E$478,Cierres!$A$2:$A$478,">="&DATE(2025,2,1),Cierres!$A$2:$A$478,"<="&EOMONTH(DATE(2025,2,1),0),Cierres!$B$2:$B$478,$B4) -> 8696910 | E4: =IF(C4=0,"",D4/C4) -> 0.77500272 | F4: =SUMIFS(Cierres!$K$2:$K$478,Cierres!$A$2:$A$478,">="&DATE(2025,2,1),Cierres!$A$2:$A$478,"<="&EOMONTH(DATE(2025,2,1),0),Cierres!$B$2:$B$478,$B4) -> 0 | G4: =IF(F4=0,"",SUMIFS(Cierres!$J$2:$J$478,Cierres!$A$2:$A$478,">="&DATE(2025,2,1),Cierres!$A$2:$A$478,"<="&EOMONTH(DATE(2025,2,1),0),Cierres!$B$2:$B$478,$B4,Cierres!$K$2:$K$478,">0")/F4) | H4: =ROUND(SUMIFS(Cierres!$F$2:$F$478,Cierres!$A$2:$A$478,">="&DATE(2025,2,1),Cierres!$A$2:$A$478,"<="&EOMONTH(DATE(2025,2,1),0),Cierres!$B$2:$B$478,$B4)*Léeme!$B$13+SUMIFS(Cierres!$G$2:$G$478,Cierres!$A$2:$A$478,">="&DATE(2025,2,1),Cierres!$A$2:$A$478,"<="&EOMONTH(DATE(2025,2,1),0),Cierres!$B$2:$B$478,$B4)*Léeme!$B$14+SUMIFS(Cierres!$H$2:$H$478,Cierres!$A$2:$A$478,">="&DATE(2025,2,1),Cierres!$A$2:$A$478,"<="&EOMONTH(DATE(2025,2,1),0),Cierres!$B$2:$B$478,$B4)*Léeme!$B$15,0) -> 35168 | I4: =COUNTIFS(Cierres!$A$2:$A$478,">="&DATE(2025,2,1),Cierres!$A$2:$A$478,"<="&EOMONTH(DATE(2025,2,1),0),Cierres!$B$2:$B$478,$B4,Cierres!$Q$2:$Q$478,"<>") -> 0 | J4: =COUNTIFS(Cierres!$A$2:$A$478,">="&DATE(2025,2,1),Cierres!$A$2:$A$478,"<="&EOMONTH(DATE(2025,2,1),0),Cierres!$B$2:$B$478,$B4,Cierres!$S$2:$S$478,"Cuadra") -> 0 | K4: =IF(I4=0,"",J4/I4) | L4: =-SUMIFS(Cierres!$R$2:$R$478,Cierres!$A$2:$A$478,">="&DATE(2025,2,1),Cierres!$A$2:$A$478,"<="&EOMONTH(DATE(2025,2,1),0),Cierres!$B$2:$B$478,$B4,Cierres!$R$2:$R$478,"<"&-Léeme!$B$12) -> 0
A5: 2025-02 | B5: Jardín | C5: =SUMIFS(Cierres!$J$2:$J$478,Cierres!$A$2:$A$478,">="&DATE(2025,2,1),Cierres!$A$2:$A$478,"<="&EOMONTH(DATE(2025,2,1),0),Cierres!$B$2:$B$478,$B5) -> 8567530 | D5: =SUMIFS(Cierres!$E$2:$E$478,Cierres!$A$2:$A$478,">="&DATE(2025,2,1),Cierres!$A$2:$A$478,"<="&EOMONTH(DATE(2025,2,1),0),Cierres!$B$2:$B$478,$B5) -> 6665180 | E5: =IF(C5=0,"",D5/C5) -> 0.77795817 | F5: =SUMIFS(Cierres!$K$2:$K$478,Cierres!$A$2:$A$478,">="&DATE(2025,2,1),Cierres!$A$2:$A$478,"<="&EOMONTH(DATE(2025,2,1),0),Cierres!$B$2:$B$478,$B5) -> 0 | G5: =IF(F5=0,"",SUMIFS(Cierres!$J$2:$J$478,Cierres!$A$2:$A$478,">="&DATE(2025,2,1),Cierres!$A$2:$A$478,"<="&EOMONTH(DATE(2025,2,1),0),Cierres!$B$2:$B$478,$B5,Cierres!$K$2:$K$478,">0")/F5) | H5: =ROUND(SUMIFS(Cierres!$F$2:$F$478,Cierres!$A$2:$A$478,">="&DATE(2025,2,1),Cierres!$A$2:$A$478,"<="&EOMONTH(DATE(2025,2,1),0),Cierres!$B$2:$B$478,$B5)*Léeme!$B$13+SUMIFS(Cierres!$G$2:$G$478,Cierres!$A$2:$A$478,">="&DATE(2025,2,1),Cierres!$A$2:$A$478,"<="&EOMONTH(DATE(2025,2,1),0),Cierres!$B$2:$B$478,$B5)*Léeme!$B$14+SUMIFS(Cierres!$H$2:$H$478,Cierres!$A$2:$A$478,">="&DATE(2025,2,1),Cierres!$A$2:$A$478,"<="&EOMONTH(DATE(2025,2,1),0),Cierres!$B$2:$B$478,$B5)*Léeme!$B$15,0) -> 26805 | I5: =COUNTIFS(Cierres!$A$2:$A$478,">="&DATE(2025,2,1),Cierres!$A$2:$A$478,"<="&EOMONTH(DATE(2025,2,1),0),Cierres!$B$2:$B$478,$B5,Cierres!$Q$2:$Q$478,"<>") -> 0 | J5: =COUNTIFS(Cierres!$A$2:$A$478,">="&DATE(2025,2,1),Cierres!$A$2:$A$478,"<="&EOMONTH(DATE(2025,2,1),0),Cierres!$B$2:$B$478,$B5,Cierres!$S$2:$S$478,"Cuadra") -> 0 | K5: =IF(I5=0,"",J5/I5) | L5: =-SUMIFS(Cierres!$R$2:$R$478,Cierres!$A$2:$A$478,">="&DATE(2025,2,1),Cierres!$A$2:$A$478,"<="&EOMONTH(DATE(2025,2,1),0),Cierres!$B$2:$B$478,$B5,Cierres!$R$2:$R$478,"<"&-Léeme!$B$12) -> 0
A6: 2025-03 | B6: Centro | C6: =SUMIFS(Cierres!$J$2:$J$478,Cierres!$A$2:$A$478,">="&DATE(2025,3,1),Cierres!$A$2:$A$478,"<="&EOMONTH(DATE(2025,3,1),0),Cierres!$B$2:$B$478,$B6) -> 14655980 | D6: =SUMIFS(Cierres!$E$2:$E$478,Cierres!$A$2:$A$478,">="&DATE(2025,3,1),Cierres!$A$2:$A$478,"<="&EOMONTH(DATE(2025,3,1),0),Cierres!$B$2:$B$478,$B6) -> 11256980 | E6: =IF(C6=0,"",D6/C6) -> 0.76808102 | F6: =SUMIFS(Cierres!$K$2:$K$478,Cierres!$A$2:$A$478,">="&DATE(2025,3,1),Cierres!$A$2:$A$478,"<="&EOMONTH(DATE(2025,3,1),0),Cierres!$B$2:$B$478,$B6) -> 0 | G6: =IF(F6=0,"",SUMIFS(Cierres!$J$2:$J$478,Cierres!$A$2:$A$478,">="&DATE(2025,3,1),Cierres!$A$2:$A$478,"<="&EOMONTH(DATE(2025,3,1),0),Cierres!$B$2:$B$478,$B6,Cierres!$K$2:$K$478,">0")/F6) | H6: =ROUND(SUMIFS(Cierres!$F$2:$F$478,Cierres!$A$2:$A$478,">="&DATE(2025,3,1),Cierres!$A$2:$A$478,"<="&EOMONTH(DATE(2025,3,1),0),Cierres!$B$2:$B$478,$B6)*Léeme!$B$13+SUMIFS(Cierres!$G$2:$G$478,Cierres!$A$2:$A$478,">="&DATE(2025,3,1),Cierres!$A$2:$A$478,"<="&EOMONTH(DATE(2025,3,1),0),Cierres!$B$2:$B$478,$B6)*Léeme!$B$14+SUMIFS(Cierres!$H$2:$H$478,Cierres!$A$2:$A$478,">="&DATE(2025,3,1),Cierres!$A$2:$A$478,"<="&EOMONTH(DATE(2025,3,1),0),Cierres!$B$2:$B$478,$B6)*Léeme!$B$15,0) -> 46400 | I6: =COUNTIFS(Cierres!$A$2:$A$478,">="&DATE(2025,3,1),Cierres!$A$2:$A$478,"<="&EOMONTH(DATE(2025,3,1),0),Cierres!$B$2:$B$478,$B6,Cierres!$Q$2:$Q$478,"<>") -> 0 | J6: =COUNTIFS(Cierres!$A$2:$A$478,">="&DATE(2025,3,1),Cierres!$A$2:$A$478,"<="&EOMONTH(DATE(2025,3,1),0),Cierres!$B$2:$B$478,$B6,Cierres!$S$2:$S$478,"Cuadra") -> 0 | K6: =IF(I6=0,"",J6/I6) | L6: =-SUMIFS(Cierres!$R$2:$R$478,Cierres!$A$2:$A$478,">="&DATE(2025,3,1),Cierres!$A$2:$A$478,"<="&EOMONTH(DATE(2025,3,1),0),Cierres!$B$2:$B$478,$B6,Cierres!$R$2:$R$478,"<"&-Léeme!$B$12) -> 0
A7: 2025-03 | B7: Jardín | C7: =SUMIFS(Cierres!$J$2:$J$478,Cierres!$A$2:$A$478,">="&DATE(2025,3,1),Cierres!$A$2:$A$478,"<="&EOMONTH(DATE(2025,3,1),0),Cierres!$B$2:$B$478,$B7) -> 11237260 | D7: =SUMIFS(Cierres!$E$2:$E$478,Cierres!$A$2:$A$478,">="&DATE(2025,3,1),Cierres!$A$2:$A$478,"<="&EOMONTH(DATE(2025,3,1),0),Cierres!$B$2:$B$478,$B7) -> 8564250 | E7: =IF(C7=0,"",D7/C7) -> 0.76212974 | F7: =SUMIFS(Cierres!$K$2:$K$478,Cierres!$A$2:$A$478,">="&DATE(2025,3,1),Cierres!$A$2:$A$478,"<="&EOMONTH(DATE(2025,3,1),0),Cierres!$B$2:$B$478,$B7) -> 0 | G7: =IF(F7=0,"",SUMIFS(Cierres!$J$2:$J$478,Cierres!$A$2:$A$478,">="&DATE(2025,3,1),Cierres!$A$2:$A$478,"<="&EOMONTH(DATE(2025,3,1),0),Cierres!$B$2:$B$478,$B7,Cierres!$K$2:$K$478,">0")/F7) | H7: =ROUND(SUMIFS(Cierres!$F$2:$F$478,Cierres!$A$2:$A$478,">="&DATE(2025,3,1),Cierres!$A$2:$A$478,"<="&EOMONTH(DATE(2025,3,1),0),Cierres!$B$2:$B$478,$B7)*Léeme!$B$13+SUMIFS(Cierres!$G$2:$G$478,Cierres!$A$2:$A$478,">="&DATE(2025,3,1),Cierres!$A$2:$A$478,"<="&EOMONTH(DATE(2025,3,1),0),Cierres!$B$2:$B$478,$B7)*Léeme!$B$14+SUMIFS(Cierres!$H$2:$H$478,Cierres!$A$2:$A$478,">="&DATE(2025,3,1),Cierres!$A$2:$A$478,"<="&EOMONTH(DATE(2025,3,1),0),Cierres!$B$2:$B$478,$B7)*Léeme!$B$15,0) -> 36528 | I7: =COUNTIFS(Cierres!$A$2:$A$478,">="&DATE(2025,3,1),Cierres!$A$2:$A$478,"<="&EOMONTH(DATE(2025,3,1),0),Cierres!$B$2:$B$478,$B7,Cierres!$Q$2:$Q$478,"<>") -> 0 | J7: =COUNTIFS(Cierres!$A$2:$A$478,">="&DATE(2025,3,1),Cierres!$A$2:$A$478,"<="&EOMONTH(DATE(2025,3,1),0),Cierres!$B$2:$B$478,$B7,Cierres!$S$2:$S$478,"Cuadra") -> 0 | K7: =IF(I7=0,"",J7/I7) | L7: =-SUMIFS(Cierres!$R$2:$R$478,Cierres!$A$2:$A$478,">="&DATE(2025,3,1),Cierres!$A$2:$A$478,"<="&EOMONTH(DATE(2025,3,1),0),Cierres!$B$2:$B$478,$B7,Cierres!$R$2:$R$478,"<"&-Léeme!$B$12) -> 0
A8: 2025-04 | B8: Centro | C8: =SUMIFS(Cierres!$J$2:$J$478,Cierres!$A$2:$A$478,">="&DATE(2025,4,1),Cierres!$A$2:$A$478,"<="&EOMONTH(DATE(2025,4,1),0),Cierres!$B$2:$B$478,$B8) -> 14115060 | D8: =SUMIFS(Cierres!$E$2:$E$478,Cierres!$A$2:$A$478,">="&DATE(2025,4,1),Cierres!$A$2:$A$478,"<="&EOMONTH(DATE(2025,4,1),0),Cierres!$B$2:$B$478,$B8) -> 10579610 | E8: =IF(C8=0,"",D8/C8) -> 0.74952639 | F8: =SUMIFS(Cierres!$K$2:$K$478,Cierres!$A$2:$A$478,">="&DATE(2025,4,1),Cierres!$A$2:$A$478,"<="&EOMONTH(DATE(2025,4,1),0),Cierres!$B$2:$B$478,$B8) -> 0 | G8: =IF(F8=0,"",SUMIFS(Cierres!$J$2:$J$478,Cierres!$A$2:$A$478,">="&DATE(2025,4,1),Cierres!$A$2:$A$478,"<="&EOMONTH(DATE(2025,4,1),0),Cierres!$B$2:$B$478,$B8,Cierres!$K$2:$K$478,">0")/F8) | H8: =ROUND(SUMIFS(Cierres!$F$2:$F$478,Cierres!$A$2:$A$478,">="&DATE(2025,4,1),Cierres!$A$2:$A$478,"<="&EOMONTH(DATE(2025,4,1),0),Cierres!$B$2:$B$478,$B8)*Léeme!$B$13+SUMIFS(Cierres!$G$2:$G$478,Cierres!$A$2:$A$478,">="&DATE(2025,4,1),Cierres!$A$2:$A$478,"<="&EOMONTH(DATE(2025,4,1),0),Cierres!$B$2:$B$478,$B8)*Léeme!$B$14+SUMIFS(Cierres!$H$2:$H$478,Cierres!$A$2:$A$478,">="&DATE(2025,4,1),Cierres!$A$2:$A$478,"<="&EOMONTH(DATE(2025,4,1),0),Cierres!$B$2:$B$478,$B8)*Léeme!$B$15,0) -> 54450 | I8: =COUNTIFS(Cierres!$A$2:$A$478,">="&DATE(2025,4,1),Cierres!$A$2:$A$478,"<="&EOMONTH(DATE(2025,4,1),0),Cierres!$B$2:$B$478,$B8,Cierres!$Q$2:$Q$478,"<>") -> 0 | J8: =COUNTIFS(Cierres!$A$2:$A$478,">="&DATE(2025,4,1),Cierres!$A$2:$A$478,"<="&EOMONTH(DATE(2025,4,1),0),Cierres!$B$2:$B$478,$B8,Cierres!$S$2:$S$478,"Cuadra") -> 0 | K8: =IF(I8=0,"",J8/I8) | L8: =-SUMIFS(Cierres!$R$2:$R$478,Cierres!$A$2:$A$478,">="&DATE(2025,4,1),Cierres!$A$2:$A$478,"<="&EOMONTH(DATE(2025,4,1),0),Cierres!$B$2:$B$478,$B8,Cierres!$R$2:$R$478,"<"&-Léeme!$B$12) -> 0
A9: 2025-04 | B9: Jardín | C9: =SUMIFS(Cierres!$J$2:$J$478,Cierres!$A$2:$A$478,">="&DATE(2025,4,1),Cierres!$A$2:$A$478,"<="&EOMONTH(DATE(2025,4,1),0),Cierres!$B$2:$B$478,$B9) -> 10695830 | D9: =SUMIFS(Cierres!$E$2:$E$478,Cierres!$A$2:$A$478,">="&DATE(2025,4,1),Cierres!$A$2:$A$478,"<="&EOMONTH(DATE(2025,4,1),0),Cierres!$B$2:$B$478,$B9) -> 8001710 | E9: =IF(C9=0,"",D9/C9) -> 0.74811492 | F9: =SUMIFS(Cierres!$K$2:$K$478,Cierres!$A$2:$A$478,">="&DATE(2025,4,1),Cierres!$A$2:$A$478,"<="&EOMONTH(DATE(2025,4,1),0),Cierres!$B$2:$B$478,$B9) -> 0 | G9: =IF(F9=0,"",SUMIFS(Cierres!$J$2:$J$478,Cierres!$A$2:$A$478,">="&DATE(2025,4,1),Cierres!$A$2:$A$478,"<="&EOMONTH(DATE(2025,4,1),0),Cierres!$B$2:$B$478,$B9,Cierres!$K$2:$K$478,">0")/F9) | H9: =ROUND(SUMIFS(Cierres!$F$2:$F$478,Cierres!$A$2:$A$478,">="&DATE(2025,4,1),Cierres!$A$2:$A$478,"<="&EOMONTH(DATE(2025,4,1),0),Cierres!$B$2:$B$478,$B9)*Léeme!$B$13+SUMIFS(Cierres!$G$2:$G$478,Cierres!$A$2:$A$478,">="&DATE(2025,4,1),Cierres!$A$2:$A$478,"<="&EOMONTH(DATE(2025,4,1),0),Cierres!$B$2:$B$478,$B9)*Léeme!$B$14+SUMIFS(Cierres!$H$2:$H$478,Cierres!$A$2:$A$478,">="&DATE(2025,4,1),Cierres!$A$2:$A$478,"<="&EOMONTH(DATE(2025,4,1),0),Cierres!$B$2:$B$478,$B9)*Léeme!$B$15,0) -> 41407 | I9: =COUNTIFS(Cierres!$A$2:$A$478,">="&DATE(2025,4,1),Cierres!$A$2:$A$478,"<="&EOMONTH(DATE(2025,4,1),0),Cierres!$B$2:$B$478,$B9,Cierres!$Q$2:$Q$478,"<>") -> 0 | J9: =COUNTIFS(Cierres!$A$2:$A$478,">="&DATE(2025,4,1),Cierres!$A$2:$A$478,"<="&EOMONTH(DATE(2025,4,1),0),Cierres!$B$2:$B$478,$B9,Cierres!$S$2:$S$478,"Cuadra") -> 0 | K9: =IF(I9=0,"",J9/I9) | L9: =-SUMIFS(Cierres!$R$2:$R$478,Cierres!$A$2:$A$478,">="&DATE(2025,4,1),Cierres!$A$2:$A$478,"<="&EOMONTH(DATE(2025,4,1),0),Cierres!$B$2:$B$478,$B9,Cierres!$R$2:$R$478,"<"&-Léeme!$B$12) -> 0
A10: 2025-05 | B10: Centro | C10: =SUMIFS(Cierres!$J$2:$J$478,Cierres!$A$2:$A$478,">="&DATE(2025,5,1),Cierres!$A$2:$A$478,"<="&EOMONTH(DATE(2025,5,1),0),Cierres!$B$2:$B$478,$B10) -> 15047670 | D10: =SUMIFS(Cierres!$E$2:$E$478,Cierres!$A$2:$A$478,">="&DATE(2025,5,1),Cierres!$A$2:$A$478,"<="&EOMONTH(DATE(2025,5,1),0),Cierres!$B$2:$B$478,$B10) -> 10966140 | E10: =IF(C10=0,"",D10/C10) -> 0.72876 | F10: =SUMIFS(Cierres!$K$2:$K$478,Cierres!$A$2:$A$478,">="&DATE(2025,5,1),Cierres!$A$2:$A$478,"<="&EOMONTH(DATE(2025,5,1),0),Cierres!$B$2:$B$478,$B10) -> 0 | G10: =IF(F10=0,"",SUMIFS(Cierres!$J$2:$J$478,Cierres!$A$2:$A$478,">="&DATE(2025,5,1),Cierres!$A$2:$A$478,"<="&EOMONTH(DATE(2025,5,1),0),Cierres!$B$2:$B$478,$B10,Cierres!$K$2:$K$478,">0")/F10) | H10: =ROUND(SUMIFS(Cierres!$F$2:$F$478,Cierres!$A$2:$A$478,">="&DATE(2025,5,1),Cierres!$A$2:$A$478,"<="&EOMONTH(DATE(2025,5,1),0),Cierres!$B$2:$B$478,$B10)*Léeme!$B$13+SUMIFS(Cierres!$G$2:$G$478,Cierres!$A$2:$A$478,">="&DATE(2025,5,1),Cierres!$A$2:$A$478,"<="&EOMONTH(DATE(2025,5,1),0),Cierres!$B$2:$B$478,$B10)*Léeme!$B$14+SUMIFS(Cierres!$H$2:$H$478,Cierres!$A$2:$A$478,">="&DATE(2025,5,1),Cierres!$A$2:$A$478,"<="&EOMONTH(DATE(2025,5,1),0),Cierres!$B$2:$B$478,$B10)*Léeme!$B$15,0) -> 62233 | I10: =COUNTIFS(Cierres!$A$2:$A$478,">="&DATE(2025,5,1),Cierres!$A$2:$A$478,"<="&EOMONTH(DATE(2025,5,1),0),Cierres!$B$2:$B$478,$B10,Cierres!$Q$2:$Q$478,"<>") -> 0 | J10: =COUNTIFS(Cierres!$A$2:$A$478,">="&DATE(2025,5,1),Cierres!$A$2:$A$478,"<="&EOMONTH(DATE(2025,5,1),0),Cierres!$B$2:$B$478,$B10,Cierres!$S$2:$S$478,"Cuadra") -> 0 | K10: =IF(I10=0,"",J10/I10) | L10: =-SUMIFS(Cierres!$R$2:$R$478,Cierres!$A$2:$A$478,">="&DATE(2025,5,1),Cierres!$A$2:$A$478,"<="&EOMONTH(DATE(2025,5,1),0),Cierres!$B$2:$B$478,$B10,Cierres!$R$2:$R$478,"<"&-Léeme!$B$12) -> 0
A11: 2025-05 | B11: Jardín | C11: =SUMIFS(Cierres!$J$2:$J$478,Cierres!$A$2:$A$478,">="&DATE(2025,5,1),Cierres!$A$2:$A$478,"<="&EOMONTH(DATE(2025,5,1),0),Cierres!$B$2:$B$478,$B11) -> 11204450 | D11: =SUMIFS(Cierres!$E$2:$E$478,Cierres!$A$2:$A$478,">="&DATE(2025,5,1),Cierres!$A$2:$A$478,"<="&EOMONTH(DATE(2025,5,1),0),Cierres!$B$2:$B$478,$B11) -> 8106510 | E11: =IF(C11=0,"",D11/C11) -> 0.72350807 | F11: =SUMIFS(Cierres!$K$2:$K$478,Cierres!$A$2:$A$478,">="&DATE(2025,5,1),Cierres!$A$2:$A$478,"<="&EOMONTH(DATE(2025,5,1),0),Cierres!$B$2:$B$478,$B11) -> 0 | G11: =IF(F11=0,"",SUMIFS(Cierres!$J$2:$J$478,Cierres!$A$2:$A$478,">="&DATE(2025,5,1),Cierres!$A$2:$A$478,"<="&EOMONTH(DATE(2025,5,1),0),Cierres!$B$2:$B$478,$B11,Cierres!$K$2:$K$478,">0")/F11) | H11: =ROUND(SUMIFS(Cierres!$F$2:$F$478,Cierres!$A$2:$A$478,">="&DATE(2025,5,1),Cierres!$A$2:$A$478,"<="&EOMONTH(DATE(2025,5,1),0),Cierres!$B$2:$B$478,$B11)*Léeme!$B$13+SUMIFS(Cierres!$G$2:$G$478,Cierres!$A$2:$A$478,">="&DATE(2025,5,1),Cierres!$A$2:$A$478,"<="&EOMONTH(DATE(2025,5,1),0),Cierres!$B$2:$B$478,$B11)*Léeme!$B$14+SUMIFS(Cierres!$H$2:$H$478,Cierres!$A$2:$A$478,">="&DATE(2025,5,1),Cierres!$A$2:$A$478,"<="&EOMONTH(DATE(2025,5,1),0),Cierres!$B$2:$B$478,$B11)*Léeme!$B$15,0) -> 47311 | I11: =COUNTIFS(Cierres!$A$2:$A$478,">="&DATE(2025,5,1),Cierres!$A$2:$A$478,"<="&EOMONTH(DATE(2025,5,1),0),Cierres!$B$2:$B$478,$B11,Cierres!$Q$2:$Q$478,"<>") -> 0 | J11: =COUNTIFS(Cierres!$A$2:$A$478,">="&DATE(2025,5,1),Cierres!$A$2:$A$478,"<="&EOMONTH(DATE(2025,5,1),0),Cierres!$B$2:$B$478,$B11,Cierres!$S$2:$S$478,"Cuadra") -> 0 | K11: =IF(I11=0,"",J11/I11) | L11: =-SUMIFS(Cierres!$R$2:$R$478,Cierres!$A$2:$A$478,">="&DATE(2025,5,1),Cierres!$A$2:$A$478,"<="&EOMONTH(DATE(2025,5,1),0),Cierres!$B$2:$B$478,$B11,Cierres!$R$2:$R$478,"<"&-Léeme!$B$12) -> 0
A12: 2025-06 | B12: Centro | C12: =SUMIFS(Cierres!$J$2:$J$478,Cierres!$A$2:$A$478,">="&DATE(2025,6,1),Cierres!$A$2:$A$478,"<="&EOMONTH(DATE(2025,6,1),0),Cierres!$B$2:$B$478,$B12) -> 17099330 | D12: =SUMIFS(Cierres!$E$2:$E$478,Cierres!$A$2:$A$478,">="&DATE(2025,6,1),Cierres!$A$2:$A$478,"<="&EOMONTH(DATE(2025,6,1),0),Cierres!$B$2:$B$478,$B12) -> 12287290 | E12: =IF(C12=0,"",D12/C12) -> 0.71858313 | F12: =SUMIFS(Cierres!$K$2:$K$478,Cierres!$A$2:$A$478,">="&DATE(2025,6,1),Cierres!$A$2:$A$478,"<="&EOMONTH(DATE(2025,6,1),0),Cierres!$B$2:$B$478,$B12) -> 1710 | G12: =IF(F12=0,"",SUMIFS(Cierres!$J$2:$J$478,Cierres!$A$2:$A$478,">="&DATE(2025,6,1),Cierres!$A$2:$A$478,"<="&EOMONTH(DATE(2025,6,1),0),Cierres!$B$2:$B$478,$B12,Cierres!$K$2:$K$478,">0")/F12) -> 9999.6082 | H12: =ROUND(SUMIFS(Cierres!$F$2:$F$478,Cierres!$A$2:$A$478,">="&DATE(2025,6,1),Cierres!$A$2:$A$478,"<="&EOMONTH(DATE(2025,6,1),0),Cierres!$B$2:$B$478,$B12)*Léeme!$B$13+SUMIFS(Cierres!$G$2:$G$478,Cierres!$A$2:$A$478,">="&DATE(2025,6,1),Cierres!$A$2:$A$478,"<="&EOMONTH(DATE(2025,6,1),0),Cierres!$B$2:$B$478,$B12)*Léeme!$B$14+SUMIFS(Cierres!$H$2:$H$478,Cierres!$A$2:$A$478,">="&DATE(2025,6,1),Cierres!$A$2:$A$478,"<="&EOMONTH(DATE(2025,6,1),0),Cierres!$B$2:$B$478,$B12)*Léeme!$B$15,0) -> 72454 | I12: =COUNTIFS(Cierres!$A$2:$A$478,">="&DATE(2025,6,1),Cierres!$A$2:$A$478,"<="&EOMONTH(DATE(2025,6,1),0),Cierres!$B$2:$B$478,$B12,Cierres!$Q$2:$Q$478,"<>") -> 25 | J12: =COUNTIFS(Cierres!$A$2:$A$478,">="&DATE(2025,6,1),Cierres!$A$2:$A$478,"<="&EOMONTH(DATE(2025,6,1),0),Cierres!$B$2:$B$478,$B12,Cierres!$S$2:$S$478,"Cuadra") -> 16 | K12: =IF(I12=0,"",J12/I12) -> 0.64 | L12: =-SUMIFS(Cierres!$R$2:$R$478,Cierres!$A$2:$A$478,">="&DATE(2025,6,1),Cierres!$A$2:$A$478,"<="&EOMONTH(DATE(2025,6,1),0),Cierres!$B$2:$B$478,$B12,Cierres!$R$2:$R$478,"<"&-Léeme!$B$12) -> 41850
A13: 2025-06 | B13: Jardín | C13: =SUMIFS(Cierres!$J$2:$J$478,Cierres!$A$2:$A$478,">="&DATE(2025,6,1),Cierres!$A$2:$A$478,"<="&EOMONTH(DATE(2025,6,1),0),Cierres!$B$2:$B$478,$B13) -> 13025470 | D13: =SUMIFS(Cierres!$E$2:$E$478,Cierres!$A$2:$A$478,">="&DATE(2025,6,1),Cierres!$A$2:$A$478,"<="&EOMONTH(DATE(2025,6,1),0),Cierres!$B$2:$B$478,$B13) -> 9371110 | E13: =IF(C13=0,"",D13/C13) -> 0.71944506 | F13: =SUMIFS(Cierres!$K$2:$K$478,Cierres!$A$2:$A$478,">="&DATE(2025,6,1),Cierres!$A$2:$A$478,"<="&EOMONTH(DATE(2025,6,1),0),Cierres!$B$2:$B$478,$B13) -> 1303 | G13: =IF(F13=0,"",SUMIFS(Cierres!$J$2:$J$478,Cierres!$A$2:$A$478,">="&DATE(2025,6,1),Cierres!$A$2:$A$478,"<="&EOMONTH(DATE(2025,6,1),0),Cierres!$B$2:$B$478,$B13,Cierres!$K$2:$K$478,">0")/F13) -> 9996.5234 | H13: =ROUND(SUMIFS(Cierres!$F$2:$F$478,Cierres!$A$2:$A$478,">="&DATE(2025,6,1),Cierres!$A$2:$A$478,"<="&EOMONTH(DATE(2025,6,1),0),Cierres!$B$2:$B$478,$B13)*Léeme!$B$13+SUMIFS(Cierres!$G$2:$G$478,Cierres!$A$2:$A$478,">="&DATE(2025,6,1),Cierres!$A$2:$A$478,"<="&EOMONTH(DATE(2025,6,1),0),Cierres!$B$2:$B$478,$B13)*Léeme!$B$14+SUMIFS(Cierres!$H$2:$H$478,Cierres!$A$2:$A$478,">="&DATE(2025,6,1),Cierres!$A$2:$A$478,"<="&EOMONTH(DATE(2025,6,1),0),Cierres!$B$2:$B$478,$B13)*Léeme!$B$15,0) -> 55047 | I13: =COUNTIFS(Cierres!$A$2:$A$478,">="&DATE(2025,6,1),Cierres!$A$2:$A$478,"<="&EOMONTH(DATE(2025,6,1),0),Cierres!$B$2:$B$478,$B13,Cierres!$Q$2:$Q$478,"<>") -> 25 | J13: =COUNTIFS(Cierres!$A$2:$A$478,">="&DATE(2025,6,1),Cierres!$A$2:$A$478,"<="&EOMONTH(DATE(2025,6,1),0),Cierres!$B$2:$B$478,$B13,Cierres!$S$2:$S$478,"Cuadra") -> 20 | K13: =IF(I13=0,"",J13/I13) -> 0.8 | L13: =-SUMIFS(Cierres!$R$2:$R$478,Cierres!$A$2:$A$478,">="&DATE(2025,6,1),Cierres!$A$2:$A$478,"<="&EOMONTH(DATE(2025,6,1),0),Cierres!$B$2:$B$478,$B13,Cierres!$R$2:$R$478,"<"&-Léeme!$B$12) -> 5140
A14: 2025-07 | B14: Centro | C14: =SUMIFS(Cierres!$J$2:$J$478,Cierres!$A$2:$A$478,">="&DATE(2025,7,1),Cierres!$A$2:$A$478,"<="&EOMONTH(DATE(2025,7,1),0),Cierres!$B$2:$B$478,$B14) -> 18266410 | D14: =SUMIFS(Cierres!$E$2:$E$478,Cierres!$A$2:$A$478,">="&DATE(2025,7,1),Cierres!$A$2:$A$478,"<="&EOMONTH(DATE(2025,7,1),0),Cierres!$B$2:$B$478,$B14) -> 12780330 | E14: =IF(C14=0,"",D14/C14) -> 0.69966293 | F14: =SUMIFS(Cierres!$K$2:$K$478,Cierres!$A$2:$A$478,">="&DATE(2025,7,1),Cierres!$A$2:$A$478,"<="&EOMONTH(DATE(2025,7,1),0),Cierres!$B$2:$B$478,$B14) -> 1773 | G14: =IF(F14=0,"",SUMIFS(Cierres!$J$2:$J$478,Cierres!$A$2:$A$478,">="&DATE(2025,7,1),Cierres!$A$2:$A$478,"<="&EOMONTH(DATE(2025,7,1),0),Cierres!$B$2:$B$478,$B14,Cierres!$K$2:$K$478,">0")/F14) -> 10302.544 | H14: =ROUND(SUMIFS(Cierres!$F$2:$F$478,Cierres!$A$2:$A$478,">="&DATE(2025,7,1),Cierres!$A$2:$A$478,"<="&EOMONTH(DATE(2025,7,1),0),Cierres!$B$2:$B$478,$B14)*Léeme!$B$13+SUMIFS(Cierres!$G$2:$G$478,Cierres!$A$2:$A$478,">="&DATE(2025,7,1),Cierres!$A$2:$A$478,"<="&EOMONTH(DATE(2025,7,1),0),Cierres!$B$2:$B$478,$B14)*Léeme!$B$14+SUMIFS(Cierres!$H$2:$H$478,Cierres!$A$2:$A$478,">="&DATE(2025,7,1),Cierres!$A$2:$A$478,"<="&EOMONTH(DATE(2025,7,1),0),Cierres!$B$2:$B$478,$B14)*Léeme!$B$15,0) -> 82006 | I14: =COUNTIFS(Cierres!$A$2:$A$478,">="&DATE(2025,7,1),Cierres!$A$2:$A$478,"<="&EOMONTH(DATE(2025,7,1),0),Cierres!$B$2:$B$478,$B14,Cierres!$Q$2:$Q$478,"<>") -> 27 | J14: =COUNTIFS(Cierres!$A$2:$A$478,">="&DATE(2025,7,1),Cierres!$A$2:$A$478,"<="&EOMONTH(DATE(2025,7,1),0),Cierres!$B$2:$B$478,$B14,Cierres!$S$2:$S$478,"Cuadra") -> 15 | K14: =IF(I14=0,"",J14/I14) -> 0.55555556 | L14: =-SUMIFS(Cierres!$R$2:$R$478,Cierres!$A$2:$A$478,">="&DATE(2025,7,1),Cierres!$A$2:$A$478,"<="&EOMONTH(DATE(2025,7,1),0),Cierres!$B$2:$B$478,$B14,Cierres!$R$2:$R$478,"<"&-Léeme!$B$12) -> 25990
A15: 2025-07 | B15: Jardín | C15: =SUMIFS(Cierres!$J$2:$J$478,Cierres!$A$2:$A$478,">="&DATE(2025,7,1),Cierres!$A$2:$A$478,"<="&EOMONTH(DATE(2025,7,1),0),Cierres!$B$2:$B$478,$B15) -> 14306490 | D15: =SUMIFS(Cierres!$E$2:$E$478,Cierres!$A$2:$A$478,">="&DATE(2025,7,1),Cierres!$A$2:$A$478,"<="&EOMONTH(DATE(2025,7,1),0),Cierres!$B$2:$B$478,$B15) -> 9962280 | E15: =IF(C15=0,"",D15/C15) -> 0.6963469 | F15: =SUMIFS(Cierres!$K$2:$K$478,Cierres!$A$2:$A$478,">="&DATE(2025,7,1),Cierres!$A$2:$A$478,"<="&EOMONTH(DATE(2025,7,1),0),Cierres!$B$2:$B$478,$B15) -> 1403 | G15: =IF(F15=0,"",SUMIFS(Cierres!$J$2:$J$478,Cierres!$A$2:$A$478,">="&DATE(2025,7,1),Cierres!$A$2:$A$478,"<="&EOMONTH(DATE(2025,7,1),0),Cierres!$B$2:$B$478,$B15,Cierres!$K$2:$K$478,">0")/F15) -> 10197.071 | H15: =ROUND(SUMIFS(Cierres!$F$2:$F$478,Cierres!$A$2:$A$478,">="&DATE(2025,7,1),Cierres!$A$2:$A$478,"<="&EOMONTH(DATE(2025,7,1),0),Cierres!$B$2:$B$478,$B15)*Léeme!$B$13+SUMIFS(Cierres!$G$2:$G$478,Cierres!$A$2:$A$478,">="&DATE(2025,7,1),Cierres!$A$2:$A$478,"<="&EOMONTH(DATE(2025,7,1),0),Cierres!$B$2:$B$478,$B15)*Léeme!$B$14+SUMIFS(Cierres!$H$2:$H$478,Cierres!$A$2:$A$478,">="&DATE(2025,7,1),Cierres!$A$2:$A$478,"<="&EOMONTH(DATE(2025,7,1),0),Cierres!$B$2:$B$478,$B15)*Léeme!$B$15,0) -> 64970 | I15: =COUNTIFS(Cierres!$A$2:$A$478,">="&DATE(2025,7,1),Cierres!$A$2:$A$478,"<="&EOMONTH(DATE(2025,7,1),0),Cierres!$B$2:$B$478,$B15,Cierres!$Q$2:$Q$478,"<>") -> 27 | J15: =COUNTIFS(Cierres!$A$2:$A$478,">="&DATE(2025,7,1),Cierres!$A$2:$A$478,"<="&EOMONTH(DATE(2025,7,1),0),Cierres!$B$2:$B$478,$B15,Cierres!$S$2:$S$478,"Cuadra") -> 22 | K15: =IF(I15=0,"",J15/I15) -> 0.81481481 | L15: =-SUMIFS(Cierres!$R$2:$R$478,Cierres!$A$2:$A$478,">="&DATE(2025,7,1),Cierres!$A$2:$A$478,"<="&EOMONTH(DATE(2025,7,1),0),Cierres!$B$2:$B$478,$B15,Cierres!$R$2:$R$478,"<"&-Léeme!$B$12) -> 3520
A16: 2025-08 | B16: Centro | C16: =SUMIFS(Cierres!$J$2:$J$478,Cierres!$A$2:$A$478,">="&DATE(2025,8,1),Cierres!$A$2:$A$478,"<="&EOMONTH(DATE(2025,8,1),0),Cierres!$B$2:$B$478,$B16) -> 19523500 | D16: =SUMIFS(Cierres!$E$2:$E$478,Cierres!$A$2:$A$478,">="&DATE(2025,8,1),Cierres!$A$2:$A$478,"<="&EOMONTH(DATE(2025,8,1),0),Cierres!$B$2:$B$478,$B16) -> 13473090 | E16: =IF(C16=0,"",D16/C16) -> 0.69009604 | F16: =SUMIFS(Cierres!$K$2:$K$478,Cierres!$A$2:$A$478,">="&DATE(2025,8,1),Cierres!$A$2:$A$478,"<="&EOMONTH(DATE(2025,8,1),0),Cierres!$B$2:$B$478,$B16) -> 1861 | G16: =IF(F16=0,"",SUMIFS(Cierres!$J$2:$J$478,Cierres!$A$2:$A$478,">="&DATE(2025,8,1),Cierres!$A$2:$A$478,"<="&EOMONTH(DATE(2025,8,1),0),Cierres!$B$2:$B$478,$B16,Cierres!$K$2:$K$478,">0")/F16) -> 10490.865 | H16: =ROUND(SUMIFS(Cierres!$F$2:$F$478,Cierres!$A$2:$A$478,">="&DATE(2025,8,1),Cierres!$A$2:$A$478,"<="&EOMONTH(DATE(2025,8,1),0),Cierres!$B$2:$B$478,$B16)*Léeme!$B$13+SUMIFS(Cierres!$G$2:$G$478,Cierres!$A$2:$A$478,">="&DATE(2025,8,1),Cierres!$A$2:$A$478,"<="&EOMONTH(DATE(2025,8,1),0),Cierres!$B$2:$B$478,$B16)*Léeme!$B$14+SUMIFS(Cierres!$H$2:$H$478,Cierres!$A$2:$A$478,">="&DATE(2025,8,1),Cierres!$A$2:$A$478,"<="&EOMONTH(DATE(2025,8,1),0),Cierres!$B$2:$B$478,$B16)*Léeme!$B$15,0) -> 89750 | I16: =COUNTIFS(Cierres!$A$2:$A$478,">="&DATE(2025,8,1),Cierres!$A$2:$A$478,"<="&EOMONTH(DATE(2025,8,1),0),Cierres!$B$2:$B$478,$B16,Cierres!$Q$2:$Q$478,"<>") -> 27 | J16: =COUNTIFS(Cierres!$A$2:$A$478,">="&DATE(2025,8,1),Cierres!$A$2:$A$478,"<="&EOMONTH(DATE(2025,8,1),0),Cierres!$B$2:$B$478,$B16,Cierres!$S$2:$S$478,"Cuadra") -> 17 | K16: =IF(I16=0,"",J16/I16) -> 0.62962963 | L16: =-SUMIFS(Cierres!$R$2:$R$478,Cierres!$A$2:$A$478,">="&DATE(2025,8,1),Cierres!$A$2:$A$478,"<="&EOMONTH(DATE(2025,8,1),0),Cierres!$B$2:$B$478,$B16,Cierres!$R$2:$R$478,"<"&-Léeme!$B$12) -> 67100
A17: 2025-08 | B17: Jardín | C17: =SUMIFS(Cierres!$J$2:$J$478,Cierres!$A$2:$A$478,">="&DATE(2025,8,1),Cierres!$A$2:$A$478,"<="&EOMONTH(DATE(2025,8,1),0),Cierres!$B$2:$B$478,$B17) -> 11355740 | D17: =SUMIFS(Cierres!$E$2:$E$478,Cierres!$A$2:$A$478,">="&DATE(2025,8,1),Cierres!$A$2:$A$478,"<="&EOMONTH(DATE(2025,8,1),0),Cierres!$B$2:$B$478,$B17) -> 7807500 | E17: =IF(C17=0,"",D17/C17) -> 0.68753776 | F17: =SUMIFS(Cierres!$K$2:$K$478,Cierres!$A$2:$A$478,">="&DATE(2025,8,1),Cierres!$A$2:$A$478,"<="&EOMONTH(DATE(2025,8,1),0),Cierres!$B$2:$B$478,$B17) -> 1082 | G17: =IF(F17=0,"",SUMIFS(Cierres!$J$2:$J$478,Cierres!$A$2:$A$478,">="&DATE(2025,8,1),Cierres!$A$2:$A$478,"<="&EOMONTH(DATE(2025,8,1),0),Cierres!$B$2:$B$478,$B17,Cierres!$K$2:$K$478,">0")/F17) -> 10495.139 | H17: =ROUND(SUMIFS(Cierres!$F$2:$F$478,Cierres!$A$2:$A$478,">="&DATE(2025,8,1),Cierres!$A$2:$A$478,"<="&EOMONTH(DATE(2025,8,1),0),Cierres!$B$2:$B$478,$B17)*Léeme!$B$13+SUMIFS(Cierres!$G$2:$G$478,Cierres!$A$2:$A$478,">="&DATE(2025,8,1),Cierres!$A$2:$A$478,"<="&EOMONTH(DATE(2025,8,1),0),Cierres!$B$2:$B$478,$B17)*Léeme!$B$14+SUMIFS(Cierres!$H$2:$H$478,Cierres!$A$2:$A$478,">="&DATE(2025,8,1),Cierres!$A$2:$A$478,"<="&EOMONTH(DATE(2025,8,1),0),Cierres!$B$2:$B$478,$B17)*Léeme!$B$15,0) -> 52825 | I17: =COUNTIFS(Cierres!$A$2:$A$478,">="&DATE(2025,8,1),Cierres!$A$2:$A$478,"<="&EOMONTH(DATE(2025,8,1),0),Cierres!$B$2:$B$478,$B17,Cierres!$Q$2:$Q$478,"<>") -> 24 | J17: =COUNTIFS(Cierres!$A$2:$A$478,">="&DATE(2025,8,1),Cierres!$A$2:$A$478,"<="&EOMONTH(DATE(2025,8,1),0),Cierres!$B$2:$B$478,$B17,Cierres!$S$2:$S$478,"Cuadra") -> 23 | K17: =IF(I17=0,"",J17/I17) -> 0.95833333 | L17: =-SUMIFS(Cierres!$R$2:$R$478,Cierres!$A$2:$A$478,">="&DATE(2025,8,1),Cierres!$A$2:$A$478,"<="&EOMONTH(DATE(2025,8,1),0),Cierres!$B$2:$B$478,$B17,Cierres!$R$2:$R$478,"<"&-Léeme!$B$12) -> 610
A18: 2025-09 | B18: Centro | C18: =SUMIFS(Cierres!$J$2:$J$478,Cierres!$A$2:$A$478,">="&DATE(2025,9,1),Cierres!$A$2:$A$478,"<="&EOMONTH(DATE(2025,9,1),0),Cierres!$B$2:$B$478,$B18) -> 15321760 | D18: =SUMIFS(Cierres!$E$2:$E$478,Cierres!$A$2:$A$478,">="&DATE(2025,9,1),Cierres!$A$2:$A$478,"<="&EOMONTH(DATE(2025,9,1),0),Cierres!$B$2:$B$478,$B18) -> 10222300 | E18: =IF(C18=0,"",D18/C18) -> 0.66717531 | F18: =SUMIFS(Cierres!$K$2:$K$478,Cierres!$A$2:$A$478,">="&DATE(2025,9,1),Cierres!$A$2:$A$478,"<="&EOMONTH(DATE(2025,9,1),0),Cierres!$B$2:$B$478,$B18) -> 1407 | G18: =IF(F18=0,"",SUMIFS(Cierres!$J$2:$J$478,Cierres!$A$2:$A$478,">="&DATE(2025,9,1),Cierres!$A$2:$A$478,"<="&EOMONTH(DATE(2025,9,1),0),Cierres!$B$2:$B$478,$B18,Cierres!$K$2:$K$478,">0")/F18) -> 10889.666 | H18: =ROUND(SUMIFS(Cierres!$F$2:$F$478,Cierres!$A$2:$A$478,">="&DATE(2025,9,1),Cierres!$A$2:$A$478,"<="&EOMONTH(DATE(2025,9,1),0),Cierres!$B$2:$B$478,$B18)*Léeme!$B$13+SUMIFS(Cierres!$G$2:$G$478,Cierres!$A$2:$A$478,">="&DATE(2025,9,1),Cierres!$A$2:$A$478,"<="&EOMONTH(DATE(2025,9,1),0),Cierres!$B$2:$B$478,$B18)*Léeme!$B$14+SUMIFS(Cierres!$H$2:$H$478,Cierres!$A$2:$A$478,">="&DATE(2025,9,1),Cierres!$A$2:$A$478,"<="&EOMONTH(DATE(2025,9,1),0),Cierres!$B$2:$B$478,$B18)*Léeme!$B$15,0) -> 75169 | I18: =COUNTIFS(Cierres!$A$2:$A$478,">="&DATE(2025,9,1),Cierres!$A$2:$A$478,"<="&EOMONTH(DATE(2025,9,1),0),Cierres!$B$2:$B$478,$B18,Cierres!$Q$2:$Q$478,"<>") -> 25 | J18: =COUNTIFS(Cierres!$A$2:$A$478,">="&DATE(2025,9,1),Cierres!$A$2:$A$478,"<="&EOMONTH(DATE(2025,9,1),0),Cierres!$B$2:$B$478,$B18,Cierres!$S$2:$S$478,"Cuadra") -> 14 | K18: =IF(I18=0,"",J18/I18) -> 0.56 | L18: =-SUMIFS(Cierres!$R$2:$R$478,Cierres!$A$2:$A$478,">="&DATE(2025,9,1),Cierres!$A$2:$A$478,"<="&EOMONTH(DATE(2025,9,1),0),Cierres!$B$2:$B$478,$B18,Cierres!$R$2:$R$478,"<"&-Léeme!$B$12) -> 40990
A19: 2025-09 | B19: Jardín | C19: =SUMIFS(Cierres!$J$2:$J$478,Cierres!$A$2:$A$478,">="&DATE(2025,9,1),Cierres!$A$2:$A$478,"<="&EOMONTH(DATE(2025,9,1),0),Cierres!$B$2:$B$478,$B19) -> 9568090 | D19: =SUMIFS(Cierres!$E$2:$E$478,Cierres!$A$2:$A$478,">="&DATE(2025,9,1),Cierres!$A$2:$A$478,"<="&EOMONTH(DATE(2025,9,1),0),Cierres!$B$2:$B$478,$B19) -> 6398570 | E19: =IF(C19=0,"",D19/C19) -> 0.66874057 | F19: =SUMIFS(Cierres!$K$2:$K$478,Cierres!$A$2:$A$478,">="&DATE(2025,9,1),Cierres!$A$2:$A$478,"<="&EOMONTH(DATE(2025,9,1),0),Cierres!$B$2:$B$478,$B19) -> 880 | G19: =IF(F19=0,"",SUMIFS(Cierres!$J$2:$J$478,Cierres!$A$2:$A$478,">="&DATE(2025,9,1),Cierres!$A$2:$A$478,"<="&EOMONTH(DATE(2025,9,1),0),Cierres!$B$2:$B$478,$B19,Cierres!$K$2:$K$478,">0")/F19) -> 10872.83 | H19: =ROUND(SUMIFS(Cierres!$F$2:$F$478,Cierres!$A$2:$A$478,">="&DATE(2025,9,1),Cierres!$A$2:$A$478,"<="&EOMONTH(DATE(2025,9,1),0),Cierres!$B$2:$B$478,$B19)*Léeme!$B$13+SUMIFS(Cierres!$G$2:$G$478,Cierres!$A$2:$A$478,">="&DATE(2025,9,1),Cierres!$A$2:$A$478,"<="&EOMONTH(DATE(2025,9,1),0),Cierres!$B$2:$B$478,$B19)*Léeme!$B$14+SUMIFS(Cierres!$H$2:$H$478,Cierres!$A$2:$A$478,">="&DATE(2025,9,1),Cierres!$A$2:$A$478,"<="&EOMONTH(DATE(2025,9,1),0),Cierres!$B$2:$B$478,$B19)*Léeme!$B$15,0) -> 47035 | I19: =COUNTIFS(Cierres!$A$2:$A$478,">="&DATE(2025,9,1),Cierres!$A$2:$A$478,"<="&EOMONTH(DATE(2025,9,1),0),Cierres!$B$2:$B$478,$B19,Cierres!$Q$2:$Q$478,"<>") -> 23 | J19: =COUNTIFS(Cierres!$A$2:$A$478,">="&DATE(2025,9,1),Cierres!$A$2:$A$478,"<="&EOMONTH(DATE(2025,9,1),0),Cierres!$B$2:$B$478,$B19,Cierres!$S$2:$S$478,"Cuadra") -> 19 | K19: =IF(I19=0,"",J19/I19) -> 0.82608696 | L19: =-SUMIFS(Cierres!$R$2:$R$478,Cierres!$A$2:$A$478,">="&DATE(2025,9,1),Cierres!$A$2:$A$478,"<="&EOMONTH(DATE(2025,9,1),0),Cierres!$B$2:$B$478,$B19,Cierres!$R$2:$R$478,"<"&-Léeme!$B$12) -> 1720
A20: 2025-10 | B20: Centro | C20: =SUMIFS(Cierres!$J$2:$J$478,Cierres!$A$2:$A$478,">="&DATE(2025,10,1),Cierres!$A$2:$A$478,"<="&EOMONTH(DATE(2025,10,1),0),Cierres!$B$2:$B$478,$B20) -> 4916270 | D20: =SUMIFS(Cierres!$E$2:$E$478,Cierres!$A$2:$A$478,">="&DATE(2025,10,1),Cierres!$A$2:$A$478,"<="&EOMONTH(DATE(2025,10,1),0),Cierres!$B$2:$B$478,$B20) -> 3282600 | E20: =IF(C20=0,"",D20/C20) -> 0.66770133 | F20: =SUMIFS(Cierres!$K$2:$K$478,Cierres!$A$2:$A$478,">="&DATE(2025,10,1),Cierres!$A$2:$A$478,"<="&EOMONTH(DATE(2025,10,1),0),Cierres!$B$2:$B$478,$B20) -> 440 | G20: =IF(F20=0,"",SUMIFS(Cierres!$J$2:$J$478,Cierres!$A$2:$A$478,">="&DATE(2025,10,1),Cierres!$A$2:$A$478,"<="&EOMONTH(DATE(2025,10,1),0),Cierres!$B$2:$B$478,$B20,Cierres!$K$2:$K$478,">0")/F20) -> 11173.341 | H20: =ROUND(SUMIFS(Cierres!$F$2:$F$478,Cierres!$A$2:$A$478,">="&DATE(2025,10,1),Cierres!$A$2:$A$478,"<="&EOMONTH(DATE(2025,10,1),0),Cierres!$B$2:$B$478,$B20)*Léeme!$B$13+SUMIFS(Cierres!$G$2:$G$478,Cierres!$A$2:$A$478,">="&DATE(2025,10,1),Cierres!$A$2:$A$478,"<="&EOMONTH(DATE(2025,10,1),0),Cierres!$B$2:$B$478,$B20)*Léeme!$B$14+SUMIFS(Cierres!$H$2:$H$478,Cierres!$A$2:$A$478,">="&DATE(2025,10,1),Cierres!$A$2:$A$478,"<="&EOMONTH(DATE(2025,10,1),0),Cierres!$B$2:$B$478,$B20)*Léeme!$B$15,0) -> 23890 | I20: =COUNTIFS(Cierres!$A$2:$A$478,">="&DATE(2025,10,1),Cierres!$A$2:$A$478,"<="&EOMONTH(DATE(2025,10,1),0),Cierres!$B$2:$B$478,$B20,Cierres!$Q$2:$Q$478,"<>") -> 8 | J20: =COUNTIFS(Cierres!$A$2:$A$478,">="&DATE(2025,10,1),Cierres!$A$2:$A$478,"<="&EOMONTH(DATE(2025,10,1),0),Cierres!$B$2:$B$478,$B20,Cierres!$S$2:$S$478,"Cuadra") -> 6 | K20: =IF(I20=0,"",J20/I20) -> 0.75 | L20: =-SUMIFS(Cierres!$R$2:$R$478,Cierres!$A$2:$A$478,">="&DATE(2025,10,1),Cierres!$A$2:$A$478,"<="&EOMONTH(DATE(2025,10,1),0),Cierres!$B$2:$B$478,$B20,Cierres!$R$2:$R$478,"<"&-Léeme!$B$12) -> 15100
A21: 2025-10 | B21: Jardín | C21: =SUMIFS(Cierres!$J$2:$J$478,Cierres!$A$2:$A$478,">="&DATE(2025,10,1),Cierres!$A$2:$A$478,"<="&EOMONTH(DATE(2025,10,1),0),Cierres!$B$2:$B$478,$B21) -> 3637310 | D21: =SUMIFS(Cierres!$E$2:$E$478,Cierres!$A$2:$A$478,">="&DATE(2025,10,1),Cierres!$A$2:$A$478,"<="&EOMONTH(DATE(2025,10,1),0),Cierres!$B$2:$B$478,$B21) -> 2402360 | E21: =IF(C21=0,"",D21/C21) -> 0.66047711 | F21: =SUMIFS(Cierres!$K$2:$K$478,Cierres!$A$2:$A$478,">="&DATE(2025,10,1),Cierres!$A$2:$A$478,"<="&EOMONTH(DATE(2025,10,1),0),Cierres!$B$2:$B$478,$B21) -> 321 | G21: =IF(F21=0,"",SUMIFS(Cierres!$J$2:$J$478,Cierres!$A$2:$A$478,">="&DATE(2025,10,1),Cierres!$A$2:$A$478,"<="&EOMONTH(DATE(2025,10,1),0),Cierres!$B$2:$B$478,$B21,Cierres!$K$2:$K$478,">0")/F21) -> 11331.184 | H21: =ROUND(SUMIFS(Cierres!$F$2:$F$478,Cierres!$A$2:$A$478,">="&DATE(2025,10,1),Cierres!$A$2:$A$478,"<="&EOMONTH(DATE(2025,10,1),0),Cierres!$B$2:$B$478,$B21)*Léeme!$B$13+SUMIFS(Cierres!$G$2:$G$478,Cierres!$A$2:$A$478,">="&DATE(2025,10,1),Cierres!$A$2:$A$478,"<="&EOMONTH(DATE(2025,10,1),0),Cierres!$B$2:$B$478,$B21)*Léeme!$B$14+SUMIFS(Cierres!$H$2:$H$478,Cierres!$A$2:$A$478,">="&DATE(2025,10,1),Cierres!$A$2:$A$478,"<="&EOMONTH(DATE(2025,10,1),0),Cierres!$B$2:$B$478,$B21)*Léeme!$B$15,0) -> 18085 | I21: =COUNTIFS(Cierres!$A$2:$A$478,">="&DATE(2025,10,1),Cierres!$A$2:$A$478,"<="&EOMONTH(DATE(2025,10,1),0),Cierres!$B$2:$B$478,$B21,Cierres!$Q$2:$Q$478,"<>") -> 8 | J21: =COUNTIFS(Cierres!$A$2:$A$478,">="&DATE(2025,10,1),Cierres!$A$2:$A$478,"<="&EOMONTH(DATE(2025,10,1),0),Cierres!$B$2:$B$478,$B21,Cierres!$S$2:$S$478,"Cuadra") -> 7 | K21: =IF(I21=0,"",J21/I21) -> 0.875 | L21: =-SUMIFS(Cierres!$R$2:$R$478,Cierres!$A$2:$A$478,">="&DATE(2025,10,1),Cierres!$A$2:$A$478,"<="&EOMONTH(DATE(2025,10,1),0),Cierres!$B$2:$B$478,$B21,Cierres!$R$2:$R$478,"<"&-Léeme!$B$12) -> 0
A23: Fórmulas sobre la hoja Cierres. Hasta mayo (Excel) no hay tickets ni arqueo; hasta marzo la billetera está dentro de transferencia.

Sheet Fiado
A1: Cliente | B1: Nombre | C1: Condición | D1: Comprado a cuenta | E1: Cobrado | F1: Saldo | G1: Saldo del motor | H1: Control | I1: Comprado a cuenta (90 d) | J1: Cobrado (90 d) | K1: Pagó de lo comprado | L1: Estado
A2: 1 | B2: Restaurante La Esquina | C2: Cuenta corriente | D2: =SUMIFS(Pedidos!$D$2:$D$732,Pedidos!$B$2:$B$732,A2,Pedidos!$E$2:$E$732,"Cuenta corriente") -> 3654800 | E2: =SUMIFS(Cobros!$D$2:$D$353,Cobros!$B$2:$B$353,A2) -> 3487700 | F2: =IF(D2=0,"",D2-E2) -> 167100 | G2: 167100 | H2: =IF(G2="","",IF(F2=G2,"OK","Revisar")) -> OK | I2: =SUMIFS(Pedidos!$D$2:$D$732,Pedidos!$B$2:$B$732,A2,Pedidos!$E$2:$E$732,"Cuenta corriente",Pedidos!$A$2:$A$732,">"&Léeme!$B$11-90) -> 1330700 | J2: =SUMIFS(Cobros!$D$2:$D$353,Cobros!$B$2:$B$353,A2,Cobros!$A$2:$A$353,">"&Léeme!$B$11-90) -> 1213000 | K2: =IF(I2=0,"",J2/I2) -> 0.91155031 | L2: Activo
A3: 2 | B3: Rotisería El Buen Gusto | C3: Contado | D3: =SUMIFS(Pedidos!$D$2:$D$732,Pedidos!$B$2:$B$732,A3,Pedidos!$E$2:$E$732,"Cuenta corriente") -> 0 | E3: =SUMIFS(Cobros!$D$2:$D$353,Cobros!$B$2:$B$353,A3) -> 1039700 | F3: =IF(D3=0,"",D3-E3) | H3: =IF(G3="","",IF(F3=G3,"OK","Revisar")) | I3: =SUMIFS(Pedidos!$D$2:$D$732,Pedidos!$B$2:$B$732,A3,Pedidos!$E$2:$E$732,"Cuenta corriente",Pedidos!$A$2:$A$732,">"&Léeme!$B$11-90) -> 0 | J3: =SUMIFS(Cobros!$D$2:$D$353,Cobros!$B$2:$B$353,A3,Cobros!$A$2:$A$353,">"&Léeme!$B$11-90) -> 725200 | K3: =IF(I3=0,"",J3/I3) | L3: Activo
A4: 3 | B4: Almacén Doña Rosa | C4: Cuenta corriente | D4: =SUMIFS(Pedidos!$D$2:$D$732,Pedidos!$B$2:$B$732,A4,Pedidos!$E$2:$E$732,"Cuenta corriente") -> 4064600 | E4: =SUMIFS(Cobros!$D$2:$D$353,Cobros!$B$2:$B$353,A4) -> 4007200 | F4: =IF(D4=0,"",D4-E4) -> 57400 | G4: 57400 | H4: =IF(G4="","",IF(F4=G4,"OK","Revisar")) -> OK | I4: =SUMIFS(Pedidos!$D$2:$D$732,Pedidos!$B$2:$B$732,A4,Pedidos!$E$2:$E$732,"Cuenta corriente",Pedidos!$A$2:$A$732,">"&Léeme!$B$11-90) -> 0 | J4: =SUMIFS(Cobros!$D$2:$D$353,Cobros!$B$2:$B$353,A4,Cobros!$A$2:$A$353,">"&Léeme!$B$11-90) -> 0 | K4: =IF(I4=0,"",J4/I4) | L4: Dejó de comprar
A5: 4 | B5: Bodegón Los Abuelos | C5: Cuenta corriente | D5: =SUMIFS(Pedidos!$D$2:$D$732,Pedidos!$B$2:$B$732,A5,Pedidos!$E$2:$E$732,"Cuenta corriente") -> 4973800 | E5: =SUMIFS(Cobros!$D$2:$D$353,Cobros!$B$2:$B$353,A5) -> 4645600 | F5: =IF(D5=0,"",D5-E5) -> 328200 | G5: 328200 | H5: =IF(G5="","",IF(F5=G5,"OK","Revisar")) -> OK | I5: =SUMIFS(Pedidos!$D$2:$D$732,Pedidos!$B$2:$B$732,A5,Pedidos!$E$2:$E$732,"Cuenta corriente",Pedidos!$A$2:$A$732,">"&Léeme!$B$11-90) -> 1627200 | J5: =SUMIFS(Cobros!$D$2:$D$353,Cobros!$B$2:$B$353,A5,Cobros!$A$2:$A$353,">"&Léeme!$B$11-90) -> 1718200 | K5: =IF(I5=0,"",J5/I5) -> 1.0559243 | L5: Activo
A6: 5 | B6: Cantina del Puerto | C6: Cuenta corriente | D6: =SUMIFS(Pedidos!$D$2:$D$732,Pedidos!$B$2:$B$732,A6,Pedidos!$E$2:$E$732,"Cuenta corriente") -> 5903900 | E6: =SUMIFS(Cobros!$D$2:$D$353,Cobros!$B$2:$B$353,A6) -> 5301900 | F6: =IF(D6=0,"",D6-E6) -> 602000 | G6: 602000 | H6: =IF(G6="","",IF(F6=G6,"OK","Revisar")) -> OK | I6: =SUMIFS(Pedidos!$D$2:$D$732,Pedidos!$B$2:$B$732,A6,Pedidos!$E$2:$E$732,"Cuenta corriente",Pedidos!$A$2:$A$732,">"&Léeme!$B$11-90) -> 2135600 | J6: =SUMIFS(Cobros!$D$2:$D$353,Cobros!$B$2:$B$353,A6,Cobros!$A$2:$A$353,">"&Léeme!$B$11-90) -> 1554500 | K6: =IF(I6=0,"",J6/I6) -> 0.72789848 | L6: Activo
A7: 6 | B7: Rotisería Sabores | C7: Cuenta corriente | D7: =SUMIFS(Pedidos!$D$2:$D$732,Pedidos!$B$2:$B$732,A7,Pedidos!$E$2:$E$732,"Cuenta corriente") -> 1516200 | E7: =SUMIFS(Cobros!$D$2:$D$353,Cobros!$B$2:$B$353,A7) -> 1501800 | F7: =IF(D7=0,"",D7-E7) -> 14400 | G7: 14400 | H7: =IF(G7="","",IF(F7=G7,"OK","Revisar")) -> OK | I7: =SUMIFS(Pedidos!$D$2:$D$732,Pedidos!$B$2:$B$732,A7,Pedidos!$E$2:$E$732,"Cuenta corriente",Pedidos!$A$2:$A$732,">"&Léeme!$B$11-90) -> 482200 | J7: =SUMIFS(Cobros!$D$2:$D$353,Cobros!$B$2:$B$353,A7,Cobros!$A$2:$A$353,">"&Léeme!$B$11-90) -> 475600 | K7: =IF(I7=0,"",J7/I7) -> 0.98631273 | L7: Compra menos seguido
A8: 7 | B8: Restaurante Il Forno | C8: Cuenta corriente | D8: =SUMIFS(Pedidos!$D$2:$D$732,Pedidos!$B$2:$B$732,A8,Pedidos!$E$2:$E$732,"Cuenta corriente") -> 1907400 | E8: =SUMIFS(Cobros!$D$2:$D$353,Cobros!$B$2:$B$353,A8) -> 1826200 | F8: =IF(D8=0,"",D8-E8) -> 81200 | G8: 81200 | H8: =IF(G8="","",IF(F8=G8,"OK","Revisar")) -> OK | I8: =SUMIFS(Pedidos!$D$2:$D$732,Pedidos!$B$2:$B$732,A8,Pedidos!$E$2:$E$732,"Cuenta corriente",Pedidos!$A$2:$A$732,">"&Léeme!$B$11-90) -> 692100 | J8: =SUMIFS(Cobros!$D$2:$D$353,Cobros!$B$2:$B$353,A8,Cobros!$A$2:$A$353,">"&Léeme!$B$11-90) -> 614100 | K8: =IF(I8=0,"",J8/I8) -> 0.88729952 | L8: Activo
A9: 8 | B9: Almacén San Martín | C9: Contado | D9: =SUMIFS(Pedidos!$D$2:$D$732,Pedidos!$B$2:$B$732,A9,Pedidos!$E$2:$E$732,"Cuenta corriente") -> 0 | E9: =SUMIFS(Cobros!$D$2:$D$353,Cobros!$B$2:$B$353,A9) -> 4703400 | F9: =IF(D9=0,"",D9-E9) | H9: =IF(G9="","",IF(F9=G9,"OK","Revisar")) | I9: =SUMIFS(Pedidos!$D$2:$D$732,Pedidos!$B$2:$B$732,A9,Pedidos!$E$2:$E$732,"Cuenta corriente",Pedidos!$A$2:$A$732,">"&Léeme!$B$11-90) -> 0 | J9: =SUMIFS(Cobros!$D$2:$D$353,Cobros!$B$2:$B$353,A9,Cobros!$A$2:$A$353,">"&Léeme!$B$11-90) -> 3475700 | K9: =IF(I9=0,"",J9/I9) | L9: Activo
A10: 9 | B10: Club Atlético Villa Sur | C10: Contado | D10: =SUMIFS(Pedidos!$D$2:$D$732,Pedidos!$B$2:$B$732,A10,Pedidos!$E$2:$E$732,"Cuenta corriente") -> 0 | E10: =SUMIFS(Cobros!$D$2:$D$353,Cobros!$B$2:$B$353,A10) -> 950100 | F10: =IF(D10=0,"",D10-E10) | H10: =IF(G10="","",IF(F10=G10,"OK","Revisar")) | I10: =SUMIFS(Pedidos!$D$2:$D$732,Pedidos!$B$2:$B$732,A10,Pedidos!$E$2:$E$732,"Cuenta corriente",Pedidos!$A$2:$A$732,">"&Léeme!$B$11-90) -> 0 | J10: =SUMIFS(Cobros!$D$2:$D$353,Cobros!$B$2:$B$353,A10,Cobros!$A$2:$A$353,">"&Léeme!$B$11-90) -> 660500 | K10: =IF(I10=0,"",J10/I10) | L10: Activo
A11: 10 | B11: Parrilla El Fogón | C11: Cuenta corriente | D11: =SUMIFS(Pedidos!$D$2:$D$732,Pedidos!$B$2:$B$732,A11,Pedidos!$E$2:$E$732,"Cuenta corriente") -> 1681300 | E11: =SUMIFS(Cobros!$D$2:$D$353,Cobros!$B$2:$B$353,A11) -> 1529400 | F11: =IF(D11=0,"",D11-E11) -> 151900 | G11: 151900 | H11: =IF(G11="","",IF(F11=G11,"OK","Revisar")) -> OK | I11: =SUMIFS(Pedidos!$D$2:$D$732,Pedidos!$B$2:$B$732,A11,Pedidos!$E$2:$E$732,"Cuenta corriente",Pedidos!$A$2:$A$732,">"&Léeme!$B$11-90) -> 206000 | J11: =SUMIFS(Cobros!$D$2:$D$353,Cobros!$B$2:$B$353,A11,Cobros!$A$2:$A$353,">"&Léeme!$B$11-90) -> 213900 | K11: =IF(I11=0,"",J11/I11) -> 1.0383495 | L11: Dejó de comprar
A12: 11 | B12: Bar La Plaza | C12: Contado | D12: =SUMIFS(Pedidos!$D$2:$D$732,Pedidos!$B$2:$B$732,A12,Pedidos!$E$2:$E$732,"Cuenta corriente") -> 0 | E12: =SUMIFS(Cobros!$D$2:$D$353,Cobros!$B$2:$B$353,A12) -> 2368400 | F12: =IF(D12=0,"",D12-E12) | H12: =IF(G12="","",IF(F12=G12,"OK","Revisar")) | I12: =SUMIFS(Pedidos!$D$2:$D$732,Pedidos!$B$2:$B$732,A12,Pedidos!$E$2:$E$732,"Cuenta corriente",Pedidos!$A$2:$A$732,">"&Léeme!$B$11-90) -> 0 | J12: =SUMIFS(Cobros!$D$2:$D$353,Cobros!$B$2:$B$353,A12,Cobros!$A$2:$A$353,">"&Léeme!$B$11-90) -> 1726000 | K12: =IF(I12=0,"",J12/I12) | L12: Activo
A13: 12 | B13: Rotisería La Nonna | C13: Contado | D13: =SUMIFS(Pedidos!$D$2:$D$732,Pedidos!$B$2:$B$732,A13,Pedidos!$E$2:$E$732,"Cuenta corriente") -> 0 | E13: =SUMIFS(Cobros!$D$2:$D$353,Cobros!$B$2:$B$353,A13) -> 1417200 | F13: =IF(D13=0,"",D13-E13) | H13: =IF(G13="","",IF(F13=G13,"OK","Revisar")) | I13: =SUMIFS(Pedidos!$D$2:$D$732,Pedidos!$B$2:$B$732,A13,Pedidos!$E$2:$E$732,"Cuenta corriente",Pedidos!$A$2:$A$732,">"&Léeme!$B$11-90) -> 0 | J13: =SUMIFS(Cobros!$D$2:$D$353,Cobros!$B$2:$B$353,A13,Cobros!$A$2:$A$353,">"&Léeme!$B$11-90) -> 1142800 | K13: =IF(I13=0,"",J13/I13) | L13: Activo
A14: 13 | B14: Restaurante Mediterráneo | C14: Cuenta corriente | D14: =SUMIFS(Pedidos!$D$2:$D$732,Pedidos!$B$2:$B$732,A14,Pedidos!$E$2:$E$732,"Cuenta corriente") -> 1448200 | E14: =SUMIFS(Cobros!$D$2:$D$353,Cobros!$B$2:$B$353,A14) -> 1187700 | F14: =IF(D14=0,"",D14-E14) -> 260500 | G14: 260500 | H14: =IF(G14="","",IF(F14=G14,"OK","Revisar")) -> OK | I14: =SUMIFS(Pedidos!$D$2:$D$732,Pedidos!$B$2:$B$732,A14,Pedidos!$E$2:$E$732,"Cuenta corriente",Pedidos!$A$2:$A$732,">"&Léeme!$B$11-90) -> 556900 | J14: =SUMIFS(Cobros!$D$2:$D$353,Cobros!$B$2:$B$353,A14,Cobros!$A$2:$A$353,">"&Léeme!$B$11-90) -> 349400 | K14: =IF(I14=0,"",J14/I14) -> 0.62740169 | L14: Activo · paga menos
A15: 14 | B15: Almacén El Trébol | C15: Cuenta corriente | D15: =SUMIFS(Pedidos!$D$2:$D$732,Pedidos!$B$2:$B$732,A15,Pedidos!$E$2:$E$732,"Cuenta corriente") -> 3867000 | E15: =SUMIFS(Cobros!$D$2:$D$353,Cobros!$B$2:$B$353,A15) -> 3654000 | F15: =IF(D15=0,"",D15-E15) -> 213000 | G15: 213000 | H15: =IF(G15="","",IF(F15=G15,"OK","Revisar")) -> OK | I15: =SUMIFS(Pedidos!$D$2:$D$732,Pedidos!$B$2:$B$732,A15,Pedidos!$E$2:$E$732,"Cuenta corriente",Pedidos!$A$2:$A$732,">"&Léeme!$B$11-90) -> 1220300 | J15: =SUMIFS(Cobros!$D$2:$D$353,Cobros!$B$2:$B$353,A15,Cobros!$A$2:$A$353,">"&Léeme!$B$11-90) -> 1301200 | K15: =IF(I15=0,"",J15/I15) -> 1.0662952 | L15: Activo
A16: 15 | B16: Comedor Escolar Norte | C16: Cuenta corriente | D16: =SUMIFS(Pedidos!$D$2:$D$732,Pedidos!$B$2:$B$732,A16,Pedidos!$E$2:$E$732,"Cuenta corriente") -> 5105800 | E16: =SUMIFS(Cobros!$D$2:$D$353,Cobros!$B$2:$B$353,A16) -> 4929400 | F16: =IF(D16=0,"",D16-E16) -> 176400 | G16: 176400 | H16: =IF(G16="","",IF(F16=G16,"OK","Revisar")) -> OK | I16: =SUMIFS(Pedidos!$D$2:$D$732,Pedidos!$B$2:$B$732,A16,Pedidos!$E$2:$E$732,"Cuenta corriente",Pedidos!$A$2:$A$732,">"&Léeme!$B$11-90) -> 1725000 | J16: =SUMIFS(Cobros!$D$2:$D$353,Cobros!$B$2:$B$353,A16,Cobros!$A$2:$A$353,">"&Léeme!$B$11-90) -> 1689600 | K16: =IF(I16=0,"",J16/I16) -> 0.97947826 | L16: Activo
A17: 16 | B17: Trattoria Bella Vista | C17: Contado | D17: =SUMIFS(Pedidos!$D$2:$D$732,Pedidos!$B$2:$B$732,A17,Pedidos!$E$2:$E$732,"Cuenta corriente") -> 0 | E17: =SUMIFS(Cobros!$D$2:$D$353,Cobros!$B$2:$B$353,A17) -> 1578000 | F17: =IF(D17=0,"",D17-E17) | H17: =IF(G17="","",IF(F17=G17,"OK","Revisar")) | I17: =SUMIFS(Pedidos!$D$2:$D$732,Pedidos!$B$2:$B$732,A17,Pedidos!$E$2:$E$732,"Cuenta corriente",Pedidos!$A$2:$A$732,">"&Léeme!$B$11-90) -> 0 | J17: =SUMIFS(Cobros!$D$2:$D$353,Cobros!$B$2:$B$353,A17,Cobros!$A$2:$A$353,">"&Léeme!$B$11-90) -> 1091500 | K17: =IF(I17=0,"",J17/I17) | L17: Activo
A18: 17 | B18: Rotisería Don Pepe | C18: Cuenta corriente | D18: =SUMIFS(Pedidos!$D$2:$D$732,Pedidos!$B$2:$B$732,A18,Pedidos!$E$2:$E$732,"Cuenta corriente") -> 1691500 | E18: =SUMIFS(Cobros!$D$2:$D$353,Cobros!$B$2:$B$353,A18) -> 1562400 | F18: =IF(D18=0,"",D18-E18) -> 129100 | G18: 129100 | H18: =IF(G18="","",IF(F18=G18,"OK","Revisar")) -> OK | I18: =SUMIFS(Pedidos!$D$2:$D$732,Pedidos!$B$2:$B$732,A18,Pedidos!$E$2:$E$732,"Cuenta corriente",Pedidos!$A$2:$A$732,">"&Léeme!$B$11-90) -> 329900 | J18: =SUMIFS(Cobros!$D$2:$D$353,Cobros!$B$2:$B$353,A18,Cobros!$A$2:$A$353,">"&Léeme!$B$11-90) -> 343200 | K18: =IF(I18=0,"",J18/I18) -> 1.0403152 | L18: Dejó de comprar
A19: 18 | B19: Restaurante Las Tinajas | C19: Contado | D19: =SUMIFS(Pedidos!$D$2:$D$732,Pedidos!$B$2:$B$732,A19,Pedidos!$E$2:$E$732,"Cuenta corriente") -> 0 | E19: =SUMIFS(Cobros!$D$2:$D$353,Cobros!$B$2:$B$353,A19) -> 1334400 | F19: =IF(D19=0,"",D19-E19) | H19: =IF(G19="","",IF(F19=G19,"OK","Revisar")) | I19: =SUMIFS(Pedidos!$D$2:$D$732,Pedidos!$B$2:$B$732,A19,Pedidos!$E$2:$E$732,"Cuenta corriente",Pedidos!$A$2:$A$732,">"&Léeme!$B$11-90) -> 0 | J19: =SUMIFS(Cobros!$D$2:$D$353,Cobros!$B$2:$B$353,A19,Cobros!$A$2:$A$353,">"&Léeme!$B$11-90) -> 1019400 | K19: =IF(I19=0,"",J19/I19) | L19: Activo
A20: 19 | B20: Bar del Centro | C20: Cuenta corriente | D20: =SUMIFS(Pedidos!$D$2:$D$732,Pedidos!$B$2:$B$732,A20,Pedidos!$E$2:$E$732,"Cuenta corriente") -> 7778500 | E20: =SUMIFS(Cobros!$D$2:$D$353,Cobros!$B$2:$B$353,A20) -> 7654600 | F20: =IF(D20=0,"",D20-E20) -> 123900 | G20: 123900 | H20: =IF(G20="","",IF(F20=G20,"OK","Revisar")) -> OK | I20: =SUMIFS(Pedidos!$D$2:$D$732,Pedidos!$B$2:$B$732,A20,Pedidos!$E$2:$E$732,"Cuenta corriente",Pedidos!$A$2:$A$732,">"&Léeme!$B$11-90) -> 3007700 | J20: =SUMIFS(Cobros!$D$2:$D$353,Cobros!$B$2:$B$353,A20,Cobros!$A$2:$A$353,">"&Léeme!$B$11-90) -> 2996700 | K20: =IF(I20=0,"",J20/I20) -> 0.99634272 | L20: Activo
A21: 20 | B21: Almacén Los Pinos | C21: Cuenta corriente | D21: =SUMIFS(Pedidos!$D$2:$D$732,Pedidos!$B$2:$B$732,A21,Pedidos!$E$2:$E$732,"Cuenta corriente") -> 4802500 | E21: =SUMIFS(Cobros!$D$2:$D$353,Cobros!$B$2:$B$353,A21) -> 4624400 | F21: =IF(D21=0,"",D21-E21) -> 178100 | G21: 178100 | H21: =IF(G21="","",IF(F21=G21,"OK","Revisar")) -> OK | I21: =SUMIFS(Pedidos!$D$2:$D$732,Pedidos!$B$2:$B$732,A21,Pedidos!$E$2:$E$732,"Cuenta corriente",Pedidos!$A$2:$A$732,">"&Léeme!$B$11-90) -> 1420000 | J21: =SUMIFS(Cobros!$D$2:$D$353,Cobros!$B$2:$B$353,A21,Cobros!$A$2:$A$353,">"&Léeme!$B$11-90) -> 1460400 | K21: =IF(I21=0,"",J21/I21) -> 1.0284507 | L21: Activo
A22: 21 | B22: Restaurante Tierra Nuestra | C22: Cuenta corriente | D22: =SUMIFS(Pedidos!$D$2:$D$732,Pedidos!$B$2:$B$732,A22,Pedidos!$E$2:$E$732,"Cuenta corriente") -> 2769700 | E22: =SUMIFS(Cobros!$D$2:$D$353,Cobros!$B$2:$B$353,A22) -> 2769100 | F22: =IF(D22=0,"",D22-E22) -> 600 | G22: 600 | H22: =IF(G22="","",IF(F22=G22,"OK","Revisar")) -> OK | I22: =SUMIFS(Pedidos!$D$2:$D$732,Pedidos!$B$2:$B$732,A22,Pedidos!$E$2:$E$732,"Cuenta corriente",Pedidos!$A$2:$A$732,">"&Léeme!$B$11-90) -> 857300 | J22: =SUMIFS(Cobros!$D$2:$D$353,Cobros!$B$2:$B$353,A22,Cobros!$A$2:$A$353,">"&Léeme!$B$11-90) -> 880500 | K22: =IF(I22=0,"",J22/I22) -> 1.0270617 | L22: En riesgo
A23: 22 | B23: Rotisería La Familia | C23: Contado | D23: =SUMIFS(Pedidos!$D$2:$D$732,Pedidos!$B$2:$B$732,A23,Pedidos!$E$2:$E$732,"Cuenta corriente") -> 0 | E23: =SUMIFS(Cobros!$D$2:$D$353,Cobros!$B$2:$B$353,A23) -> 4820600 | F23: =IF(D23=0,"",D23-E23) | H23: =IF(G23="","",IF(F23=G23,"OK","Revisar")) | I23: =SUMIFS(Pedidos!$D$2:$D$732,Pedidos!$B$2:$B$732,A23,Pedidos!$E$2:$E$732,"Cuenta corriente",Pedidos!$A$2:$A$732,">"&Léeme!$B$11-90) -> 0 | J23: =SUMIFS(Cobros!$D$2:$D$353,Cobros!$B$2:$B$353,A23,Cobros!$A$2:$A$353,">"&Léeme!$B$11-90) -> 3412700 | K23: =IF(I23=0,"",J23/I23) | L23: Activo
A24: 23 | B24: Hotel Cerro Azul | C24: Contado | D24: =SUMIFS(Pedidos!$D$2:$D$732,Pedidos!$B$2:$B$732,A24,Pedidos!$E$2:$E$732,"Cuenta corriente") -> 0 | E24: =SUMIFS(Cobros!$D$2:$D$353,Cobros!$B$2:$B$353,A24) -> 2650100 | F24: =IF(D24=0,"",D24-E24) | H24: =IF(G24="","",IF(F24=G24,"OK","Revisar")) | I24: =SUMIFS(Pedidos!$D$2:$D$732,Pedidos!$B$2:$B$732,A24,Pedidos!$E$2:$E$732,"Cuenta corriente",Pedidos!$A$2:$A$732,">"&Léeme!$B$11-90) -> 0 | J24: =SUMIFS(Cobros!$D$2:$D$353,Cobros!$B$2:$B$353,A24,Cobros!$A$2:$A$353,">"&Léeme!$B$11-90) -> 1917100 | K24: =IF(I24=0,"",J24/I24) | L24: Activo
A25: 24 | B25: Restaurante El Molino | C25: Cuenta corriente | D25: =SUMIFS(Pedidos!$D$2:$D$732,Pedidos!$B$2:$B$732,A25,Pedidos!$E$2:$E$732,"Cuenta corriente") -> 956100 | E25: =SUMIFS(Cobros!$D$2:$D$353,Cobros!$B$2:$B$353,A25) -> 767000 | F25: =IF(D25=0,"",D25-E25) -> 189100 | G25: 189100 | H25: =IF(G25="","",IF(F25=G25,"OK","Revisar")) -> OK | I25: =SUMIFS(Pedidos!$D$2:$D$732,Pedidos!$B$2:$B$732,A25,Pedidos!$E$2:$E$732,"Cuenta corriente",Pedidos!$A$2:$A$732,">"&Léeme!$B$11-90) -> 956100 | J25: =SUMIFS(Cobros!$D$2:$D$353,Cobros!$B$2:$B$353,A25,Cobros!$A$2:$A$353,">"&Léeme!$B$11-90) -> 767000 | K25: =IF(I25=0,"",J25/I25) -> 0.80221734 | L25: Nuevo

Sheet Cierres
A1: Fecha | B1: Local | C1: Responsable | D1: Fuente | E1: Efectivo | F1: Débito | G1: Crédito | H1: Billetera virtual | I1: Transferencia | J1: Venta total | K1: Tickets | L1: Gasto con la caja | M1: Concepto | N1: Retiro del dueño | O1: Fondo | P1: Efectivo esperado | Q1: Efectivo contado | R1: Diferencia | S1: Caja | T1: Incompleta
A2: 45659 | B2: Centro | D2: Excel | E2: 290670 | F2: 35160 | G2: 14700 | H2: 0 | I2: 19770 | J2: =SUM(E2:I2) -> 360300 | L2: 0 | N2: 256000 | P2: =IF(O2="","",O2+E2-L2-N2) | R2: =IF(OR(Q2="",P2=""),"",Q2-P2) | S2: =IF(R2="","",IF(ABS(R2)<=Léeme!$B$12,"Cuadra",IF(R2<0,"Faltante","Sobrante"))) | T2: No
A3: 45659 | B3: Jardín | D3: Excel | E3: 212420 | F3: 26850 | G3: 9720 | H3: 0 | I3: 15960 | J3: =SUM(E3:I3) -> 264950 | L3: 0 | N3: 0 | P3: =IF(O3="","",O3+E3-L3-N3) | R3: =IF(OR(Q3="",P3=""),"",Q3-P3) | S3: =IF(R3="","",IF(ABS(R3)<=Léeme!$B$12,"Cuadra",IF(R3<0,"Faltante","Sobrante"))) | T3: No
A4: 45660 | B4: Centro | D4: Excel | E4: 262960 | F4: 34000 | G4: 12360 | H4: 0 | I4: 21370 | J4: =SUM(E4:I4) -> 330690 | L4: 12950 | M4: Envases | N4: 0 | P4: =IF(O4="","",O4+E4-L4-N4) | R4: =IF(OR(Q4="",P4=""),"",Q4-P4) | S4: =IF(R4="","",IF(ABS(R4)<=Léeme!$B$12,"Cuadra",IF(R4<0,"Faltante","Sobrante"))) | T4: No
A5: 45660 | B5: Jardín | D5: Excel | E5: 204580 | F5: 27510 | G5: 10270 | H5: 0 | I5: 16660 | J5: =SUM(E5:I5) -> 259020 | L5: 0 | N5: 124000 | P5: =IF(O5="","",O5+E5-L5-N5) | R5: =IF(OR(Q5="",P5=""),"",Q5-P5) | S5: =IF(R5="","",IF(ABS(R5)<=Léeme!$B$12,"Cuadra",IF(R5<0,"Faltante","Sobrante"))) | T5: No
A6: 45661 | B6: Centro | D6: Excel | E6: 368810 | F6: 47260 | G6: 18230 | H6: 0 | I6: 28590 | J6: =SUM(E6:I6) -> 462890 | L6: 8100 | M6: Verdulería | N6: 0 | P6: =IF(O6="","",O6+E6-L6-N6) | R6: =IF(OR(Q6="",P6=""),"",Q6-P6) | S6: =IF(R6="","",IF(ABS(R6)<=Léeme!$B$12,"Cuadra",IF(R6<0,"Faltante","Sobrante"))) | T6: No
A7: 45661 | B7: Jardín | D7: Excel | E7: 331140 | F7: 44530 | G7: 15270 | H7: 0 | I7: 23160 | J7: =SUM(E7:I7) -> 414100 | L7: 3280 | M7: Limpieza | N7: 206000 | P7: =IF(O7="","",O7+E7-L7-N7) | R7: =IF(OR(Q7="",P7=""),"",Q7-P7) | S7: =IF(R7="","",IF(ABS(R7)<=Léeme!$B$12,"Cuadra",IF(R7<0,"Faltante","Sobrante"))) | T7: No
A8: 45662 | B8: Centro | D8: Excel | E8: 646200 | F8: 81120 | G8: 29660 | H8: 0 | I8: 47210 | J8: =SUM(E8:I8) -> 804190 | L8: 0 | N8: 497000 | P8: =IF(O8="","",O8+E8-L8-N8) | R8: =IF(OR(Q8="",P8=""),"",Q8-P8) | S8: =IF(R8="","",IF(ABS(R8)<=Léeme!$B$12,"Cuadra",IF(R8<0,"Faltante","Sobrante"))) | T8: No
A9: 45662 | B9: Jardín | D9: Excel | E9: 511510 | F9: 57830 | G9: 24240 | H9: 0 | I9: 37710 | J9: =SUM(E9:I9) -> 631290 | L9: 0 | N9: 447000 | P9: =IF(O9="","",O9+E9-L9-N9) | R9: =IF(OR(Q9="",P9=""),"",Q9-P9) | S9: =IF(R9="","",IF(ABS(R9)<=Léeme!$B$12,"Cuadra",IF(R9<0,"Faltante","Sobrante"))) | T9: No
A10: 45664 | B10: Centro | D10: Excel | E10: 241600 | F10: 32140 | G10: 13090 | H10: 0 | I10: 19450 | J10: =SUM(E10:I10) -> 306280 | L10: 14640 | M10: Verdulería | N10: 0 | P10: =IF(O10="","",O10+E10-L10-N10) | R10: =IF(OR(Q10="",P10=""),"",Q10-P10) | S10: =IF(R10="","",IF(ABS(R10)<=Léeme!$B$12,"Cuadra",IF(R10<0,"Faltante","Sobrante"))) | T10: No
A11: 45664 | B11: Jardín | D11: Excel | E11: 191030 | F11: 22630 | G11: 10000 | H11: 0 | I11: 15670 | J11: =SUM(E11:I11) -> 239330 | L11: 0 | N11: 0 | P11: =IF(O11="","",O11+E11-L11-N11) | R11: =IF(OR(Q11="",P11=""),"",Q11-P11) | S11: =IF(R11="","",IF(ABS(R11)<=Léeme!$B$12,"Cuadra",IF(R11<0,"Faltante","Sobrante"))) | T11: No
A12: 45665 | B12: Centro | D12: Excel | E12: 240450 | F12: 30530 | G12: 12110 | H12: 0 | I12: 17810 | J12: =SUM(E12:I12) -> 300900 | L12: 0 | N12: 211000 | P12: =IF(O12="","",O12+E12-L12-N12) | R12: =IF(OR(Q12="",P12=""),"",Q12-P12) | S12: =IF(R12="","",IF(ABS(R12)<=Léeme!$B$12,"Cuadra",IF(R12<0,"Faltante","Sobrante"))) | T12: No
A13: 45665 | B13: Jardín | D13: Excel | E13: 209810 | F13: 25630 | G13: 12380 | H13: 0 | I13: 16960 | J13: =SUM(E13:I13) -> 264780 | L13: 10070 | M13: Verdulería | N13: 161000 | P13: =IF(O13="","",O13+E13-L13-N13) | R13: =IF(OR(Q13="",P13=""),"",Q13-P13) | S13: =IF(R13="","",IF(ABS(R13)<=Léeme!$B$12,"Cuadra",IF(R13<0,"Faltante","Sobrante"))) | T13: No
A14: 45666 | B14: Centro | D14: Excel | E14: 289890 | F14: 31670 | G14: 13090 | H14: 0 | I14: 19650 | J14: =SUM(E14:I14) -> 354300 | L14: 0 | N14: 0 | P14: =IF(O14="","",O14+E14-L14-N14) | R14: =IF(OR(Q14="",P14=""),"",Q14-P14) | S14: =IF(R14="","",IF(ABS(R14)<=Léeme!$B$12,"Cuadra",IF(R14<0,"Faltante","Sobrante"))) | T14: No
A15: 45666 | B15: Jardín | D15: Excel | E15: 179760 | F15: 24280 | G15: 8980 | H15: 0 | I15: 14560 | J15: =SUM(E15:I15) -> 227580 | L15: 0 | N15: 139000 | P15: =IF(O15="","",O15+E15-L15-N15) | R15: =IF(OR(Q15="",P15=""),"",Q15-P15) | S15: =IF(R15="","",IF(ABS(R15)<=Léeme!$B$12,"Cuadra",IF(R15<0,"Faltante","Sobrante"))) | T15: No
A16: 45667 | B16: Centro | D16: Excel | E16: 266560 | F16: 40430 | G16: 15140 | H16: 0 | I16: 22700 | J16: =SUM(E16:I16) -> 344830 | L16: 17140 | M16: Verdulería | N16: 163000 | P16: =IF(O16="","",O16+E16-L16-N16) | R16: =IF(OR(Q16="",P16=""),"",Q16-P16) | S16: =IF(R16="","",IF(ABS(R16)<=Léeme!$B$12,"Cuadra",IF(R16<0,"Faltante","Sobrante"))) | T16: No
A17: 45667 | B17: Jardín | D17: Excel | E17: 182400 | F17: 21950 | G17: 9940 | H17: 0 | I17: 15230 | J17: =SUM(E17:I17) -> 229520 | L17: 0 | N17: 0 | P17: =IF(O17="","",O17+E17-L17-N17) | R17: =IF(OR(Q17="",P17=""),"",Q17-P17) | S17: =IF(R17="","",IF(ABS(R17)<=Léeme!$B$12,"Cuadra",IF(R17<0,"Faltante","Sobrante"))) | T17: No
A18: 45668 | B18: Centro | D18: Excel | E18: 398510 | F18: 46380 | G18: 18240 | H18: 0 | I18: 27930 | J18: =SUM(E18:I18) -> 491060 | L18: 5960 | M18: Delivery | N18: 0 | P18: =IF(O18="","",O18+E18-L18-N18) | R18: =IF(OR(Q18="",P18=""),"",Q18-P18) | S18: =IF(R18="","",IF(ABS(R18)<=Léeme!$B$12,"Cuadra",IF(R18<0,"Faltante","Sobrante"))) | T18: No
A19: 45668 | B19: Jardín | D19: Excel | E19: 310450 | F19: 38210 | G19: 18040 | H19: 0 | I19: 26930 | J19: =SUM(E19:I19) -> 393630 | L19: 0 | N19: 266000 | P19: =IF(O19="","",O19+E19-L19-N19) | R19: =IF(OR(Q19="",P19=""),"",Q19-P19) | S19: =IF(R19="","",IF(ABS(R19)<=Léeme!$B$12,"Cuadra",IF(R19<0,"Faltante","Sobrante"))) | T19: No
A20: 45669 | B20: Centro | D20: Excel | E20: 627890 | F20: 89190 | G20: 35420 | H20: 0 | I20: 55850 | J20: =SUM(E20:I20) -> 808350 | L20: 0 | N20: 0 | P20: =IF(O20="","",O20+E20-L20-N20) | R20: =IF(OR(Q20="",P20=""),"",Q20-P20) | S20: =IF(R20="","",IF(ABS(R20)<=Léeme!$B$12,"Cuadra",IF(R20<0,"Faltante","Sobrante"))) | T20: No
A21: 45669 | B21: Jardín | D21: Excel | E21: 503080 | F21: 60000 | G21: 23300 | H21: 0 | I21: 36330 | J21: =SUM(E21:I21) -> 622710 | L21: 0 | N21: 438000 | P21: =IF(O21="","",O21+E21-L21-N21) | R21: =IF(OR(Q21="",P21=""),"",Q21-P21) | S21: =IF(R21="","",IF(ABS(R21)<=Léeme!$B$12,"Cuadra",IF(R21<0,"Faltante","Sobrante"))) | T21: No
A22: 45671 | B22: Centro | D22: Excel | E22: 241450 | F22: 30380 | G22: 12680 | H22: 0 | I22: 20030 | J22: =SUM(E22:I22) -> 304540 | L22: 0 | N22: 0 | P22: =IF(O22="","",O22+E22-L22-N22) | R22: =IF(OR(Q22="",P22=""),"",Q22-P22) | S22: =IF(R22="","",IF(ABS(R22)<=Léeme!$B$12,"Cuadra",IF(R22<0,"Faltante","Sobrante"))) | T22: No
